Workbook
Name 능력단위: #REF!

Sheet ●프롬프트
A1: LLM 프롬프트
A2: 너는 "의료기기 개발, 제조 기업"을 대상으로 하는 "AI전환교육"을 위한 교육 컨설턴트 및 교육설계개발자야. 엑셀에서 제시하는 기본적인 내용을 바탕으로 요구하는 내용을 만들어서 셀에 입력해 주면 되. 최대한 AI/AX 전문가 이면서 의료기기에 대한 전문가 여서 최적의 교육과정을 개발해 주면 되. 아래의 내용을 참고해서 작업해줘 ## 셀 설명 B3:C30에는 니가 알아야할 내용이 담겨 있어, B열부분에는 제목, C열 부분에는 내용이 있어. 여기에는 기초적인 교육과정의 제목과 커리큘럼이 있어. 단, 시간(C11)은 아직 못 정해서 임의로 넣은거라 참고하지 말고, 여기 있는 내용을 바탕으로 J70:J118 부분에 내용을 적절하게 채워주면 되. J70:J118의 각 칸은 1일차~5일차의 각 시간별(1시간단위) 교육 내용이 들어가는 셀이야. 해당 일차와 시간은 B70:C118을 참고하면 되. 그리고 K70, K80, K90, K100, K110은 각각 일차에 해당하는 내용의 커리큘럼을 1일 단위로 넣는 곳이야. 바로 위의 셀에 몇일차 인지 나와 있어. 여기는 많이 상세하게 작성해줘. 최소한 100~150자 정도 여기는 3일차로 과정을 만들어서 채워줘. 점심시간은 뺴고 나머지만 채워줘. 각 시간별 교육내용은 제목처럼 한줄(20~30자)로 작성해줘. 그래서 니가 해야할 것은 B3:C30을 참조해서, 이 과정이 몇시간 짜리의 과정인지 정해야해. 1일을 8시간으로 해서 8,16,24,32,40시간으로 정할 수 있어. 가급적 2일~4일정도가 적절할꺼야. 너무 길어도 안되고 2~3일정도가 적절. 마지막 APX1의 PBL 과정은 8주차 인데 이건 8일차로 해 주면 되. 1주일에 한번씩 과정을 진행한다고 생각하면 되. 이건 입력 하는 곳도 J148까지 있어. C3:C28 의 각 셀에 대한 참고내용은 제목은 B열에 있고, 출력포맷 예시는 J열에 있어. 그래서 만약 니가 C13에 내용을 넣어야 하는 경우 B2:C11의 내용을 바탕으로 고민한 다음, B13의 제목과, J13의 출력포맷 예시를 확인해서 넣어주면 되.

Sheet 1-AFX1 리터러시
A1: 커리큘럼 기초 내용
B2: 분류선택 | C2: 07.인공지능 > 07.생성형AI엔지니어링> 프롬프트 구현
A3: {{edu_title}} | B3: 훈련과정명 | C3: 의료·바이오 AI 리터러시 입문 (4h) | J3: 기획자와 컨설턴트를 위한 AI개발의 이해
B4: 커리큘럼 | C4: 1. 의료·바이오 분야 AI 적용 사례와 한계 2. AI의 이해 (생성형 AI의 이해 및 활용, ChatGPT/Claude/Gemini) 3. 프롬프트엔지니어링과 생성형AI의 고급 활용 4. 반복업무를 손쉽게 하는 나만의 챗봇 (GPTs, Gems) 5. AI를 활용한 문서작업 - ( ChatGPT, Claude, Gemini, Genspark, Google Docs ) 6. 리서치, 기획, 제안, 문서작업 등을 위한 NotebookLM 활용법 7. AI윤리, 보안의 이해
A5: {{edu_cate01}} | B5: 대분류 | C5: =VLOOKUP($C$2,통합!A2:J52,2,FALSE) -> 20.정보통신
A6: {{edu_cate02}} | B6: 중분류 | C6: =VLOOKUP($C$2,통합!A2:J52,3,FALSE) -> 01.정보기술
A7: {{edu_cate03}} | B7: 소분류 | C7: =VLOOKUP($C$2,통합!A2:J52,4,FALSE) -> 07.인공지능
A8: {{edu_cate04}} | B8: 세분류 | C8: =VLOOKUP($C$2,통합!A2:J52,8,FALSE)&"."&VLOOKUP($C$2,통합!A2:J52,9,FALSE) -> 05.프롬프트 구현
A9: {{edu_cate05}} | B9: 훈련방법 | C9: =VLOOKUP($C$2,통합!A2:J52,7,FALSE) -> 2001070705_25v1
A10: {{edu_ncslevel}} | B10: 훈련수준 | C10: =VLOOKUP($C$2,통합!A2:J52,6,FALSE) -> 5
A11: {{edu_time}} | B11: 훈련시간 | C11: =F78&"시간( "&K131&"일)" -> 1시간( 1일) | J11: 000시간(00일)
A12: 교육과정 세부 정보
A13: {{edu_target}} | B13: 훈련대상자 | C13: 의료기기 개발·제조 기업 임직원 중 AI 활용에 관심이 있는 전 직군 (품질, RA, R&D, 생산, 영업, 경영지원 등) | J13: 기획자, 컨설턴트, 디자이너 등 개발과 AI에 이해가 필요한 직무
A14: {{edu_job}} | B14: 대상직종 | C14: 전직무 | J14: 기획자
A15: {{edu_limit}} | B15: 정원 | C15: 20명 | J15: 00명
A16: {{edu_feature}} | B16: 훈련과정 특성 | C16: 의료기기 산업 종사자를 대상으로 생성형 AI의 기본 개념부터 실무 활용까지 다루는 AI 전환(AX) 입문 과정으로, 의료기기 분야 특화 사례와 실습 중심의 교육을 통해 디지털 전환 역량을 강화하는 신기술·융복합 훈련과정 | J16: 4차 산업혁명 등 관련된 신기술, 융복합, 미래전략산업 직종 과정 등 훈련과정의 특성 기재
A17: {{edu_summary}} | B17: 주요훈련내용 | C17: 의료·바이오 분야의 AI 적용 현황과 한계를 이해하고, ChatGPT·Claude·Gemini 등 주요 생성형 AI 도구의 원리와 활용법을 학습한다. 프롬프트 엔지니어링 기법을 익혀 AI를 고급 활용하고, GPTs·Gems를 통해 나만의 챗봇을 제작하며, AI 기반 문서작성과 NotebookLM을 활용한 리서치·기획 역량을 배양한다. 또한 AI 윤리와 보안에 대한 인식을 갖춘다. | J17: 주요훈련내용을 요약해서 작성
A18: {{edu_ncsreason}} | B18: NCS 미적용 사유 | C18: 본 훈련과정은 의료기기 산업 현장의 AI 전환(AX) 수요에 맞춰 생성형 AI 활용 역량 강화를 목적으로 설계된 과정으로, 기존 NCS 분류체계에 정확히 부합하는 능력단위가 부재하여 산업 현장 맞춤형 커리큘럼으로 자체 구성함 | J18: 주요훈련내용을 요약해서 작성
A19: {{edu_goal}} | B19: 훈련목표 | C19: 의료기기 산업 종사자가 생성형 AI의 개념과 원리를 이해하고, 프롬프트 엔지니어링과 주요 AI 도구(ChatGPT, Claude, Gemini, NotebookLM 등)를 활용하여 문서작성, 리서치, 기획 등 실무 업무에 AI를 효과적으로 적용할 수 있는 기초 역량을 습득하는 것을 목표로 함 | J19: IT 기본 지식을 습득하고 개발자와 원활히 소통하며, 컨설팅 업무에 필요한 IT 전문 지식과 생성형 AI에 대한 이해를 높여 실무에 바로 적용할 수 있는 역량을 키우는 것을 목표로 함
A20: {{edu_guidegoal}} | B20: 지도목표 | C20: 의료기기 분야의 AI 적용 사례와 생성형 AI 도구의 기본 원리를 명확히 이해하고, 실습을 통해 프롬프트 엔지니어링 능력을 키워 최신 AI 기술을 의료기기 업무 현장에 바로 적용할 수 있는 실무 문제 해결 능력을 갖추어 업무 효율성을 높입니다. | J20: IT 기본 개념을 명확히 이해하고, 실습을 통해 능력을 키워 최신 AI 기술을 활용한 실무 문제 해결 능력을 갖추어 업무의 효율성을 높입니다.
A21: {{edu_guidegoaldetail}} | B21: 세부 지도목표 | C21: * 의료·바이오 분야 AI 적용 사례와 한계점 분석 * 생성형 AI(ChatGPT, Claude, Gemini)의 원리와 활용 방법 이해 * 프롬프트 엔지니어링 기법을 통한 AI 고급 활용 능력 배양 * GPTs, Gems를 활용한 맞춤형 챗봇 제작 실습 * AI 기반 문서작성 및 NotebookLM을 활용한 리서치·기획 역량 강화 * AI 윤리 및 보안 이슈에 대한 인식 제고 | J21: * 운영체제, 서버, 클라우드 인프라의 기본 개념 설명 * 데이터베이스의 기초 지식과 데이터 관리 방법 이해 * 생성형 AI와 LLM의 원리 및 적용 사례 소개 * IT 용어와 개념을 쉽게 설명하고 실제 사례를 통해 이해 증진
A22: {{edu_guidegoaldetail-1}} | B22: 지도내용 | C22: [의료·바이오 AI 개론 및 생성형 AI 활용] - 의료기기 분야 AI 적용 사례와 한계점 분석 - 생성형 AI(ChatGPT, Claude, Gemini)의 원리 이해 및 실습 | J22: [IT 기본 개념] - 운영체제와 서버의 기본 개념 - 클라우드 인프라의 이해
A23: {{edu_guidegoaldetail-2}} | C23: [프롬프트 엔지니어링과 AI 고급 활용] - 프롬프트 엔지니어링 기법을 통한 생성형 AI 고급 활용 - 나만의 챗봇 만들기 (GPTs, Gems) 실습 | J23: [데이터베이스와 개발 기초] - 데이터베이스 기초 개념 - 개발 관련 기초 지식 및 용어
A24: {{edu_guidegoaldetail-3}} | C24: [AI 기반 문서작성 및 윤리·보안] - AI를 활용한 문서작업 및 NotebookLM 활용 리서치·기획 - AI 윤리, 보안의 이해 및 의료기기 업무 적용 시 주의사항 | J24: [생성형 AI와 LLM] - 생성형 AI의 개념과 원리 - LLM의 동작 원리 및 실제 사례
A25: {{edu_learnhow}} | B25: 교수학습방법 | C25: 강의: 슬라이드 및 의료기기 산업 사례 영상 자료를 활용하여 시각적 이해를 돕고, 실제 의료기기 AI 적용 사례 중심으로 설명 실습: ChatGPT, Claude, Gemini 등 생성형 AI 도구를 직접 활용한 프롬프트 작성 및 문서작성 실습 토론: 의료기기 업무 현장에서의 AI 활용 방안에 대한 그룹 토론을 통해 실무 적용 능력 배양 Q&A: 실시간 질문을 통해 이해도 점검 및 피드백 제공 | J25: 강의: 슬라이드 및 영상 자료를 활용하여 시각적 이해를 돕고, 사례 중심으로 설명 실습: 간단한 클라우드 설정 및 데이터베이스 생성 실습 토론: 실제 사례에 기반한 토론을 통해 실무 적용 능력 배양 Q&A: 실시간 질문을 통해 이해도 점검 및 피드백 제공
A26: {{edu_testhow}} | B26: 평가방법 | C26: 가. 평가시점 : 교과목 수업 종료시 나. 평가내용 • 생성형 AI 도구(ChatGPT, Claude, Gemini)의 기본 활용 능력 • 프롬프트 엔지니어링을 통한 업무 적용 능력 • AI 윤리 및 보안에 대한 이해도 다. 평가방법 • 결과평가 : 실습 결과물 제출 및 구두발표 | J26: 가. 평가시점 : 교과목 수업 종료시 나. 평가내용 • 호텔 운영 프로그램에 대한 지식(Fidelio, Opera 등) • 객실 업셀링 능력 • 고객정보 검색 능력 및 활용 기술 다. 평가방법 • 결과평가 : 구두발표
A27: {{edu_book}} | B27: 훈련교재 | C27: 자체교재 | J27: 자체교재
A28: {{edu_future}} | B28: 연계 훈련과정 (해당 훈련과정의 중장기 체계적 운영의 적정성을 위한 레벨업 실시 계획) | C28: [Basic] Lv.1 - 의료·바이오 AI 리터러시 입문 (본 과정) Lv.2 - 의료기기 데이터 분석 및 AI 활용 기초 Lv.2 - 의료기기 업무 자동화를 위한 AI 워크플로우 [Advance] Lv.3 - 의료기기 품질관리(QA)를 위한 AI 활용 Lv.3 - 의료기기 인허가(RA)를 위한 AI 활용 Lv.4 - 의료기기 R&D를 위한 AI 활용 Lv.5 - 의료기기 데이터 파이프라인 구축 및 운영 | J28: [Basic] Lv.1 - 기획자와 컨설턴트를 위한 AI개발의 이해 Lv.2 - 바이브코딩 이론 및 실습 Lv.2 - 웹서비스 배포 전략 및 클라우드 서비스의 이해 [Advance] Lv.3 - 데이터베이스 이해 및 실습 1 (MySQL) Lv.3 - 데이터베이스 이해 및 실습 2 (Supabase) Lv.3 - 데이터베이스 이해 및 실습 3 (Firebase) Lv.4 - 웹앱서비스운영전략 Lv.5 - 개발에서 배포 운영까지의 파이프라인 구축
A29: {{edu_needreason}} | B29: 사업 필요성&목적 | J29: 기획자들의 경우 개발자와의 커뮤니케이션에서 어려움을 겪는 경우가 많음, 또한 관련 직무의 수요조사 결과 관련된 교육의 필요성이 제기됨 본 과정은 이런 소통과 기획자의 직무에 필요한 IT관련 기초지식을 배양하여 직무관련 역량을 높이며, 바이브코딩을 통해 업무의 프로세스와 효율을 높일 수 있다
A30: {{edu_curri}} | B30: 커리큘럼 요약 | J30: LLM(예: ChatGPT, Claude)의 구조와 생성형 AI 패러다임을 이해하고, 의료·바이오 산업에서의 적용 가능성과 한계를 학습하며 기초 툴을 실습한다. 업무 전환을 위해 프롬프트의 기본 구조와 컨텍스트 설계, 페르소나 설정 및 출력 제어 방법을 익히고 직무별 적용 실습을 진행한다. 의료 AI 윤리, 개인정보 비식별화, 저작권 및 사내 보안 가이드라인을 학습하여 민감정보를 안전하게 처리하는 역량을 강화한다.
A31: {{edu_edutime}} | B31: 총시간(%) | C31: =F78&"시간 (100%)" -> 1시간 (100%)
A32: {{time_day_1}} | B32: 1일차 교육시간 | C32: =COUNTA(G82:G90) -> 1
A33: {{time_day_2}} | B33: 2일차 교육시간 | C33: =COUNTA(G92:G100) -> 0
A34: {{time_day_3}} | B34: 3일차 교육시간 | C34: =COUNTA(G102:G110) -> 0
A35: {{time_day_4}} | B35: 4일차 교육시간 | C35: =COUNTA(G112:G120) -> 0
A36: {{time_day_5}} | B36: 5일차 교육시간 | C36: =COUNTA(G122:G130) -> 0
A37: {{topic_day_1}} | B37: 1일차 교육내용 | C37: =K82 -> 의료·바이오 분야의 AI 적용 현황과 한계를 파악한 후, ChatGPT·Claude·Gemini 등 주요 생성형 AI 도구의 원리를 이해하고 직접 실습한다. 프롬프트 엔지니어링 기법을 익혀 AI를 고급 활용하는 방법을 배우고, GPTs·Gems를 활용하여 의료기기 업무에 특화된 나만의 챗봇을 제작하는 실습을 진행한다. 마지막으로 AI 활용 시 반드시 고려해야 할 윤리적 이슈와 보안 가이드라인을 학습하여 안전한 AI 활용 역량을 갖춘다.
A38: {{topic_day_2}} | B38: 2일차 교육내용 | C38: =K92 -> 0
A39: {{topic_day_3}} | B39: 3일차 교육내용 | C39: =K102 -> 0
A40: {{topic_day_4}} | B40: 4일차 교육내용 | C40: =K112 -> 0
...

Sheet 2-AFX-2 데이터
A1: 커리큘럼 기초 내용
B2: 분류선택 | C2: 07.인공지능 > 07.생성형AI엔지니어링> 프롬프트 구현
A3: {{edu_title}} | B3: 훈련과정명 | C3: 의료·바이오 데이터리터러시와 데이터시각화 (6h) | J3: 기획자와 컨설턴트를 위한 AI개발의 이해
B4: 커리큘럼 | C4: 1. 의료·바이오 데이터리터러시의 이해 2. 데이터분석의 기초와 데이터 수집 (ChatGPT/Claude/Gemini) 3. 데이터전처리 (Excel, Excel for Claude) : 비정형 데이터 정형화 4. 데이터시각화 기초 (ChatGPT, Tableau) 5. 데이터 분석 리포트 제작 (ChatGPT, Tableau)
A5: {{edu_cate01}} | B5: 대분류 | C5: =VLOOKUP($C$2,통합!A2:J52,2,FALSE) -> 20.정보통신
A6: {{edu_cate02}} | B6: 중분류 | C6: =VLOOKUP($C$2,통합!A2:J52,3,FALSE) -> 01.정보기술
A7: {{edu_cate03}} | B7: 소분류 | C7: =VLOOKUP($C$2,통합!A2:J52,4,FALSE) -> 07.인공지능
A8: {{edu_cate04}} | B8: 세분류 | C8: =VLOOKUP($C$2,통합!A2:J52,8,FALSE)&"."&VLOOKUP($C$2,통합!A2:J52,9,FALSE) -> 05.프롬프트 구현
A9: {{edu_cate05}} | B9: 훈련방법 | C9: =VLOOKUP($C$2,통합!A2:J52,7,FALSE) -> 2001070705_25v1
A10: {{edu_ncslevel}} | B10: 훈련수준 | C10: =VLOOKUP($C$2,통합!A2:J52,6,FALSE) -> 5
A11: {{edu_time}} | B11: 훈련시간 | C11: =F78&"시간( "&K131&"일)" -> 1시간( 1일) | J11: 000시간(00일)
A12: 교육과정 세부 정보
A13: {{edu_target}} | B13: 훈련대상자 | C13: 의료기기 개발·제조 기업 임직원 중 데이터 분석과 AI 활용에 관심이 있는 전 직군 (품질, RA, R&D, 생산, 영업, 경영지원 등) | J13: 기획자, 컨설턴트, 디자이너 등 개발과 AI에 이해가 필요한 직무
A14: {{edu_job}} | B14: 대상직종 | C14: 데이터 분석이 필요한 전 직무 | J14: 기획자
A15: {{edu_limit}} | B15: 정원 | C15: 20명 | J15: 00명
A16: {{edu_feature}} | B16: 훈련과정 특성 | C16: 의료기기 산업 종사자를 대상으로 데이터리터러시의 기본 개념부터 AI를 활용한 데이터 수집·전처리·시각화·리포트 제작까지 다루는 AI 전환(AX) 데이터 활용 과정으로, 의료기기 분야 실제 데이터 사례와 실습 중심의 교육을 통해 데이터 기반 의사결정 역량을 강화하는 신기술·융복합 훈련과정 | J16: 4차 산업혁명 등 관련된 신기술, 융복합, 미래전략산업 직종 과정 등 훈련과정의 특성 기재
A17: {{edu_summary}} | B17: 주요훈련내용 | C17: 의료·바이오 분야의 데이터리터러시 개념을 이해하고, ChatGPT·Claude·Gemini를 활용한 데이터 수집 방법을 학습한다. Excel과 Excel for Claude를 활용하여 비정형 의료기기 데이터를 정형화하는 전처리 기법을 익히고, ChatGPT와 Tableau를 활용한 데이터시각화 기초를 배운다. 최종적으로 의료기기 분야 데이터 분석 리포트를 직접 제작하는 실습을 수행한다. | J17: 주요훈련내용을 요약해서 작성
A18: {{edu_ncsreason}} | B18: NCS 미적용 사유 | C18: 본 훈련과정은 의료기기 산업 현장의 데이터 기반 AI 전환(AX) 수요에 맞춰 데이터리터러시 및 시각화 역량 강화를 목적으로 설계된 과정으로, 기존 NCS 분류체계에 정확히 부합하는 능력단위가 부재하여 산업 현장 맞춤형 커리큘럼으로 자체 구성함 | J18: 주요훈련내용을 요약해서 작성
A19: {{edu_goal}} | B19: 훈련목표 | C19: 의료기기 산업 종사자가 데이터리터러시의 개념을 이해하고, 생성형 AI(ChatGPT, Claude, Gemini)와 Tableau 등 도구를 활용하여 의료기기 데이터의 수집·전처리·시각화·리포트 제작까지 전 과정을 수행할 수 있는 데이터 활용 역량을 습득하는 것을 목표로 함 | J19: IT 기본 지식을 습득하고 개발자와 원활히 소통하며, 컨설팅 업무에 필요한 IT 전문 지식과 생성형 AI에 대한 이해를 높여 실무에 바로 적용할 수 있는 역량을 키우는 것을 목표로 함
A20: {{edu_guidegoal}} | B20: 지도목표 | C20: 의료기기 분야의 데이터 특성과 활용 사례를 명확히 이해하고, AI 도구를 활용한 데이터 수집·전처리·시각화 실습을 통해 데이터 기반 의사결정 능력을 키워 의료기기 업무 현장에 바로 적용할 수 있는 실무 문제 해결 능력을 갖추어 업무 효율성을 높입니다. | J20: IT 기본 개념을 명확히 이해하고, 실습을 통해 능력을 키워 최신 AI 기술을 활용한 실무 문제 해결 능력을 갖추어 업무의 효율성을 높입니다.
A21: {{edu_guidegoaldetail}} | B21: 세부 지도목표 | C21: * 의료·바이오 분야 데이터리터러시의 개념과 중요성 이해 * 생성형 AI(ChatGPT, Claude, Gemini)를 활용한 데이터 수집 기법 습득 * Excel과 Excel for Claude를 활용한 비정형 데이터 전처리 능력 배양 * ChatGPT와 Tableau를 활용한 데이터시각화 기초 역량 강화 * 의료기기 분야 데이터 분석 리포트 제작 실습을 통한 종합 역량 함양 | J21: * 운영체제, 서버, 클라우드 인프라의 기본 개념 설명 * 데이터베이스의 기초 지식과 데이터 관리 방법 이해 * 생성형 AI와 LLM의 원리 및 적용 사례 소개 * IT 용어와 개념을 쉽게 설명하고 실제 사례를 통해 이해 증진
A22: {{edu_guidegoaldetail-1}} | B22: 지도내용 | C22: [데이터리터러시와 AI 기반 데이터 수집] - 의료·바이오 데이터리터러시의 개념과 의료기기 데이터 특성 이해 - AI(ChatGPT/Claude/Gemini)를 활용한 데이터 수집 방법론 | J22: [IT 기본 개념] - 운영체제와 서버의 기본 개념 - 클라우드 인프라의 이해
A23: {{edu_guidegoaldetail-2}} | C23: [데이터 전처리 및 시각화] - Excel과 Excel for Claude를 활용한 비정형 데이터 정형화 전처리 - ChatGPT와 Tableau를 활용한 데이터시각화 기초 | J23: [데이터베이스와 개발 기초] - 데이터베이스 기초 개념 - 개발 관련 기초 지식 및 용어
A24: {{edu_guidegoaldetail-3}} | C24: [데이터 분석 리포트 제작] - ChatGPT와 Tableau를 활용한 의료기기 데이터 분석 리포트 제작 - 데이터 기반 의사결정 및 리포트 발표 실습 | J24: [생성형 AI와 LLM] - 생성형 AI의 개념과 원리 - LLM의 동작 원리 및 실제 사례
A25: {{edu_learnhow}} | B25: 교수학습방법 | C25: 강의: 슬라이드 및 의료기기 데이터 분석 사례 자료를 활용하여 데이터리터러시의 개념과 활용 방법을 시각적으로 설명 실습: ChatGPT·Claude·Gemini를 활용한 데이터 수집, Excel·Excel for Claude를 활용한 전처리, Tableau를 활용한 시각화 및 리포트 제작 실습 토론: 의료기기 업무 현장의 실제 데이터 활용 사례를 기반으로 그룹 토론을 통해 실무 적용 능력 배양 Q&A: 실시간 질문을 통해 이해도 점검 및 피드백 제공 | J25: 강의: 슬라이드 및 영상 자료를 활용하여 시각적 이해를 돕고, 사례 중심으로 설명 실습: 간단한 클라우드 설정 및 데이터베이스 생성 실습 토론: 실제 사례에 기반한 토론을 통해 실무 적용 능력 배양 Q&A: 실시간 질문을 통해 이해도 점검 및 피드백 제공
A26: {{edu_testhow}} | B26: 평가방법 | C26: 가. 평가시점 : 교과목 수업 종료시 나. 평가내용 • AI 도구(ChatGPT, Claude, Gemini)를 활용한 데이터 수집 능력 • Excel 및 AI를 활용한 데이터 전처리 능력 • Tableau를 활용한 데이터시각화 및 리포트 제작 능력 다. 평가방법 • 결과평가 : 데이터 분석 리포트 제출 및 구두발표 | J26: 가. 평가시점 : 교과목 수업 종료시 나. 평가내용 • 호텔 운영 프로그램에 대한 지식(Fidelio, Opera 등) • 객실 업셀링 능력 • 고객정보 검색 능력 및 활용 기술 다. 평가방법 • 결과평가 : 구두발표
A27: {{edu_book}} | B27: 훈련교재 | C27: 자체교재 | J27: 자체교재
A28: {{edu_future}} | B28: 연계 훈련과정 (해당 훈련과정의 중장기 체계적 운영의 적정성을 위한 레벨업 실시 계획) | C28: [Basic] Lv.1 - 의료·바이오 AI 리터러시 입문 Lv.2 - 의료·바이오 데이터리터러시와 데이터시각화 (본 과정) Lv.2 - 의료기기 업무 자동화를 위한 AI 워크플로우 [Advance] Lv.3 - 의료기기 품질관리(QA)를 위한 AI 활용 Lv.3 - 의료기기 인허가(RA)를 위한 AI 활용 Lv.4 - 의료기기 R&D를 위한 AI 활용 Lv.5 - 의료기기 데이터 파이프라인 구축 및 운영 | J28: [Basic] Lv.1 - 기획자와 컨설턴트를 위한 AI개발의 이해 Lv.2 - 바이브코딩 이론 및 실습 Lv.2 - 웹서비스 배포 전략 및 클라우드 서비스의 이해 [Advance] Lv.3 - 데이터베이스 이해 및 실습 1 (MySQL) Lv.3 - 데이터베이스 이해 및 실습 2 (Supabase) Lv.3 - 데이터베이스 이해 및 실습 3 (Firebase) Lv.4 - 웹앱서비스운영전략 Lv.5 - 개발에서 배포 운영까지의 파이프라인 구축
A29: {{edu_needreason}} | B29: 사업 필요성&목적 | J29: 기획자들의 경우 개발자와의 커뮤니케이션에서 어려움을 겪는 경우가 많음, 또한 관련 직무의 수요조사 결과 관련된 교육의 필요성이 제기됨 본 과정은 이런 소통과 기획자의 직무에 필요한 IT관련 기초지식을 배양하여 직무관련 역량을 높이며, 바이브코딩을 통해 업무의 프로세스와 효율을 높일 수 있다
A30: {{edu_curri}} | B30: 커리큘럼 요약 | J30: LLM(예: ChatGPT, Claude)의 구조와 생성형 AI 패러다임을 이해하고, 의료·바이오 산업에서의 적용 가능성과 한계를 학습하며 기초 툴을 실습한다. 업무 전환을 위해 프롬프트의 기본 구조와 컨텍스트 설계, 페르소나 설정 및 출력 제어 방법을 익히고 직무별 적용 실습을 진행한다. 의료 AI 윤리, 개인정보 비식별화, 저작권 및 사내 보안 가이드라인을 학습하여 민감정보를 안전하게 처리하는 역량을 강화한다.
A31: {{edu_edutime}} | B31: 총시간(%) | C31: =F78&"시간 (100%)" -> 1시간 (100%)
A32: {{time_day_1}} | B32: 1일차 교육시간 | C32: =COUNTA(G82:G90) -> 1
A33: {{time_day_2}} | B33: 2일차 교육시간 | C33: =COUNTA(G92:G100) -> 0
A34: {{time_day_3}} | B34: 3일차 교육시간 | C34: =COUNTA(G102:G110) -> 0
A35: {{time_day_4}} | B35: 4일차 교육시간 | C35: =COUNTA(G112:G120) -> 0
A36: {{time_day_5}} | B36: 5일차 교육시간 | C36: =COUNTA(G122:G130) -> 0
A37: {{topic_day_1}} | B37: 1일차 교육내용 | C37: =K82 -> 의료·바이오 분야 데이터리터러시의 개념과 의료기기 데이터의 특성을 이해한 후, ChatGPT·Claude·Gemini를 활용하여 의료기기 관련 데이터를 직접 수집하는 실습을 진행한다. Excel과 Excel for Claude를 활용하여 비정형 의료기기 데이터를 정형화하는 전처리 기법을 실습하고, ChatGPT와 Tableau를 활용한 데이터시각화 기초를 배운다. 최종적으로 의료기기 분야 데이터를 활용한 분석 리포트를 직접 제작하고 발표하여 데이터 기반 의사결정 역량을 함양한다.
A38: {{topic_day_2}} | B38: 2일차 교육내용 | C38: =K92 -> 0
A39: {{topic_day_3}} | B39: 3일차 교육내용 | C39: =K102 -> 0
A40: {{topic_day_4}} | B40: 4일차 교육내용 | C40: =K112 -> 0
...

Sheet 3-AFX-3 워크플로우
A1: 커리큘럼 기초 내용
B2: 분류선택 | C2: 07.인공지능 > 07.생성형AI엔지니어링> 프롬프트 구현
A3: {{edu_title}} | B3: 훈련과정명 | C3: AI 워크플로우 설계 기초 (8h) | J3: 기획자와 컨설턴트를 위한 AI개발의 이해
B4: 커리큘럼 | C4: 1. AI 워크플로우 도구의 이해 (Opal, n8n, Google AI Studio) 2. AI 워크플로우 설계 3. AI 워크플로우 실습 1 (Opal : Google 서비스 기반 워크플로우 설계) 4. AI 워크플로우 실습 2 (n8n : AI 업무자동화 워크플로우 설계) 5. AI 워크플로우 실습 3 (Google AI Studio : 멀티모달 기반 AI 워크플로우 앱 개발) 6. 통합 AI 워크플로우 구축 실습
A5: {{edu_cate01}} | B5: 대분류 | C5: =VLOOKUP($C$2,통합!A2:J52,2,FALSE) -> 20.정보통신
A6: {{edu_cate02}} | B6: 중분류 | C6: =VLOOKUP($C$2,통합!A2:J52,3,FALSE) -> 01.정보기술
A7: {{edu_cate03}} | B7: 소분류 | C7: =VLOOKUP($C$2,통합!A2:J52,4,FALSE) -> 07.인공지능
A8: {{edu_cate04}} | B8: 세분류 | C8: =VLOOKUP($C$2,통합!A2:J52,8,FALSE)&"."&VLOOKUP($C$2,통합!A2:J52,9,FALSE) -> 05.프롬프트 구현
A9: {{edu_cate05}} | B9: 훈련방법 | C9: =VLOOKUP($C$2,통합!A2:J52,7,FALSE) -> 2001070705_25v1
A10: {{edu_ncslevel}} | B10: 훈련수준 | C10: =VLOOKUP($C$2,통합!A2:J52,6,FALSE) -> 5
A11: {{edu_time}} | B11: 훈련시간 | C11: =F78&"시간( "&K131&"일)" -> 1시간( 1일) | J11: 000시간(00일)
A12: 교육과정 세부 정보
A13: {{edu_target}} | B13: 훈련대상자 | C13: 의료기기 개발·제조 기업 임직원 중 AI를 활용한 업무 자동화와 워크플로우 설계에 관심이 있는 전 직군 (품질, RA, R&D, 생산, 영업, 경영지원 등) | J13: 기획자, 컨설턴트, 디자이너 등 개발과 AI에 이해가 필요한 직무
A14: {{edu_job}} | B14: 대상직종 | C14: AI 워크플로우와 자동화가 필요한 모든 직무 | J14: 기획자
A15: {{edu_limit}} | B15: 정원 | C15: 20명 | J15: 00명
A16: {{edu_feature}} | B16: 훈련과정 특성 | C16: 의료기기 산업 종사자를 대상으로 AI 워크플로우 도구(Opal, n8n, Google AI Studio)의 개념부터 실제 업무 자동화 워크플로우 설계·구축까지 다루는 AI 전환(AX) 워크플로우 과정으로, 의료기기 분야 반복 업무의 자동화 사례와 실습 중심의 교육을 통해 업무 프로세스 혁신 역량을 강화하는 신기술·융복합 훈련과정 | J16: 4차 산업혁명 등 관련된 신기술, 융복합, 미래전략산업 직종 과정 등 훈련과정의 특성 기재
A17: {{edu_summary}} | B17: 주요훈련내용 | C17: AI 워크플로우 도구(Opal, n8n, Google AI Studio)의 개념과 특성을 이해하고, 의료기기 업무에 적합한 워크플로우를 설계하는 방법을 학습한다. Opal을 활용한 Google 서비스 기반 워크플로우, n8n을 활용한 업무자동화 워크플로우, Google AI Studio를 활용한 멀티모달 AI 워크플로우 앱 개발을 실습하고, 최종적으로 의료기기 업무에 특화된 통합 AI 워크플로우를 구축하는 프로젝트를 수행한다. | J17: 주요훈련내용을 요약해서 작성
A18: {{edu_ncsreason}} | B18: NCS 미적용 사유 | C18: 본 훈련과정은 의료기기 산업 현장의 AI 기반 업무 자동화 전환(AX) 수요에 맞춰 AI 워크플로우 설계 및 구축 역량 강화를 목적으로 설계된 과정으로, 기존 NCS 분류체계에 정확히 부합하는 능력단위가 부재하여 산업 현장 맞춤형 커리큘럼으로 자체 구성함 | J18: 주요훈련내용을 요약해서 작성
A19: {{edu_goal}} | B19: 훈련목표 | C19: 의료기기 산업 종사자가 AI 워크플로우 도구(Opal, n8n, Google AI Studio)의 원리와 활용법을 이해하고, 의료기기 업무의 반복 프로세스를 AI로 자동화하는 워크플로우를 직접 설계·구축할 수 있는 업무 자동화 역량을 습득하는 것을 목표로 함 | J19: IT 기본 지식을 습득하고 개발자와 원활히 소통하며, 컨설팅 업무에 필요한 IT 전문 지식과 생성형 AI에 대한 이해를 높여 실무에 바로 적용할 수 있는 역량을 키우는 것을 목표로 함
A20: {{edu_guidegoal}} | B20: 지도목표 | C20: AI 워크플로우 도구의 기본 원리와 설계 방법론을 명확히 이해하고, 실습을 통해 Opal·n8n·Google AI Studio 활용 능력을 키워 의료기기 업무 현장의 반복 프로세스를 AI로 자동화할 수 있는 실무 문제 해결 능력을 갖추어 업무 효율성을 높입니다. | J20: IT 기본 개념을 명확히 이해하고, 실습을 통해 능력을 키워 최신 AI 기술을 활용한 실무 문제 해결 능력을 갖추어 업무의 효율성을 높입니다.
A21: {{edu_guidegoaldetail}} | B21: 세부 지도목표 | C21: * AI 워크플로우 도구(Opal, n8n, Google AI Studio)의 개념과 특성 비교 이해 * 의료기기 업무 프로세스 분석 및 AI 워크플로우 설계 방법론 습득 * Opal을 활용한 Google 서비스 기반 업무 자동화 워크플로우 이해 * n8n을 활용한 AI 업무자동화 워크플로우 설계 및 구현 실습 * Google AI Studio를 활용한 멀티모달 AI 워크플로우 앱 개발 실습 * 의료기기 업무에 특화된 통합 AI 워크플로우 구축 및 발표 | J21: * 운영체제, 서버, 클라우드 인프라의 기본 개념 설명 * 데이터베이스의 기초 지식과 데이터 관리 방법 이해 * 생성형 AI와 LLM의 원리 및 적용 사례 소개 * IT 용어와 개념을 쉽게 설명하고 실제 사례를 통해 이해 증진
A22: {{edu_guidegoaldetail-1}} | B22: 지도내용 | C22: [AI 워크플로우 도구 이해와 설계] - AI 워크플로우 도구(Opal, n8n, Google AI Studio)의 개념과 특성 비교 - 의료기기 업무 프로세스 분석 및 워크플로우 설계 방법론 | J22: [IT 기본 개념] - 운영체제와 서버의 기본 개념 - 클라우드 인프라의 이해
A23: {{edu_guidegoaldetail-2}} | C23: [도구별 워크플로우 실습] - Opal을 활용한 Google 서비스 기반 업무 자동화 워크플로우 이해 - n8n을 활용한 AI 업무자동화 워크플로우 설계 및 구현 | J23: [데이터베이스와 개발 기초] - 데이터베이스 기초 개념 - 개발 관련 기초 지식 및 용어
A24: {{edu_guidegoaldetail-3}} | C24: [멀티모달 AI 앱 및 통합 워크플로우 구축] - Google AI Studio를 활용한 멀티모달 AI 워크플로우 앱 개발 - 의료기기 업무에 특화된 통합 AI 워크플로우 구축 및 발표 | J24: [생성형 AI와 LLM] - 생성형 AI의 개념과 원리 - LLM의 동작 원리 및 실제 사례
A25: {{edu_learnhow}} | B25: 교수학습방법 | C25: 강의: 슬라이드 및 의료기기 업무 자동화 사례 영상 자료를 활용하여 AI 워크플로우 도구의 개념과 설계 방법을 시각적으로 설명 실습: Opal·n8n·Google AI Studio를 직접 활용한 워크플로우 설계 및 구축 실습, 의료기기 업무 시나리오 기반 통합 프로젝트 수행 토론: 의료기기 업무 현장의 반복 프로세스 개선 방안에 대한 그룹 토론을 통해 실무 적용 능력 배양 Q&A: 실시간 질문을 통해 이해도 점검 및 피드백 제공 | J25: 강의: 슬라이드 및 영상 자료를 활용하여 시각적 이해를 돕고, 사례 중심으로 설명 실습: 간단한 클라우드 설정 및 데이터베이스 생성 실습 토론: 실제 사례에 기반한 토론을 통해 실무 적용 능력 배양 Q&A: 실시간 질문을 통해 이해도 점검 및 피드백 제공
A26: {{edu_testhow}} | B26: 평가방법 | C26: 가. 평가시점 : 교과목 수업 종료시 나. 평가내용 • AI 워크플로우 도구(n8n, Google AI Studio)의 기본 활용 능력 • 의료기기 업무 프로세스에 맞는 워크플로우 설계 능력 • 통합 AI 워크플로우 구축 및 발표 능력 다. 평가방법 • 결과평가 : 통합 워크플로우 구축 결과물 제출 및 구두발표 | J26: 가. 평가시점 : 교과목 수업 종료시 나. 평가내용 • 호텔 운영 프로그램에 대한 지식(Fidelio, Opera 등) • 객실 업셀링 능력 • 고객정보 검색 능력 및 활용 기술 다. 평가방법 • 결과평가 : 구두발표
A27: {{edu_book}} | B27: 훈련교재 | C27: 자체교재 | J27: 자체교재
A28: {{edu_future}} | B28: 연계 훈련과정 (해당 훈련과정의 중장기 체계적 운영의 적정성을 위한 레벨업 실시 계획) | C28: [Basic] Lv.1 - 의료·바이오 AI 리터러시 입문 Lv.2 - 의료·바이오 데이터리터러시와 데이터시각화 Lv.2 - AI 워크플로우 설계 기초 (본 과정) [Advance] Lv.3 - 의료기기 품질관리(QA)를 위한 AI 활용 Lv.3 - 의료기기 인허가(RA)를 위한 AI 활용 Lv.4 - 의료기기 R&D를 위한 AI 활용 Lv.5 - 의료기기 데이터 파이프라인 구축 및 운영 | J28: [Basic] Lv.1 - 기획자와 컨설턴트를 위한 AI개발의 이해 Lv.2 - 바이브코딩 이론 및 실습 Lv.2 - 웹서비스 배포 전략 및 클라우드 서비스의 이해 [Advance] Lv.3 - 데이터베이스 이해 및 실습 1 (MySQL) Lv.3 - 데이터베이스 이해 및 실습 2 (Supabase) Lv.3 - 데이터베이스 이해 및 실습 3 (Firebase) Lv.4 - 웹앱서비스운영전략 Lv.5 - 개발에서 배포 운영까지의 파이프라인 구축
A29: {{edu_needreason}} | B29: 사업 필요성&목적 | J29: 기획자들의 경우 개발자와의 커뮤니케이션에서 어려움을 겪는 경우가 많음, 또한 관련 직무의 수요조사 결과 관련된 교육의 필요성이 제기됨 본 과정은 이런 소통과 기획자의 직무에 필요한 IT관련 기초지식을 배양하여 직무관련 역량을 높이며, 바이브코딩을 통해 업무의 프로세스와 효율을 높일 수 있다
A30: {{edu_curri}} | B30: 커리큘럼 요약 | J30: LLM(예: ChatGPT, Claude)의 구조와 생성형 AI 패러다임을 이해하고, 의료·바이오 산업에서의 적용 가능성과 한계를 학습하며 기초 툴을 실습한다. 업무 전환을 위해 프롬프트의 기본 구조와 컨텍스트 설계, 페르소나 설정 및 출력 제어 방법을 익히고 직무별 적용 실습을 진행한다. 의료 AI 윤리, 개인정보 비식별화, 저작권 및 사내 보안 가이드라인을 학습하여 민감정보를 안전하게 처리하는 역량을 강화한다.
A31: {{edu_edutime}} | B31: 총시간(%) | C31: =F78&"시간 (100%)" -> 1시간 (100%)
A32: {{time_day_1}} | B32: 1일차 교육시간 | C32: =COUNTA(G82:G90) -> 1
A33: {{time_day_2}} | B33: 2일차 교육시간 | C33: =COUNTA(G92:G100) -> 0
A34: {{time_day_3}} | B34: 3일차 교육시간 | C34: =COUNTA(G102:G110) -> 0
A35: {{time_day_4}} | B35: 4일차 교육시간 | C35: =COUNTA(G112:G120) -> 0
A36: {{time_day_5}} | B36: 5일차 교육시간 | C36: =COUNTA(G122:G130) -> 0
A37: {{topic_day_1}} | B37: 1일차 교육내용 | C37: =K82 -> AI 워크플로우 도구(Opal, n8n, Google AI Studio)의 개념과 특성을 비교·이해한 후, 의료기기 업무 프로세스를 분석하여 AI 워크플로우를 설계하는 방법론을 학습한다. Opal을 활용한 Google 서비스 기반 업무 자동화, n8n을 활용한 AI 업무자동화 워크플로우 설계, Google AI Studio를 활용한 멀티모달 AI 앱 개발을 단계별로 실습한다. 최종적으로 의료기기 업무에 특화된 통합 AI 워크플로우를 직접 구축하는 프로젝트를 수행하고 결과를 발표하여 업무 프로세스 혁신 역량을 함양한다.
A38: {{topic_day_2}} | B38: 2일차 교육내용 | C38: =K92 -> 0
A39: {{topic_day_3}} | B39: 3일차 교육내용 | C39: =K102 -> 0
A40: {{topic_day_4}} | B40: 4일차 교육내용 | C40: =K112 -> 0
...

Sheet 4-ALX QA
A1: 커리큘럼 기초 내용
B2: 분류선택 | C2: 07.인공지능 > 07.생성형AI엔지니어링> 프롬프트 구현
A3: {{edu_title}} | B3: 훈련과정명 | C3: ISO 13485 기반 QMS 반복문서 AI 자동화 구현 (18h) | J3: 기획자와 컨설턴트를 위한 AI개발의 이해
B4: 커리큘럼 | C4: 1. ISO 13485 기반 QMS 반복문서 구조 이해 (SOP, CAPA, 내부감사) 2. ISO 요구사항–문서 항목 매핑 체계 설계 3. 생성형 AI 기반 QMS 문서 자동 생성 기초 (ChatGPT, Claude) 4. SOP 자동 작성 템플릿 설계 실습 (ChatGPT, Claude, Office for Claude) 5. CAPA 보고서 AI 구조화 및 자동 초안 생성 (Claude 중심, ChatGPT 보조) 6. 내부감사 체크리스트 및 문서 검증 체크리스트 자동 생성 (Claude + Excel/Google Sheet 연계) 7. 문서 작성–검증 자동 흐름 설계 (n8n 기반 자동화 기초) 8. 최종 산출물 완성: SOP 자동 템플릿, CAPA 자동화 구조, 감사 대응 체크리스트
A5: {{edu_cate01}} | B5: 대분류 | C5: =VLOOKUP($C$2,통합!A2:J52,2,FALSE) -> 20.정보통신
A6: {{edu_cate02}} | B6: 중분류 | C6: =VLOOKUP($C$2,통합!A2:J52,3,FALSE) -> 01.정보기술
A7: {{edu_cate03}} | B7: 소분류 | C7: =VLOOKUP($C$2,통합!A2:J52,4,FALSE) -> 07.인공지능
A8: {{edu_cate04}} | B8: 세분류 | C8: =VLOOKUP($C$2,통합!A2:J52,8,FALSE)&"."&VLOOKUP($C$2,통합!A2:J52,9,FALSE) -> 05.프롬프트 구현
A9: {{edu_cate05}} | B9: 훈련방법 | C9: =VLOOKUP($C$2,통합!A2:J52,7,FALSE) -> 2001070705_25v1
A10: {{edu_ncslevel}} | B10: 훈련수준 | C10: =VLOOKUP($C$2,통합!A2:J52,6,FALSE) -> 5
A11: {{edu_time}} | B11: 훈련시간 | C11: =F78&"시간( "&K131&"일)" -> 1시간( 3일) | J11: 000시간(00일)
A12: 교육과정 세부 정보
A13: {{edu_target}} | B13: 훈련대상자 | C13: 의료기기 개발·제조 기업의 품질관리(QA/QC) 담당자 및 품질경영시스템(QMS) 운영 관련 임직원 | J13: 기획자, 컨설턴트, 디자이너 등 개발과 AI에 이해가 필요한 직무
A14: {{edu_job}} | B14: 대상직종 | C14: 의료기기 품질관리(QA/QC), 품질경영시스템(QMS) 운영, 내부감사, 규제대응 등 | J14: 기획자
A15: {{edu_limit}} | B15: 정원 | C15: 20명 | J15: 00명
A16: {{edu_feature}} | B16: 훈련과정 특성 | C16: 의료기기 품질관리 담당자를 대상으로 ISO 13485 기반 QMS 반복문서(SOP, CAPA, 내부감사 문서)의 구조를 이해하고, 생성형 AI(ChatGPT, Claude)와 n8n을 활용하여 문서 자동 생성·검증 체계를 구축하는 AI 전환(AX) 심화 과정으로, 실제 QMS 문서 자동화 실습 중심의 교육을 통해 품질관리 업무 혁신 역량을 강화하는 신기술·융복합 훈련과정 | J16: 4차 산업혁명 등 관련된 신기술, 융복합, 미래전략산업 직종 과정 등 훈련과정의 특성 기재
A17: {{edu_summary}} | B17: 주요훈련내용 | C17: QMS 문서의 구조와 유형을 이해하고, ISO 13485 요구사항과 문서 항목 간 관계를 분석한다. ChatGPT를 활용한 프롬프트 기반 문서 생성 기법을 습득하고, 기존 QMS 문서를 프롬프트 설계를 통해 생성하는 실습을 진행한다. Office for Claude를 활용하여 문서 템플릿을 설계하고 문서 AI 자동화 체계를 구현하는 실습을 수행한다. 최종적으로 문서 작성부터 검증까지의 자동 흐름을 설계하여 QMS 문서 자동화 역량을 완성한다. | J17: 주요훈련내용을 요약해서 작성
A18: {{edu_ncsreason}} | B18: NCS 미적용 사유 | C18: 본 훈련과정은 의료기기 품질관리(QA) 현장의 QMS 문서 자동화 AI 전환(AX) 수요에 맞춰 ISO 13485 기반 문서 자동화 역량 강화를 목적으로 설계된 과정으로, 기존 NCS 분류체계에 정확히 부합하는 능력단위가 부재하여 산업 현장 맞춤형 커리큘럼으로 자체 구성함 | J18: 주요훈련내용을 요약해서 작성
A19: {{edu_goal}} | B19: 훈련목표 | C19: 의료기기 품질관리 담당자가 QMS 문서의 구조와 ISO 13485 요구사항을 이해하고, 프롬프트 기반 문서 생성(ChatGPT)과 문서 템플릿 설계 및 AI 자동화 구현(Office for Claude)을 통해 QMS 문서의 작성부터 검증까지 자동 흐름을 직접 설계·구축할 수 있는 QMS 문서 자동화 역량을 습득하는 것을 목표로 함 | J19: IT 기본 지식을 습득하고 개발자와 원활히 소통하며, 컨설팅 업무에 필요한 IT 전문 지식과 생성형 AI에 대한 이해를 높여 실무에 바로 적용할 수 있는 역량을 키우는 것을 목표로 함
A20: {{edu_guidegoal}} | B20: 지도목표 | C20: ISO 13485 기반 QMS 문서의 구조와 AI 활용 자동화 방법론을 명확히 이해하고, 실습을 통해 생성형 AI 기반 문서 자동 생성·검증 능력을 키워 의료기기 품질관리 업무 현장에서 반복문서 작성 시간을 획기적으로 단축하고 문서 품질을 향상시킬 수 있는 실무 역량을 갖추어 업무 효율성을 높입니다. | J20: IT 기본 개념을 명확히 이해하고, 실습을 통해 능력을 키워 최신 AI 기술을 활용한 실무 문제 해결 능력을 갖추어 업무의 효율성을 높입니다.
A21: {{edu_guidegoaldetail}} | B21: 세부 지도목표 | C21: * QMS 문서의 구조와 유형(SOP, CAPA, 내부감사 등) 이해 및 문서 작성 요건 분석 * ISO 13485 요구사항의 이해 및 문서 항목 간 매핑 체계 설계 능력 습득 * ChatGPT를 활용한 프롬프트 기반 QMS 문서 생성 기법 배양 * Office for Claude를 활용한 문서 템플릿 설계 실습 * Office for Claude를 활용한 문서 AI 자동화 설계 및 구현 실습 * 문서 작성–검증 자동 흐름 설계 역량 함양 | J21: * 운영체제, 서버, 클라우드 인프라의 기본 개념 설명 * 데이터베이스의 기초 지식과 데이터 관리 방법 이해 * 생성형 AI와 LLM의 원리 및 적용 사례 소개 * IT 용어와 개념을 쉽게 설명하고 실제 사례를 통해 이해 증진
A22: {{edu_guidegoaldetail-1}} | B22: 지도내용 | C22: [QMS 문서 및 ISO 13485 요구사항 이해] - QMS 문서의 구조와 유형(SOP, CAPA, 내부감사) 분석 및 작성 요건 이해 - ISO 13485 요구사항 분석 및 문서 항목 간 매핑 체계 설계 | J22: [IT 기본 개념] - 운영체제와 서버의 기본 개념 - 클라우드 인프라의 이해
A23: {{edu_guidegoaldetail-2}} | C23: [프롬프트 기반 문서 생성 및 템플릿 설계] - ChatGPT를 활용한 프롬프트 설계 기반 기존 QMS 문서 생성 실습 - Office for Claude를 활용한 문서 템플릿 설계 실습 | J23: [데이터베이스와 개발 기초] - 데이터베이스 기초 개념 - 개발 관련 기초 지식 및 용어
A24: {{edu_guidegoaldetail-3}} | C24: [문서 AI 자동화 구현 및 자동 흐름 설계] - Office for Claude를 활용한 문서 AI 자동화 설계 및 구현 실습 - 문서 작성–검증 자동 흐름 설계 및 최종 산출물 완성 | J24: [생성형 AI와 LLM] - 생성형 AI의 개념과 원리 - LLM의 동작 원리 및 실제 사례
A25: {{edu_learnhow}} | B25: 교수학습방법 | C25: 강의: 슬라이드 및 ISO 13485 QMS 문서 사례 자료를 활용하여 QMS 문서 구조와 ISO 요구사항, AI 자동화 방법론을 시각적으로 설명 실습: ChatGPT를 활용한 프롬프트 기반 문서 생성 실습, Office for Claude를 활용한 템플릿 설계 및 문서 AI 자동화 구현 실습, 문서 작성–검증 자동 흐름 설계, 최종 산출물 완성 프로젝트 수행 토론: 의료기기 품질관리 현장의 QMS 문서 자동화 적용 방안에 대한 그룹 토론을 통해 실무 적용 능력 배양 Q&A: 실시간 질문을 통해 이해도 점검 및 피드백 제공 | J25: 강의: 슬라이드 및 영상 자료를 활용하여 시각적 이해를 돕고, 사례 중심으로 설명 실습: 간단한 클라우드 설정 및 데이터베이스 생성 실습 토론: 실제 사례에 기반한 토론을 통해 실무 적용 능력 배양 Q&A: 실시간 질문을 통해 이해도 점검 및 피드백 제공
A26: {{edu_testhow}} | B26: 평가방법 | C26: 가. 평가시점 : 교과목 수업 종료시 나. 평가내용 • ChatGPT를 활용한 프롬프트 기반 QMS 문서 생성 능력 • Office for Claude를 활용한 문서 템플릿 설계 및 AI 자동화 구현 능력 • 문서 작성–검증 자동 흐름 설계 능력 다. 평가방법 • 결과평가 : 최종 산출물(문서 템플릿, AI 자동화 구현물, 자동 흐름 설계서) 제출 및 구두발표 | J26: 가. 평가시점 : 교과목 수업 종료시 나. 평가내용 • 호텔 운영 프로그램에 대한 지식(Fidelio, Opera 등) • 객실 업셀링 능력 • 고객정보 검색 능력 및 활용 기술 다. 평가방법 • 결과평가 : 구두발표
A27: {{edu_book}} | B27: 훈련교재 | C27: 자체교재 | J27: 자체교재
A28: {{edu_future}} | B28: 연계 훈련과정 (해당 훈련과정의 중장기 체계적 운영의 적정성을 위한 레벨업 실시 계획) | C28: [Basic] Lv.1 - 의료·바이오 AI 리터러시 입문 Lv.2 - 의료·바이오 데이터리터러시와 데이터시각화 Lv.2 - AI 워크플로우 설계 기초 [Advance] Lv.3 - ISO 13485 기반 QMS 반복문서 AI 자동화 구현 (본 과정) Lv.3 - 의료기기 인허가(RA)를 위한 AI 활용 Lv.4 - 의료기기 R&D를 위한 AI 활용 Lv.5 - 의료기기 데이터 파이프라인 구축 및 운영 | J28: [Basic] Lv.1 - 기획자와 컨설턴트를 위한 AI개발의 이해 Lv.2 - 바이브코딩 이론 및 실습 Lv.2 - 웹서비스 배포 전략 및 클라우드 서비스의 이해 [Advance] Lv.3 - 데이터베이스 이해 및 실습 1 (MySQL) Lv.3 - 데이터베이스 이해 및 실습 2 (Supabase) Lv.3 - 데이터베이스 이해 및 실습 3 (Firebase) Lv.4 - 웹앱서비스운영전략 Lv.5 - 개발에서 배포 운영까지의 파이프라인 구축
A29: {{edu_needreason}} | B29: 사업 필요성&목적 | J29: 기획자들의 경우 개발자와의 커뮤니케이션에서 어려움을 겪는 경우가 많음, 또한 관련 직무의 수요조사 결과 관련된 교육의 필요성이 제기됨 본 과정은 이런 소통과 기획자의 직무에 필요한 IT관련 기초지식을 배양하여 직무관련 역량을 높이며, 바이브코딩을 통해 업무의 프로세스와 효율을 높일 수 있다
A30: {{edu_curri}} | B30: 커리큘럼 요약 | J30: LLM(예: ChatGPT, Claude)의 구조와 생성형 AI 패러다임을 이해하고, 의료·바이오 산업에서의 적용 가능성과 한계를 학습하며 기초 툴을 실습한다. 업무 전환을 위해 프롬프트의 기본 구조와 컨텍스트 설계, 페르소나 설정 및 출력 제어 방법을 익히고 직무별 적용 실습을 진행한다. 의료 AI 윤리, 개인정보 비식별화, 저작권 및 사내 보안 가이드라인을 학습하여 민감정보를 안전하게 처리하는 역량을 강화한다.
A31: {{edu_edutime}} | B31: 총시간(%) | C31: =F78&"시간 (100%)" -> 1시간 (100%)
A32: {{time_day_1}} | B32: 1일차 교육시간 | C32: =COUNTA(G82:G90) -> 1
A33: {{time_day_2}} | B33: 2일차 교육시간 | C33: =COUNTA(G92:G100) -> 0
A34: {{time_day_3}} | B34: 3일차 교육시간 | C34: =COUNTA(G102:G110) -> 0
A35: {{time_day_4}} | B35: 4일차 교육시간 | C35: =COUNTA(G112:G120) -> 0
A36: {{time_day_5}} | B36: 5일차 교육시간 | C36: =COUNTA(G122:G130) -> 0
A37: {{topic_day_1}} | B37: 1일차 교육내용 | C37: =K82 -> QMS 문서의 유형(SOP, CAPA, 내부감사 등)과 구조를 분석하고, 각 문서 유형별 작성 요건과 실무에서의 문서 작성 흐름을 이해한다. ISO 13485 요구사항의 핵심 조항을 분석·해설하고, ISO 요구사항과 문서 항목 간 매핑 체계를 직접 설계하는 실습을 진행한다. 매핑 결과를 검토하고 실제 문서에 적용하는 토론을 통해 QMS 문서 자동화의 기반을 다진다.
A38: {{topic_day_2}} | B38: 2일차 교육내용 | C38: =K92 -> ChatGPT를 활용한 프롬프트 설계의 원리와 기법을 학습하고, 기존 QMS 문서(SOP, CAPA 등)를 프롬프트 설계를 통해 생성하는 실습을 진행한다. 생성된 문서의 품질을 검토하고 프롬프트를 최적화하는 심화 실습 후, Office for Claude를 활용하여 SOP·CAPA 문서 템플릿을 직접 설계하는 실습을 수행하여 프롬프트 기반 문서 생성과 템플릿화 능력을 함양한다.
A39: {{topic_day_3}} | B39: 3일차 교육내용 | C39: =K102 -> Office for Claude를 활용하여 문서 AI 자동화 체계를 설계하고 문서 자동 생성·검증 기능을 구현하는 실습을 진행한다. 문서 작성부터 검증까지의 전체 프로세스를 통합한 자동 흐름을 설계하고, 3일간의 학습 내용을 종합하여 문서 템플릿, AI 자동화 구현물, 자동 흐름 설계서를 최종 산출물로 완성한다. 팀별 발표와 피드백을 통해 현업 적용 전략을 수립한다.
A40: {{topic_day_4}} | B40: 4일차 교육내용 | C40: =K112 -> 0
...

Sheet 5-ALX RA
A1: 커리큘럼 기초 내용
B2: 분류선택 | C2: 07.인공지능 > 07.생성형AI엔지니어링> 프롬프트 구현
A3: {{edu_title}} | B3: 훈련과정명 | C3: 규제·인허가 AI 자동화 실무 (18h) | J3: 기획자와 컨설턴트를 위한 AI개발의 이해
B4: 커리큘럼 | C4: 1. 생성형 AI로 규정 문서 핵심 빠르게 파악하기 (ChatGPT) 2. AI 기반 규제 요구사항 구조화 및 체크리스트 자동 생성 (ChatGPT, Claude Cowork, Excel for Claude) 3. 기술문서(TD) 초안 자동 작성 및 템플릿화 (ChatGPT, Claude) 4. 기존 문서–최신 규정 비교 및 Gap 자동 도출 (Excel for Claude) 5. Deficiency 대응 문장 자동 생성 (ChatGPT) 6. 규정 변경 영향 분석 자동화 (Claude Cowork, Excel for Claude, n8n) 7. RA 업무 AI 워크플로 설계 및 템플릿 구축 (ChatGPT, Claude Cowork, n8n)
A5: {{edu_cate01}} | B5: 대분류 | C5: =VLOOKUP($C$2,통합!A2:J52,2,FALSE) -> 20.정보통신
A6: {{edu_cate02}} | B6: 중분류 | C6: =VLOOKUP($C$2,통합!A2:J52,3,FALSE) -> 01.정보기술
A7: {{edu_cate03}} | B7: 소분류 | C7: =VLOOKUP($C$2,통합!A2:J52,4,FALSE) -> 07.인공지능
A8: {{edu_cate04}} | B8: 세분류 | C8: =VLOOKUP($C$2,통합!A2:J52,8,FALSE)&"."&VLOOKUP($C$2,통합!A2:J52,9,FALSE) -> 05.프롬프트 구현
A9: {{edu_cate05}} | B9: 훈련방법 | C9: =VLOOKUP($C$2,통합!A2:J52,7,FALSE) -> 2001070705_25v1
A10: {{edu_ncslevel}} | B10: 훈련수준 | C10: =VLOOKUP($C$2,통합!A2:J52,6,FALSE) -> 5
A11: {{edu_time}} | B11: 훈련시간 | C11: =F78&"시간( "&K131&"일)" -> 1시간( 3일) | J11: 000시간(00일)
A12: 교육과정 세부 정보
A13: {{edu_target}} | B13: 훈련대상자 | C13: 의료기기 개발·제조 기업의 인허가(RA) 담당자 및 규제대응 관련 임직원 | J13: 기획자, 컨설턴트, 디자이너 등 개발과 AI에 이해가 필요한 직무
A14: {{edu_job}} | B14: 대상직종 | C14: 의료기기 인허가(RA), 규제대응, 기술문서(TD) 작성, 품질관리(QA) 등 | J14: 기획자
A15: {{edu_limit}} | B15: 정원 | C15: 20명 | J15: 00명
A16: {{edu_feature}} | B16: 훈련과정 특성 | C16: 의료기기 인허가(RA) 담당자를 대상으로 생성형 AI(ChatGPT, Claude)를 활용하여 규정 문서 분석, 규제 요구사항 체크리스트 자동 생성, 기술문서(TD) 초안 자동 작성, 기존 문서와 최신 규정 간 Gap 분석, Deficiency 대응 문장 자동 생성, 규정 변경 영향 분석 자동화, RA 업무 AI 워크플로 설계까지 다루는 AI 전환(AX) 심화 과정으로, 실제 RA 업무 시나리오 기반 실습 중심의 교육을 통해 인허가 업무 혁신 역량을 강화하는 신기술·융복합 훈련과정 | J16: 4차 산업혁명 등 관련된 신기술, 융복합, 미래전략산업 직종 과정 등 훈련과정의 특성 기재
A17: {{edu_summary}} | B17: 주요훈련내용 | C17: 생성형 AI(ChatGPT)로 규정 문서의 핵심을 빠르게 파악하는 방법을 학습하고, ChatGPT·Claude Cowork·Excel for Claude를 활용하여 규제 요구사항을 구조화하고 체크리스트를 자동 생성한다. 기술문서(TD) 초안 자동 작성 및 템플릿화를 실습하고, Excel for Claude를 활용하여 기존 문서와 최신 규정 간 Gap을 자동 도출한다. ChatGPT를 활용한 Deficiency 대응 문장 자동 생성, Claude Cowork·Excel for Claude·n8n을 활용한 규정 변경 영향 분석 자동화를 실습하며, 최종적으로 RA 업무 전반의 AI 워크플로를 설계하고 템플릿을 구축한다. | J17: 주요훈련내용을 요약해서 작성
A18: {{edu_ncsreason}} | B18: NCS 미적용 사유 | C18: 본 훈련과정은 의료기기 인허가(RA) 현장의 규제 문서 자동화 AI 전환(AX) 수요에 맞춰 RA 업무 전반의 AI 활용 역량 강화를 목적으로 설계된 과정으로, 기존 NCS 분류체계에 정확히 부합하는 능력단위가 부재하여 산업 현장 맞춤형 커리큘럼으로 자체 구성함 | J18: 주요훈련내용을 요약해서 작성
A19: {{edu_goal}} | B19: 훈련목표 | C19: 의료기기 인허가(RA) 담당자가 생성형 AI(ChatGPT, Claude)와 자동화 도구(Excel for Claude, Claude Cowork, n8n)를 활용하여 규정 문서 분석, 규제 체크리스트 자동 생성, 기술문서(TD) 초안 작성, Gap 분석, Deficiency 대응, 규정 변경 영향 분석, RA 업무 워크플로 설계까지 인허가 업무 전 과정에 AI를 효과적으로 적용할 수 있는 실무 역량을 습득하는 것을 목표로 함 | J19: IT 기본 지식을 습득하고 개발자와 원활히 소통하며, 컨설팅 업무에 필요한 IT 전문 지식과 생성형 AI에 대한 이해를 높여 실무에 바로 적용할 수 있는 역량을 키우는 것을 목표로 함
A20: {{edu_guidegoal}} | B20: 지도목표 | C20: 의료기기 규제·인허가 업무의 AI 활용 자동화 방법론을 명확히 이해하고, 실습을 통해 생성형 AI 기반 규제 문서 분석·작성·검증 능력을 키워 RA 업무 현장에서 반복적인 규제 대응 업무 시간을 획기적으로 단축하고 문서 정확성을 향상시킬 수 있는 실무 문제 해결 능력을 갖추어 업무 효율성을 높입니다. | J20: IT 기본 개념을 명확히 이해하고, 실습을 통해 능력을 키워 최신 AI 기술을 활용한 실무 문제 해결 능력을 갖추어 업무의 효율성을 높입니다.
A21: {{edu_guidegoaldetail}} | B21: 세부 지도목표 | C21: * 생성형 AI(ChatGPT)를 활용한 규정 문서 핵심 파악 및 분석 능력 배양 * AI 기반 규제 요구사항 구조화 및 체크리스트 자동 생성 기법 습득 * 기술문서(TD) 초안 자동 작성 및 템플릿화 실습 * 기존 문서와 최신 규정 간 Gap 자동 도출 능력 강화 * Deficiency 대응 문장 자동 생성 및 규정 변경 영향 분석 자동화 실습 * RA 업무 AI 워크플로 설계 및 템플릿 구축 역량 함양 | J21: * 운영체제, 서버, 클라우드 인프라의 기본 개념 설명 * 데이터베이스의 기초 지식과 데이터 관리 방법 이해 * 생성형 AI와 LLM의 원리 및 적용 사례 소개 * IT 용어와 개념을 쉽게 설명하고 실제 사례를 통해 이해 증진
A22: {{edu_guidegoaldetail-1}} | B22: 지도내용 | C22: [규정 문서 AI 분석과 규제 체크리스트 자동화] - 생성형 AI(ChatGPT)를 활용한 규정 문서 핵심 파악 및 분석 - AI 기반 규제 요구사항 구조화 및 체크리스트 자동 생성 | J22: [IT 기본 개념] - 운영체제와 서버의 기본 개념 - 클라우드 인프라의 이해
A23: {{edu_guidegoaldetail-2}} | C23: [TD 자동 작성 및 Gap·Deficiency 대응] - 기술문서(TD) 초안 자동 작성 및 템플릿화 실습 - 기존 문서–최신 규정 Gap 자동 도출 및 Deficiency 대응 문장 생성 | J23: [데이터베이스와 개발 기초] - 데이터베이스 기초 개념 - 개발 관련 기초 지식 및 용어
A24: {{edu_guidegoaldetail-3}} | C24: [규정 변경 영향 분석 및 RA 워크플로 구축] - 규정 변경 영향 분석 자동화 (Claude Cowork, Excel for Claude, n8n) - RA 업무 AI 워크플로 설계 및 템플릿 구축 | J24: [생성형 AI와 LLM] - 생성형 AI의 개념과 원리 - LLM의 동작 원리 및 실제 사례
A25: {{edu_learnhow}} | B25: 교수학습방법 | C25: 강의: 슬라이드 및 의료기기 인허가 규제 사례 자료를 활용하여 RA 업무 AI 자동화 방법론을 시각적으로 설명 실습: ChatGPT·Claude·Excel for Claude·Claude Cowork를 활용한 규정 분석·TD 초안 작성·Gap 도출·Deficiency 대응·규정 변경 영향 분석 실습, n8n 기반 RA 워크플로 설계 실습, 최종 템플릿 구축 프로젝트 수행 토론: 의료기기 인허가 현장의 규제 대응 AI 활용 방안에 대한 그룹 토론을 통해 실무 적용 능력 배양 Q&A: 실시간 질문을 통해 이해도 점검 및 피드백 제공 | J25: 강의: 슬라이드 및 영상 자료를 활용하여 시각적 이해를 돕고, 사례 중심으로 설명 실습: 간단한 클라우드 설정 및 데이터베이스 생성 실습 토론: 실제 사례에 기반한 토론을 통해 실무 적용 능력 배양 Q&A: 실시간 질문을 통해 이해도 점검 및 피드백 제공
A26: {{edu_testhow}} | B26: 평가방법 | C26: 가. 평가시점 : 교과목 수업 종료시 나. 평가내용 • 생성형 AI(ChatGPT, Claude)를 활용한 규제 문서 분석 및 자동 작성 능력 • 기술문서(TD) 초안 자동 작성 및 Gap 분석 능력 • RA 업무 AI 워크플로 설계 및 템플릿 구축 능력 다. 평가방법 • 결과평가 : 최종 산출물(RA 워크플로 설계서, TD 템플릿, 규제 체크리스트) 제출 및 구두발표 | J26: 가. 평가시점 : 교과목 수업 종료시 나. 평가내용 • 호텔 운영 프로그램에 대한 지식(Fidelio, Opera 등) • 객실 업셀링 능력 • 고객정보 검색 능력 및 활용 기술 다. 평가방법 • 결과평가 : 구두발표
A27: {{edu_book}} | B27: 훈련교재 | C27: 자체교재 | J27: 자체교재
A28: {{edu_future}} | B28: 연계 훈련과정 (해당 훈련과정의 중장기 체계적 운영의 적정성을 위한 레벨업 실시 계획) | C28: [Basic] Lv.1 - 의료·바이오 AI 리터러시 입문 Lv.2 - 의료·바이오 데이터리터러시와 데이터시각화 Lv.2 - AI 워크플로우 설계 기초 [Advance] Lv.3 - ISO 13485 기반 QMS 반복문서 AI 자동화 구현 Lv.3 - 규제·인허가 AI 자동화 실무 (본 과정) Lv.4 - 의료기기 R&D를 위한 AI 활용 Lv.5 - 의료기기 데이터 파이프라인 구축 및 운영 | J28: [Basic] Lv.1 - 기획자와 컨설턴트를 위한 AI개발의 이해 Lv.2 - 바이브코딩 이론 및 실습 Lv.2 - 웹서비스 배포 전략 및 클라우드 서비스의 이해 [Advance] Lv.3 - 데이터베이스 이해 및 실습 1 (MySQL) Lv.3 - 데이터베이스 이해 및 실습 2 (Supabase) Lv.3 - 데이터베이스 이해 및 실습 3 (Firebase) Lv.4 - 웹앱서비스운영전략 Lv.5 - 개발에서 배포 운영까지의 파이프라인 구축
A29: {{edu_needreason}} | B29: 사업 필요성&목적 | J29: 기획자들의 경우 개발자와의 커뮤니케이션에서 어려움을 겪는 경우가 많음, 또한 관련 직무의 수요조사 결과 관련된 교육의 필요성이 제기됨 본 과정은 이런 소통과 기획자의 직무에 필요한 IT관련 기초지식을 배양하여 직무관련 역량을 높이며, 바이브코딩을 통해 업무의 프로세스와 효율을 높일 수 있다
A30: {{edu_curri}} | B30: 커리큘럼 요약 | J30: LLM(예: ChatGPT, Claude)의 구조와 생성형 AI 패러다임을 이해하고, 의료·바이오 산업에서의 적용 가능성과 한계를 학습하며 기초 툴을 실습한다. 업무 전환을 위해 프롬프트의 기본 구조와 컨텍스트 설계, 페르소나 설정 및 출력 제어 방법을 익히고 직무별 적용 실습을 진행한다. 의료 AI 윤리, 개인정보 비식별화, 저작권 및 사내 보안 가이드라인을 학습하여 민감정보를 안전하게 처리하는 역량을 강화한다.
A31: {{edu_edutime}} | B31: 총시간(%) | C31: =F78&"시간 (100%)" -> 1시간 (100%)
A32: {{time_day_1}} | B32: 1일차 교육시간 | C32: =COUNTA(G82:G90) -> 1
A33: {{time_day_2}} | B33: 2일차 교육시간 | C33: =COUNTA(G92:G100) -> 0
A34: {{time_day_3}} | B34: 3일차 교육시간 | C34: =COUNTA(G102:G110) -> 0
A35: {{time_day_4}} | B35: 4일차 교육시간 | C35: =COUNTA(G112:G120) -> 0
A36: {{time_day_5}} | B36: 5일차 교육시간 | C36: =COUNTA(G122:G130) -> 0
A37: {{topic_day_1}} | B37: 1일차 교육내용 | C37: =K82 -> ChatGPT를 활용하여 의료기기 규정 문서의 핵심을 빠르게 파악하는 방법을 학습하고, 주요 규제 요구사항을 추출·요약하는 실습을 진행한다. ChatGPT와 Claude Cowork를 활용하여 규제 요구사항을 구조화하고, Excel for Claude를 활용하여 체크리스트를 자동 생성하는 실습을 수행한다. 오후에는 기술문서(TD) 초안 자동 작성과 템플릿화의 기초를 실습하여 규제 문서 AI 자동화의 토대를 다진다.
A38: {{topic_day_2}} | B38: 2일차 교육내용 | C38: =K92 -> Excel for Claude를 활용하여 기존 문서와 최신 규정 간 Gap을 자동으로 도출하는 방법을 학습하고, 실제 의료기기 규정 변경 사례를 적용한 Gap 분석 실습을 진행한다. ChatGPT를 활용한 Deficiency 대응 문장 자동 생성을 기초부터 실제 심사 지적 사례까지 심화 실습하며, Claude Cowork·Excel for Claude·n8n을 활용한 규정 변경 영향 분석 자동화의 설계와 기초 연계 실습을 수행한다.
A39: {{topic_day_3}} | B39: 3일차 교육내용 | C39: =K102 -> ChatGPT·Claude Cowork·n8n을 활용하여 RA 업무 전반의 AI 워크플로를 설계하고, n8n 기반 업무 자동화 파이프라인을 구축하는 실습을 진행한다. 3일간의 학습 내용을 종합하여 TD 템플릿, 규제 체크리스트, RA 워크플로 설계서를 최종 산출물로 완성하고 팀별 발표를 통해 결과를 공유한다. 종합 피드백과 함께 현업에서의 RA AI 자동화 적용 전략을 수립한다.
A40: {{topic_day_4}} | B40: 4일차 교육내용 | C40: =K112 -> 0
...

Sheet 6-ALX R&D
A1: 커리큘럼 기초 내용
B2: 분류선택 | C2: 07.인공지능 > 07.생성형AI엔지니어링> 프롬프트 구현
A3: {{edu_title}} | B3: 훈련과정명 | C3: 의료기기 연구개발 설계 관리 AX 실습 과정 (18h) | J3: 기획자와 컨설턴트를 위한 AI개발의 이해
B4: 커리큘럼 | C4: 1. 생성형 AI 협업 환경을 위한 설계관리 전주기 이해 ( IEC 62304·ISO 14971 등 ) 2. AI로 요구사항(URS) 구조화 및 자동 도출 (Claude, ChatGPT, Claude Cowork) 3. 요구사항 기반 SRS 초안 자동 생성 및 문서 일관성·논리 검증 (ChatGPT, Claude) 4. 요구사항을 검증 가능한 테스트 케이스로 자동 변환 및 표준 문서 출력 (ChatGPT, Excel, Google AI Studio) 5. 설계 변경 시 영향 받는 요구·테스트·위험 항목 자동 식별 및 알림 설계 (Claude Code, ChatGPT, Claude Cowork, n8n ) 6. 요구–설계–검증–위험 간 Traceability 매트릭스 자동 생성 및 누락 탐지 (Claude Code, ChatGPT, Excel, Google AI Studio) 7. 설계 입력부터 변경관리까지 연결된 AI 기반 설계관리 워크플로 통합 설계 (ChatGPT, Claude Code, Claude Cowork, n8n)
A5: {{edu_cate01}} | B5: 대분류 | C5: =VLOOKUP($C$2,통합!A2:J52,2,FALSE) -> 20.정보통신
A6: {{edu_cate02}} | B6: 중분류 | C6: =VLOOKUP($C$2,통합!A2:J52,3,FALSE) -> 01.정보기술
A7: {{edu_cate03}} | B7: 소분류 | C7: =VLOOKUP($C$2,통합!A2:J52,4,FALSE) -> 07.인공지능
A8: {{edu_cate04}} | B8: 세분류 | C8: =VLOOKUP($C$2,통합!A2:J52,8,FALSE)&"."&VLOOKUP($C$2,통합!A2:J52,9,FALSE) -> 05.프롬프트 구현
A9: {{edu_cate05}} | B9: 훈련방법 | C9: =VLOOKUP($C$2,통합!A2:J52,7,FALSE) -> 2001070705_25v1
A10: {{edu_ncslevel}} | B10: 훈련수준 | C10: =VLOOKUP($C$2,통합!A2:J52,6,FALSE) -> 5
A11: {{edu_time}} | B11: 훈련시간 | C11: =F78&"시간( "&K131&"일)" -> 1시간( 3일) | J11: 000시간(00일)
A12: 교육과정 세부 정보
A13: {{edu_target}} | B13: 훈련대상자 | C13: 의료기기 개발·제조 기업의 연구개발(R&D) 담당자 및 설계관리(Design Controls) 관련 임직원 | J13: 기획자, 컨설턴트, 디자이너 등 개발과 AI에 이해가 필요한 직무
A14: {{edu_job}} | B14: 대상직종 | C14: 의료기기 연구개발(R&D), 설계관리, 소프트웨어 개발, 위험관리, V&V 등 | J14: 기획자
A15: {{edu_limit}} | B15: 정원 | C15: 20명 | J15: 00명
A16: {{edu_feature}} | B16: 훈련과정 특성 | C16: 의료기기 R&D 담당자를 대상으로 IEC 62304·ISO 14971 기반 설계관리 전주기를 이해하고, 생성형 AI(ChatGPT, Claude, Claude Cowork, Claude Code)와 자동화 도구(Excel, n8n, Google AI Studio)를 활용하여 URS 구조화·SRS 자동 생성·TC 자동 변환·ECO 변경 영향 자동 식별·Traceability 자동 생성까지 설계관리 전 과정의 AI 자동화를 실습하고, 설계 입력부터 변경관리까지 연결된 AI 워크플로를 통합 설계하는 AI 전환(AX) 심화 과정으로, 실제 R&D 업무 시나리오 기반 실습 중심의 신기술·융복합 훈련과정 | J16: 4차 산업혁명 등 관련된 신기술, 융복합, 미래전략산업 직종 과정 등 훈련과정의 특성 기재
A17: {{edu_summary}} | B17: 주요훈련내용 | C17: 생성형 AI 협업 환경에서의 설계관리 전주기(IEC 62304·ISO 14971)를 이해한 후, Claude·ChatGPT·Claude Cowork를 활용하여 자연어 요구사항을 구조화된 URS로 자동 변환하고 SRS 초안을 자동 생성하며 문서 일관성·논리를 검증한다. ChatGPT·Excel·Google AI Studio를 활용하여 요구사항을 테스트 케이스로 자동 변환하고 표준 문서로 출력하며, Claude Code·n8n을 활용하여 설계 변경 시 영향 항목을 자동 식별하고 알림 체계를 설계한다. Traceability 매트릭스를 AI로 자동 생성하여 누락을 탐지하고, 최종적으로 설계 입력부터 변경관리까지 연결된 AI 기반 설계관리 워크플로를 통합 설계한다. | J17: 주요훈련내용을 요약해서 작성
A18: {{edu_ncsreason}} | B18: NCS 미적용 사유 | C18: 본 훈련과정은 의료기기 R&D 현장의 설계관리(Design Controls) AI 전환(AX) 수요에 맞춰 설계관리 프로세스 전반의 AI 자동화 역량 강화를 목적으로 설계된 과정으로, 기존 NCS 분류체계에 정확히 부합하는 능력단위가 부재하여 산업 현장 맞춤형 커리큘럼으로 자체 구성함 | J18: 주요훈련내용을 요약해서 작성
A19: {{edu_goal}} | B19: 훈련목표 | C19: 의료기기 R&D 담당자가 생성형 AI 협업 환경(ChatGPT, Claude, Claude Cowork, Claude Code)을 활용하여 설계관리 전주기(URS 구조화→SRS 자동 생성→TC 자동 변환→ECO 변경 영향 자동 식별→Traceability 자동 생성)를 AI로 수행하고, n8n·Google AI Studio 기반으로 설계 입력부터 변경관리까지 연결된 통합 워크플로를 직접 설계·구축할 수 있는 설계관리 AX 실무 역량을 습득하는 것을 목표로 함 | J19: IT 기본 지식을 습득하고 개발자와 원활히 소통하며, 컨설팅 업무에 필요한 IT 전문 지식과 생성형 AI에 대한 이해를 높여 실무에 바로 적용할 수 있는 역량을 키우는 것을 목표로 함
A20: {{edu_guidegoal}} | B20: 지도목표 | C20: 의료기기 설계관리 전주기의 구조를 이해하고, ChatGPT·Claude·Claude Cowork·Claude Code를 활용한 실습을 통해 URS 구조화·SRS 생성·TC 변환·ECO 영향 식별·Traceability 구축 능력을 키워, R&D 업무 현장에서 설계관리 문서화와 검증 시간을 획기적으로 단축하고 AI 기반 통합 워크플로 설계 능력을 갖추어 업무 효율성을 높입니다. | J20: IT 기본 개념을 명확히 이해하고, 실습을 통해 능력을 키워 최신 AI 기술을 활용한 실무 문제 해결 능력을 갖추어 업무의 효율성을 높입니다.
A21: {{edu_guidegoaldetail}} | B21: 세부 지도목표 | C21: * 생성형 AI 협업 환경에서의 설계관리 전주기(IEC 62304·ISO 14971) 구조 이해 * Claude·ChatGPT·Claude Cowork를 활용한 URS 구조화 및 자동 도출 실습 * ChatGPT·Claude를 활용한 SRS 초안 자동 생성 및 문서 일관성·논리 검증 실습 * ChatGPT·Excel·Google AI Studio를 활용한 TC 자동 변환 및 표준 문서 출력 실습 * Claude Code·ChatGPT·n8n을 활용한 ECO 변경 영향 자동 식별 및 알림 설계 실습 * Traceability 매트릭스 AI 자동 생성·누락 탐지 및 AI 기반 설계관리 워크플로 통합 설계 역량 함양 | J21: * 운영체제, 서버, 클라우드 인프라의 기본 개념 설명 * 데이터베이스의 기초 지식과 데이터 관리 방법 이해 * 생성형 AI와 LLM의 원리 및 적용 사례 소개 * IT 용어와 개념을 쉽게 설명하고 실제 사례를 통해 이해 증진
A22: {{edu_guidegoaldetail-1}} | B22: 지도내용 | C22: [설계관리 전주기 이해 및 AI 기반 URS 구조화·SRS 자동 생성] - 생성형 AI 협업 환경에서의 설계관리 전주기(IEC 62304·ISO 14971) 구조 이해 - Claude·ChatGPT·Claude Cowork로 URS 자동 구조화 및 SRS 초안 자동 생성·검증 실습 | J22: [IT 기본 개념] - 운영체제와 서버의 기본 개념 - 클라우드 인프라의 이해
A23: {{edu_guidegoaldetail-2}} | C23: [TC 자동 변환·ECO 변경 영향 자동 식별 실습] - ChatGPT·Excel·Google AI Studio를 활용한 TC 자동 변환 및 표준 문서 출력 실습 - Claude Code·ChatGPT·Claude Cowork·n8n을 활용한 ECO 변경 영향 자동 식별 및 알림 설계 | J23: [데이터베이스와 개발 기초] - 데이터베이스 기초 개념 - 개발 관련 기초 지식 및 용어
A24: {{edu_guidegoaldetail-3}} | C24: [Traceability 자동 생성 및 AI 워크플로 통합 설계] - Claude Code·ChatGPT·Excel·Google AI Studio로 Traceability 매트릭스 자동 생성 및 누락 탐지 - 설계 입력~변경관리 연결 AI 기반 설계관리 워크플로 통합 설계 (ChatGPT, Claude Code, Claude Cowork, n8n) | J24: [생성형 AI와 LLM] - 생성형 AI의 개념과 원리 - LLM의 동작 원리 및 실제 사례
A25: {{edu_learnhow}} | B25: 교수학습방법 | C25: 강의: 슬라이드 및 의료기기 설계관리 사례 자료를 활용하여 IEC 62304·ISO 14971 기반 설계관리 전주기와 AI 협업 환경을 시각적으로 설명 실습: Claude·ChatGPT·Claude Cowork로 URS 구조화 및 SRS 자동 생성, ChatGPT·Excel·Google AI Studio로 TC 자동 변환, Claude Code·n8n으로 ECO 변경 영향 자동 식별 및 알림 설계, Traceability 매트릭스 AI 자동 생성, 설계관리 AI 워크플로 통합 설계 실습, 최종 산출물 완성 프로젝트 수행 토론: 의료기기 R&D 현장의 설계관리 AI 전환 적용 방안에 대한 그룹 토론을 통해 실무 적용 능력 배양 Q&A: 실시간 질문을 통해 이해도 점검 및 피드백 제공 | J25: 강의: 슬라이드 및 영상 자료를 활용하여 시각적 이해를 돕고, 사례 중심으로 설명 실습: 간단한 클라우드 설정 및 데이터베이스 생성 실습 토론: 실제 사례에 기반한 토론을 통해 실무 적용 능력 배양 Q&A: 실시간 질문을 통해 이해도 점검 및 피드백 제공
A26: {{edu_testhow}} | B26: 평가방법 | C26: 가. 평가시점 : 교과목 수업 종료시 나. 평가내용 • Claude·ChatGPT·Claude Cowork를 활용한 URS 구조화 및 SRS 자동 생성 능력 • ChatGPT·Excel·Google AI Studio를 활용한 TC 자동 변환 및 ECO 변경 영향 자동 식별 능력 • Traceability 매트릭스 AI 자동 생성 및 AI 기반 설계관리 워크플로 통합 설계 능력 다. 평가방법 • 결과평가 : 최종 산출물(설계관리 전주기 AI 자동화 결과물 및 통합 워크플로 설계서) 제출 및 구두발표 | J26: 가. 평가시점 : 교과목 수업 종료시 나. 평가내용 • 호텔 운영 프로그램에 대한 지식(Fidelio, Opera 등) • 객실 업셀링 능력 • 고객정보 검색 능력 및 활용 기술 다. 평가방법 • 결과평가 : 구두발표
A27: {{edu_book}} | B27: 훈련교재 | C27: 자체교재 | J27: 자체교재
A28: {{edu_future}} | B28: 연계 훈련과정 (해당 훈련과정의 중장기 체계적 운영의 적정성을 위한 레벨업 실시 계획) | C28: [Basic] Lv.1 - 의료·바이오 AI 리터러시 입문 Lv.2 - 의료·바이오 데이터리터러시와 데이터시각화 Lv.2 - AI 워크플로우 설계 기초 [Advance] Lv.3 - ISO 13485 기반 QMS 반복문서 AI 자동화 구현 Lv.3 - 규제·인허가 AI 자동화 실무 Lv.4 - 의료기기 설계관리(Design Controls) AI 자동화 실습 (본 과정) Lv.5 - 의료기기 데이터 파이프라인 구축 및 운영 | J28: [Basic] Lv.1 - 기획자와 컨설턴트를 위한 AI개발의 이해 Lv.2 - 바이브코딩 이론 및 실습 Lv.2 - 웹서비스 배포 전략 및 클라우드 서비스의 이해 [Advance] Lv.3 - 데이터베이스 이해 및 실습 1 (MySQL) Lv.3 - 데이터베이스 이해 및 실습 2 (Supabase) Lv.3 - 데이터베이스 이해 및 실습 3 (Firebase) Lv.4 - 웹앱서비스운영전략 Lv.5 - 개발에서 배포 운영까지의 파이프라인 구축
A29: {{edu_needreason}} | B29: 사업 필요성&목적 | J29: 기획자들의 경우 개발자와의 커뮤니케이션에서 어려움을 겪는 경우가 많음, 또한 관련 직무의 수요조사 결과 관련된 교육의 필요성이 제기됨 본 과정은 이런 소통과 기획자의 직무에 필요한 IT관련 기초지식을 배양하여 직무관련 역량을 높이며, 바이브코딩을 통해 업무의 프로세스와 효율을 높일 수 있다
A30: {{edu_curri}} | B30: 커리큘럼 요약 | J30: LLM(예: ChatGPT, Claude)의 구조와 생성형 AI 패러다임을 이해하고, 의료·바이오 산업에서의 적용 가능성과 한계를 학습하며 기초 툴을 실습한다. 업무 전환을 위해 프롬프트의 기본 구조와 컨텍스트 설계, 페르소나 설정 및 출력 제어 방법을 익히고 직무별 적용 실습을 진행한다. 의료 AI 윤리, 개인정보 비식별화, 저작권 및 사내 보안 가이드라인을 학습하여 민감정보를 안전하게 처리하는 역량을 강화한다.
A31: {{edu_edutime}} | B31: 총시간(%) | C31: =F78&"시간 (100%)" -> 1시간 (100%)
A32: {{time_day_1}} | B32: 1일차 교육시간 | C32: =COUNTA(G82:G90) -> 1
A33: {{time_day_2}} | B33: 2일차 교육시간 | C33: =COUNTA(G92:G100) -> 0
A34: {{time_day_3}} | B34: 3일차 교육시간 | C34: =COUNTA(G102:G110) -> 0
A35: {{time_day_4}} | B35: 4일차 교육시간 | C35: =COUNTA(G112:G120) -> 0
A36: {{time_day_5}} | B36: 5일차 교육시간 | C36: =COUNTA(G122:G130) -> 0
A37: {{topic_day_1}} | B37: 1일차 교육내용 | C37: =K82 -> IEC 62304·ISO 14971 기반 설계관리 전주기의 구조와 URS–SRS–TC–ECO–Traceability 간 관계를 이해하고, ChatGPT·Claude·Claude Cowork·Claude Code의 도구별 역할을 파악한다. 오후에는 Claude·ChatGPT로 자연어 요구사항을 구조화된 URS로 자동 변환하고 Claude Cowork으로 협업 검토하며, ChatGPT·Claude를 활용하여 SRS 초안을 자동 생성하고 문서 일관성·논리를 검증하는 실습을 진행한다.
A38: {{topic_day_2}} | B38: 2일차 교육내용 | C38: =K92 -> ChatGPT로 SRS 기반 검증 가능한 TC를 자동 생성하고 Excel·Google AI Studio 연계로 표준 문서로 출력하는 실습을 진행한다. Claude Code로 설계 변경 시 영향 항목을 자동 식별하고, Claude Cowork·n8n으로 변경 알림 워크플로를 구축하는 실습을 수행한다. 실제 의료기기 설계 변경 시나리오에 AI를 적용하여 ECO 변경 영향 분석을 실습하고, TC 자동화와 ECO 식별 결과를 종합 검토한다.
A39: {{topic_day_3}} | B39: 3일차 교육내용 | C39: =K102 -> Claude Code·ChatGPT로 요구–설계–검증–위험 간 Traceability 매트릭스를 AI로 자동 생성하고 Excel·Google AI Studio로 누락을 탐지하는 실습을 진행한다. ChatGPT·Claude Code·Claude Cowork·n8n을 연결하여 설계 입력부터 변경관리까지 통합된 AI 워크플로를 설계하고, 3일간의 산출물을 통합하여 팀별 발표와 피드백을 통해 현업 AX 적용 전략을 수립한다.
A40: {{topic_day_4}} | B40: 4일차 교육내용 | C40: =K112 -> 0
...

Sheet 7-ALX DATA
A1: 커리큘럼 기초 내용
B2: 분류선택 | C2: 07.인공지능 > 07.생성형AI엔지니어링> 프롬프트 구현
A3: {{edu_title}} | B3: 훈련과정명 | C3: 의료기기 통합 데이터 기반 KPI 대시보드 및 AI 자동 리포팅 구축 (18h) | J3: 기획자와 컨설턴트를 위한 AI개발의 이해
B4: 커리큘럼 | C4: 1. 의료기기 품질·임상·공정 데이터 구조 이해 및 직무별 데이터 흐름 분석 2. 통합 KPI 체계 설계 및 규제 기반 의사결정 구조 수립 (ISO 13485, MFDS, FDA 기준 반영) 3. AI를 활용한 Python/Pandas 기반 데이터 정제 및 구조화 실습 (Python, Pandas, ChatGPT, Claude Code) 4. 바이브코딩을 활용한 KPI 자동 계산 코드 생성 (ChatGPT, Claude Code) 5. Streamlit 기반 KPI 대시보드 설계 및 앱 구현 (Claude Code, Python, Streamlit, ChatGPT) 6. 부서 통합 데이터 시각화 및 인터랙티브 기능 구현 (Claude Code, Streamlit, Pandas) 7. GPT 기반 KPI 자동 해석 코멘트 생성 및 분석 자동화 (ChatGPT, Claude Code) 8. 데이터 수집 → 정제 → KPI → 시각화 → AI 코멘트 → 자동 리포트 통합 AI 워크플로 구축 (Claude Code, Python, Streamlit, ChatGPT API, Claude API)
A5: {{edu_cate01}} | B5: 대분류 | C5: =VLOOKUP($C$2,통합!A2:J52,2,FALSE) -> 20.정보통신
A6: {{edu_cate02}} | B6: 중분류 | C6: =VLOOKUP($C$2,통합!A2:J52,3,FALSE) -> 01.정보기술
A7: {{edu_cate03}} | B7: 소분류 | C7: =VLOOKUP($C$2,통합!A2:J52,4,FALSE) -> 07.인공지능
A8: {{edu_cate04}} | B8: 세분류 | C8: =VLOOKUP($C$2,통합!A2:J52,8,FALSE)&"."&VLOOKUP($C$2,통합!A2:J52,9,FALSE) -> 05.프롬프트 구현
A9: {{edu_cate05}} | B9: 훈련방법 | C9: =VLOOKUP($C$2,통합!A2:J52,7,FALSE) -> 2001070705_25v1
A10: {{edu_ncslevel}} | B10: 훈련수준 | C10: =VLOOKUP($C$2,통합!A2:J52,6,FALSE) -> 5
A11: {{edu_time}} | B11: 훈련시간 | C11: =F78&"시간( "&K131&"일)" -> 1시간( 3일) | J11: 000시간(00일)
A12: 교육과정 세부 정보
A13: {{edu_target}} | B13: 훈련대상자 | C13: 의료기기 개발·제조 기업의 데이터 분석·활용 담당자 및 KPI 대시보드 구축에 관심이 있는 임직원 (품질, R&D, 생산, 경영지원 등) | J13: 기획자, 컨설턴트, 디자이너 등 개발과 AI에 이해가 필요한 직무
A14: {{edu_job}} | B14: 대상직종 | C14: 의료기기 품질관리, 연구개발(R&D), 생산관리, 경영지원, 데이터 분석 등 | J14: 기획자
A15: {{edu_limit}} | B15: 정원 | C15: 20명 | J15: 00명
A16: {{edu_feature}} | B16: 훈련과정 특성 | C16: 의료기기 산업 종사자를 대상으로 품질·임상·공정 데이터의 구조를 이해하고, 코드작성 없이 AI(ChatGPT, Claude Code)를 활용하여 Python/Pandas 기반 데이터 정제부터 바이브코딩 KPI 자동 계산, Claude Code·Streamlit 기반 KPI 대시보드 구현, GPT 기반 KPI 자동 해석, 통합 AI 워크플로 구축까지 다루는 AI 전환(AX) 최고급 과정으로, 의료기기 규제(ISO 13485, MFDS, FDA) 기준을 반영한 데이터 기반 의사결정 역량을 강화하는 신기술·융복합 훈련과정 | J16: 4차 산업혁명 등 관련된 신기술, 융복합, 미래전략산업 직종 과정 등 훈련과정의 특성 기재
A17: {{edu_summary}} | B17: 주요훈련내용 | C17: 의료기기 품질·임상·공정 데이터 구조를 이해하고 직무별 데이터 흐름을 분석한다. ISO 13485·MFDS·FDA 기준을 반영한 통합 KPI 체계를 설계하고, 코드작성 없이 ChatGPT·Claude Code를 활용하여 Python/Pandas 기반 데이터 정제·구조화를 실습한다. 바이브코딩으로 KPI 자동 계산 코드를 생성하고, Claude Code·Streamlit 기반 KPI 대시보드를 설계·구현하며 부서 통합 데이터 시각화와 인터랙티브 기능을 구현한다. ChatGPT·Claude Code 기반 KPI 자동 해석 코멘트 생성과 분석 자동화를 실습하고, 최종적으로 데이터 수집부터 AI 코멘트·자동 리포트까지 통합 AI 워크플로를 구축한다. | J17: 주요훈련내용을 요약해서 작성
A18: {{edu_ncsreason}} | B18: NCS 미적용 사유 | C18: 본 훈련과정은 의료기기 산업 현장의 데이터 기반 의사결정 및 AI 자동 리포팅 전환(AX) 수요에 맞춰 KPI 대시보드 및 AI 워크플로 구축 역량 강화를 목적으로 설계된 과정으로, 기존 NCS 분류체계에 정확히 부합하는 능력단위가 부재하여 산업 현장 맞춤형 커리큘럼으로 자체 구성함 | J18: 주요훈련내용을 요약해서 작성
A19: {{edu_goal}} | B19: 훈련목표 | C19: 의료기기 산업 종사자가 품질·임상·공정 데이터의 구조를 이해하고, 코드작성 없이 ChatGPT·Claude Code를 활용한 바이브코딩으로 Python/Pandas 기반 데이터 정제 및 KPI 자동 계산 코드를 생성하고, Claude Code·Streamlit 기반 KPI 대시보드를 구축하며, 규제 기준(ISO 13485, MFDS, FDA)을 반영한 데이터 수집부터 AI 자동 리포트까지 통합 워크플로를 직접 구축할 수 있는 데이터 파이프라인 구축 역량을 습득하는 것을 목표로 함 | J19: IT 기본 지식을 습득하고 개발자와 원활히 소통하며, 컨설팅 업무에 필요한 IT 전문 지식과 생성형 AI에 대한 이해를 높여 실무에 바로 적용할 수 있는 역량을 키우는 것을 목표로 함
A20: {{edu_guidegoal}} | B20: 지도목표 | C20: 의료기기 데이터 구조와 KPI 체계의 설계 방법론을 명확히 이해하고, 코드작성 없이 ChatGPT·Claude Code를 활용한 실습을 통해 데이터 정제·KPI 계산·대시보드 구현·AI 자동 해석 능력을 키워, 의료기기 업무 현장에서 데이터 기반 의사결정 시간을 획기적으로 단축하고 리포팅 품질을 향상시킬 수 있는 실무 문제 해결 능력을 갖추어 업무 효율성을 높입니다. | J20: IT 기본 개념을 명확히 이해하고, 실습을 통해 능력을 키워 최신 AI 기술을 활용한 실무 문제 해결 능력을 갖추어 업무의 효율성을 높입니다.
A21: {{edu_guidegoaldetail}} | B21: 세부 지도목표 | C21: * 의료기기 품질·임상·공정 데이터 구조 이해 및 직무별 데이터 흐름 분석 * ISO 13485·MFDS·FDA 기준 반영 통합 KPI 체계 설계 및 의사결정 구조 수립 * 코드작성 없이 AI를 활용하여 Python/Pandas 기반 데이터 정제·구조화 및 바이브코딩 KPI 자동 계산 실습 * Streamlit 기반 KPI 대시보드 설계·구현 및 인터랙티브 시각화 실습 * GPT 기반 KPI 자동 해석 코멘트 생성 및 분석 자동화 실습 * 데이터 수집→정제→KPI→시각화→AI 코멘트→자동 리포트 통합 워크플로 구축 역량 함양 | J21: * 운영체제, 서버, 클라우드 인프라의 기본 개념 설명 * 데이터베이스의 기초 지식과 데이터 관리 방법 이해 * 생성형 AI와 LLM의 원리 및 적용 사례 소개 * IT 용어와 개념을 쉽게 설명하고 실제 사례를 통해 이해 증진
A22: {{edu_guidegoaldetail-1}} | B22: 지도내용 | C22: [데이터 구조·KPI 설계 및 AI 활용 데이터 정제·KPI 자동 계산] - 의료기기 품질·임상·공정 데이터 구조 이해 및 KPI 체계 설계 - 코드작성 없이 ChatGPT·Claude Code로 Python/Pandas 데이터 정제 및 바이브코딩 KPI 자동 계산 | J22: [IT 기본 개념] - 운영체제와 서버의 기본 개념 - 클라우드 인프라의 이해
A23: {{edu_guidegoaldetail-2}} | C23: [Claude Code·Streamlit 대시보드 및 GPT 기반 자동 해석] - Claude Code·Streamlit 기반 KPI 대시보드 설계·구현 및 인터랙티브 시각화 - ChatGPT·Claude Code 기반 KPI 자동 해석 코멘트 생성 및 분석 자동화 | J23: [데이터베이스와 개발 기초] - 데이터베이스 기초 개념 - 개발 관련 기초 지식 및 용어
A24: {{edu_guidegoaldetail-3}} | C24: [통합 AI 워크플로 구축 및 최종 산출물] - 데이터 수집→정제→KPI→시각화→AI 코멘트→자동 리포트 통합 워크플로 구축 (Claude Code, Python, Streamlit, ChatGPT API, Claude API) - 최종 산출물: KPI 대시보드 앱, AI 자동 리포트, 통합 워크플로 | J24: [생성형 AI와 LLM] - 생성형 AI의 개념과 원리 - LLM의 동작 원리 및 실제 사례
A25: {{edu_learnhow}} | B25: 교수학습방법 | C25: 강의: 슬라이드 및 의료기기 데이터 분석·KPI 대시보드 사례 자료를 활용하여 데이터 구조·KPI 체계·AI 자동화 방법론을 시각적으로 설명 실습: 코드작성 없이 ChatGPT·Claude Code를 활용한 Python/Pandas 데이터 정제, 바이브코딩 KPI 자동 계산 코드 생성, Claude Code·Streamlit 대시보드 구현, GPT 기반 자동 해석, 통합 AI 워크플로 구축 실습, 최종 산출물 완성 프로젝트 수행 토론: 의료기기 업무 현장의 데이터 기반 의사결정 및 AI 리포팅 활용 방안에 대한 그룹 토론을 통해 실무 적용 능력 배양 Q&A: 실시간 질문을 통해 이해도 점검 및 피드백 제공 | J25: 강의: 슬라이드 및 영상 자료를 활용하여 시각적 이해를 돕고, 사례 중심으로 설명 실습: 간단한 클라우드 설정 및 데이터베이스 생성 실습 토론: 실제 사례에 기반한 토론을 통해 실무 적용 능력 배양 Q&A: 실시간 질문을 통해 이해도 점검 및 피드백 제공
A26: {{edu_testhow}} | B26: 평가방법 | C26: 가. 평가시점 : 교과목 수업 종료시 나. 평가내용 • ChatGPT·Claude Code를 활용한 Python/Pandas 데이터 정제 및 바이브코딩 KPI 자동 계산 능력 • Claude Code·Streamlit 기반 KPI 대시보드 설계·구현 능력 • GPT 기반 KPI 자동 해석 및 통합 AI 워크플로 구축 능력 다. 평가방법 • 결과평가 : 최종 산출물(KPI 대시보드 앱, AI 자동 리포트 시스템, 통합 워크플로) 제출 및 구두발표 | J26: 가. 평가시점 : 교과목 수업 종료시 나. 평가내용 • 호텔 운영 프로그램에 대한 지식(Fidelio, Opera 등) • 객실 업셀링 능력 • 고객정보 검색 능력 및 활용 기술 다. 평가방법 • 결과평가 : 구두발표
A27: {{edu_book}} | B27: 훈련교재 | C27: 자체교재 | J27: 자체교재
A28: {{edu_future}} | B28: 연계 훈련과정 (해당 훈련과정의 중장기 체계적 운영의 적정성을 위한 레벨업 실시 계획) | C28: [Basic] Lv.1 - 의료·바이오 AI 리터러시 입문 Lv.2 - 의료·바이오 데이터리터러시와 데이터시각화 Lv.2 - AI 워크플로우 설계 기초 [Advance] Lv.3 - ISO 13485 기반 QMS 반복문서 AI 자동화 구현 Lv.3 - 규제·인허가 AI 자동화 실무 Lv.4 - 의료기기 설계관리(Design Controls) AI 자동화 실습 Lv.5 - 의료기기 통합 데이터 기반 KPI 대시보드 및 AI 자동 리포팅 구축 (본 과정) | J28: [Basic] Lv.1 - 기획자와 컨설턴트를 위한 AI개발의 이해 Lv.2 - 바이브코딩 이론 및 실습 Lv.2 - 웹서비스 배포 전략 및 클라우드 서비스의 이해 [Advance] Lv.3 - 데이터베이스 이해 및 실습 1 (MySQL) Lv.3 - 데이터베이스 이해 및 실습 2 (Supabase) Lv.3 - 데이터베이스 이해 및 실습 3 (Firebase) Lv.4 - 웹앱서비스운영전략 Lv.5 - 개발에서 배포 운영까지의 파이프라인 구축
A29: {{edu_needreason}} | B29: 사업 필요성&목적 | J29: 기획자들의 경우 개발자와의 커뮤니케이션에서 어려움을 겪는 경우가 많음, 또한 관련 직무의 수요조사 결과 관련된 교육의 필요성이 제기됨 본 과정은 이런 소통과 기획자의 직무에 필요한 IT관련 기초지식을 배양하여 직무관련 역량을 높이며, 바이브코딩을 통해 업무의 프로세스와 효율을 높일 수 있다
A30: {{edu_curri}} | B30: 커리큘럼 요약 | J30: LLM(예: ChatGPT, Claude)의 구조와 생성형 AI 패러다임을 이해하고, 의료·바이오 산업에서의 적용 가능성과 한계를 학습하며 기초 툴을 실습한다. 업무 전환을 위해 프롬프트의 기본 구조와 컨텍스트 설계, 페르소나 설정 및 출력 제어 방법을 익히고 직무별 적용 실습을 진행한다. 의료 AI 윤리, 개인정보 비식별화, 저작권 및 사내 보안 가이드라인을 학습하여 민감정보를 안전하게 처리하는 역량을 강화한다.
A31: {{edu_edutime}} | B31: 총시간(%) | C31: =F78&"시간 (100%)" -> 1시간 (100%)
A32: {{time_day_1}} | B32: 1일차 교육시간 | C32: =COUNTA(G82:G90) -> 1
A33: {{time_day_2}} | B33: 2일차 교육시간 | C33: =COUNTA(G92:G100) -> 0
A34: {{time_day_3}} | B34: 3일차 교육시간 | C34: =COUNTA(G102:G110) -> 0
A35: {{time_day_4}} | B35: 4일차 교육시간 | C35: =COUNTA(G112:G120) -> 0
A36: {{time_day_5}} | B36: 5일차 교육시간 | C36: =COUNTA(G122:G130) -> 0
A37: {{topic_day_1}} | B37: 1일차 교육내용 | C37: =K82 -> 의료기기 품질·임상·공정 데이터의 구조를 이해하고 직무별 데이터 흐름을 분석한 후, ISO 13485·MFDS·FDA 기준을 반영한 통합 KPI 체계를 설계하고 규제 기반 의사결정 구조를 수립한다. 코드작성 없이 ChatGPT·Claude Code를 활용하여 Python/Pandas 기반 데이터 정제·구조화를 실습하고, 바이브코딩을 통해 KPI 자동 계산 코드를 생성·검증하는 실습을 진행한다.
A38: {{topic_day_2}} | B38: 2일차 교육내용 | C38: =K92 -> ChatGPT를 활용하여 Claude Code·Streamlit 기반 KPI 대시보드를 설계하고 실제 앱을 구현하는 실습을 진행한다. Claude Code·Streamlit·Pandas로 부서 통합 데이터 시각화와 필터·드릴다운·동적 차트 등 인터랙티브 기능을 구현한 후, ChatGPT·Claude Code를 활용하여 GPT 기반 KPI 자동 해석 코멘트 생성과 분석 자동화를 실습하여 대시보드에 AI 해석 기능을 통합한다.
A39: {{topic_day_3}} | B39: 3일차 교육내용 | C39: =K102 -> 데이터 수집부터 정제→KPI 계산→시각화→AI 코멘트→자동 리포트까지 연결되는 통합 AI 워크플로를 설계하고, ChatGPT API·Claude API를 연동하여 Claude Code·Python·Streamlit 기반 통합 시스템을 구축하는 실습을 진행한다. 3일간의 학습 내용을 종합하여 KPI 대시보드 앱, AI 자동 리포트 시스템, 통합 워크플로를 최종 산출물로 완성하고 팀별 발표를 통해 결과를 공유한다.
A40: {{topic_day_4}} | B40: 4일차 교육내용 | C40: =K112 -> 0
...

Sheet 탬플릿-기준
A1: 커리큘럼 기초 내용
B2: 분류선택 | C2: 07.인공지능 > 07.생성형AI엔지니어링> 프롬프트 구현
A3: {{edu_title}} | B3: 훈련과정명 | C3: 의료·바이오 AI 리터러시 입문 | J3: 기획자와 컨설턴트를 위한 AI개발의 이해
B4: 커리큘럼 | C4: 1. 의료·바이오 분야 AI 적용 사례와 한계 2. AI의 이해 (생성형 AI의 이해 및 활용, ChatGPT/Claude/Gemini) 3. 프롬프트엔지니어링과 생성형AI의 고급 활용 4. 반복업무를 손쉽게 하는 나만의 챗봇 (GPTs, Gems) 5. AI를 활용한 문서작업 - ( ChatGPT, Claude, Gemini, Genspark, Google Docs ) 6. 리서치, 기획, 제안, 문서작업 등을 위한 NotebookLM 활용법 7. AI윤리, 보안의 이해
A5: {{edu_cate01}} | B5: 대분류 | C5: =VLOOKUP($C$2,통합!A2:J52,2,FALSE) -> 20.정보통신
A6: {{edu_cate02}} | B6: 중분류 | C6: =VLOOKUP($C$2,통합!A2:J52,3,FALSE) -> 01.정보기술
A7: {{edu_cate03}} | B7: 소분류 | C7: =VLOOKUP($C$2,통합!A2:J52,4,FALSE) -> 07.인공지능
A8: {{edu_cate04}} | B8: 세분류 | C8: =VLOOKUP($C$2,통합!A2:J52,8,FALSE)&"."&VLOOKUP($C$2,통합!A2:J52,9,FALSE) -> 05.프롬프트 구현
A9: {{edu_cate05}} | B9: 훈련방법 | C9: =VLOOKUP($C$2,통합!A2:J52,7,FALSE) -> 2001070705_25v1
A10: {{edu_ncslevel}} | B10: 훈련수준 | C10: =VLOOKUP($C$2,통합!A2:J52,6,FALSE) -> 5
A11: {{edu_time}} | B11: 훈련시간 | C11: =F76&"시간( "&K129&"일)" -> 1시간( 0일) | J11: 000시간(00일)
A12: 교육과정 세부 정보
A13: {{edu_target}} | B13: 훈련대상자 | J13: 기획자, 컨설턴트, 디자이너 등 개발과 AI에 이해가 필요한 직무
A14: {{edu_job}} | B14: 대상직종 | J14: 기획자
A15: {{edu_limit}} | B15: 정원 | J15: 00명
A16: {{edu_feature}} | B16: 훈련과정 특성 | J16: 4차 산업혁명 등 관련된 신기술, 융복합, 미래전략산업 직종 과정 등 훈련과정의 특성 기재
A17: {{edu_summary}} | B17: 주요훈련내용 | J17: 주요훈련내용을 요약해서 작성
A18: {{edu_ncsreason}} | B18: NCS 미적용 사유 | J18: 주요훈련내용을 요약해서 작성
A19: {{edu_goal}} | B19: 훈련목표 | J19: IT 기본 지식을 습득하고 개발자와 원활히 소통하며, 컨설팅 업무에 필요한 IT 전문 지식과 생성형 AI에 대한 이해를 높여 실무에 바로 적용할 수 있는 역량을 키우는 것을 목표로 함
A20: {{edu_guidegoal}} | B20: 지도목표 | J20: IT 기본 개념을 명확히 이해하고, 실습을 통해 능력을 키워 최신 AI 기술을 활용한 실무 문제 해결 능력을 갖추어 업무의 효율성을 높입니다.
A21: {{edu_guidegoaldetail}} | B21: 세부 지도목표 | J21: * 운영체제, 서버, 클라우드 인프라의 기본 개념 설명 * 데이터베이스의 기초 지식과 데이터 관리 방법 이해 * 생성형 AI와 LLM의 원리 및 적용 사례 소개 * IT 용어와 개념을 쉽게 설명하고 실제 사례를 통해 이해 증진
A22: {{edu_guidegoaldetail-1}} | B22: 지도내용 | J22: [IT 기본 개념] - 운영체제와 서버의 기본 개념 - 클라우드 인프라의 이해
A23: {{edu_guidegoaldetail-2}} | J23: [데이터베이스와 개발 기초] - 데이터베이스 기초 개념 - 개발 관련 기초 지식 및 용어
A24: {{edu_guidegoaldetail-3}} | J24: [생성형 AI와 LLM] - 생성형 AI의 개념과 원리 - LLM의 동작 원리 및 실제 사례
A25: {{edu_learnhow}} | B25: 교수학습방법 | J25: 강의: 슬라이드 및 영상 자료를 활용하여 시각적 이해를 돕고, 사례 중심으로 설명 실습: 간단한 클라우드 설정 및 데이터베이스 생성 실습 토론: 실제 사례에 기반한 토론을 통해 실무 적용 능력 배양 Q&A: 실시간 질문을 통해 이해도 점검 및 피드백 제공
A26: {{edu_testhow}} | B26: 평가방법 | J26: 가. 평가시점 : 교과목 수업 종료시 나. 평가내용 • 호텔 운영 프로그램에 대한 지식(Fidelio, Opera 등) • 객실 업셀링 능력 • 고객정보 검색 능력 및 활용 기술 다. 평가방법 • 결과평가 : 구두발표
A27: {{edu_book}} | B27: 훈련교재 | J27: 자체교재
A28: {{edu_book}} | B28: 연계 훈련과정 (해당 훈련과정의 중장기 체계적 운영의 적정성을 위한 레벨업 실시 계획) | J28: [Basic] Lv.1 - 기획자와 컨설턴트를 위한 AI개발의 이해 Lv.2 - 바이브코딩 이론 및 실습 Lv.2 - 웹서비스 배포 전략 및 클라우드 서비스의 이해 [Advance] Lv.3 - 데이터베이스 이해 및 실습 1 (MySQL) Lv.3 - 데이터베이스 이해 및 실습 2 (Supabase) Lv.3 - 데이터베이스 이해 및 실습 3 (Firebase) Lv.4 - 웹앱서비스운영전략 Lv.5 - 개발에서 배포 운영까지의 파이프라인 구축
A29: {{edu_edutime}} | B29: 총시간(%) | C29: =F76&"시간 (100%)" -> 1시간 (100%)
A30: {{time_day_1}} | B30: 1일차 교육시간 | C30: =COUNTA(G80:G88) -> 1
A31: {{time_day_2}} | B31: 2일차 교육시간 | C31: =COUNTA(G90:G98) -> 0
A32: {{time_day_3}} | B32: 3일차 교육시간 | C32: =COUNTA(G100:G108) -> 0
A33: {{time_day_4}} | B33: 4일차 교육시간 | C33: =COUNTA(G110:G118) -> 0
A34: {{time_day_5}} | B34: 5일차 교육시간 | C34: =COUNTA(G120:G128) -> 0
A35: {{topic_day_1}} | B35: 1일차 교육내용
A36: {{topic_day_2}} | B36: 2일차 교육내용
A37: {{topic_day_3}} | B37: 3일차 교육내용
A38: {{topic_day_4}} | B38: 4일차 교육내용
A39: {{topic_day_5}} | B39: 5일차 교육내용
D43: 능력단위코드 | E43: 능력단위 명 | F43: 훈련시간 | G43: 능력단위요소 코드 | H43: 능력단위요소 명 | I43: 훈련시간
...

Sheet 탬플릿
B1: 훈련과정명 | J1: 기획자와 컨설턴트를 위한 AI개발의 이해
B2: 훈련대상자 | J2: 기획자, 컨설턴트, 디자이너 등 개발과 AI에 이해가 필요한 직무
B3: 훈련수준 | J3: L5
B4: 훈련목표 | J4: IT 기본 지식을 습득하고 개발자와 원활히 소통하며, 컨설팅 업무에 필요한 IT 전문 지식과 생성형 AI에 대한 이해를 높여 실무에 바로 적용할 수 있는 역량을 키우는 것을 목표로 함
B5: 지도목표 | J5: IT 기본 개념을 명확히 이해하고, 실습을 통해 능력을 키워 최신 AI 기술을 활용한 실무 문제 해결 능력을 갖추어 업무의 효율성을 높입니다.
B6: 세부 지도목표 | J6: * 운영체제, 서버, 클라우드 인프라의 기본 개념 설명 * 데이터베이스의 기초 지식과 데이터 관리 방법 이해 * 생성형 AI와 LLM의 원리 및 적용 사례 소개 * IT 용어와 개념을 쉽게 설명하고 실제 사례를 통해 이해 증진
B7: 지도내용 | J7: [IT 기본 개념] 운영체제와 서버의 기본 개념 클라우드 인프라의 이해
J8: [데이터베이스와 개발 기초] 데이터베이스 기초 개념 개발 관련 기초 지식 및 용어
J9: [생성형 AI와 LLM] 생성형 AI의 개념과 원리 LLM의 동작 원리 및 실제 사례
B10: 교수학습방법 | J10: 강의: 슬라이드 및 영상 자료를 활용하여 시각적 이해를 돕고, 사례 중심으로 설명 실습: 간단한 클라우드 설정 및 데이터베이스 생성 실습 토론: 실제 사례에 기반한 토론을 통해 실무 적용 능력 배양 Q&A: 실시간 질문을 통해 이해도 점검 및 피드백 제공
B11: 평가방법 | J11: 간단한 Q&A 세션을 통해 이해도 확인 실습 결과물 발표 및 피드백
B12: 훈련교재 | J12: 자체교재
D15: 능력단위코드 | E15: 능력단위 명 | F15: 훈련시간 | G15: 능력단위요소 코드 | H15: 능력단위요소 명 | I15: 훈련시간
C16: =IFERROR(G16,"") -> 2001010211_16v3.1 | D16: 2001010211_19v4 | E16: 정보시스템인프라분석 | F16: =IF(COUNTIF($D$49:$D$98,D16)=0,"",COUNTIF($D$49:$D$98,D16)) -> 1 | G16: 2001010211_16v3.1 | H16: 하드웨어 분석하기 | I16: =IF(COUNTIF($G$49:$G$98,G16)=0,"",COUNTIF($G$49:$G$98,G16)) -> 1
C17: =IFERROR(G17,"") -> 0 | F17: =IF(COUNTIF($D$49:$D$98,D17)=0,"",COUNTIF($D$49:$D$98,D17)) | I17: =IF(COUNTIF($G$49:$G$98,G17)=0,"",COUNTIF($G$49:$G$98,G17))
C18: =IFERROR(G18,"") -> 0 | F18: =IF(COUNTIF($D$49:$D$98,D18)=0,"",COUNTIF($D$49:$D$98,D18)) | I18: =IF(COUNTIF($G$49:$G$98,G18)=0,"",COUNTIF($G$49:$G$98,G18))
C19: =IFERROR(G19,"") -> 0 | F19: =IF(COUNTIF($D$49:$D$98,D19)=0,"",COUNTIF($D$49:$D$98,D19)) | I19: =IF(COUNTIF($G$49:$G$98,G19)=0,"",COUNTIF($G$49:$G$98,G19))
C20: =IFERROR(G20,"") -> 0 | F20: =IF(COUNTIF($D$49:$D$98,D20)=0,"",COUNTIF($D$49:$D$98,D20)) | I20: =IF(COUNTIF($G$49:$G$98,G20)=0,"",COUNTIF($G$49:$G$98,G20))
C21: =IFERROR(G21,"") -> 0 | F21: =IF(COUNTIF($D$49:$D$98,D21)=0,"",COUNTIF($D$49:$D$98,D21)) | I21: =IF(COUNTIF($G$49:$G$98,G21)=0,"",COUNTIF($G$49:$G$98,G21))
C22: =IFERROR(G22,"") -> 0 | F22: =IF(COUNTIF($D$49:$D$98,D22)=0,"",COUNTIF($D$49:$D$98,D22)) | I22: =IF(COUNTIF($G$49:$G$98,G22)=0,"",COUNTIF($G$49:$G$98,G22))
C23: =IFERROR(G23,"") -> 0 | F23: =IF(COUNTIF($D$49:$D$98,D23)=0,"",COUNTIF($D$49:$D$98,D23)) | I23: =IF(COUNTIF($G$49:$G$98,G23)=0,"",COUNTIF($G$49:$G$98,G23))
C24: =IFERROR(G24,"") -> 0 | F24: =IF(COUNTIF($D$49:$D$98,D24)=0,"",COUNTIF($D$49:$D$98,D24)) | I24: =IF(COUNTIF($G$49:$G$98,G24)=0,"",COUNTIF($G$49:$G$98,G24))
C25: =IFERROR(G25,"") -> 0 | F25: =IF(COUNTIF($D$49:$D$98,D25)=0,"",COUNTIF($D$49:$D$98,D25)) | I25: =IF(COUNTIF($G$49:$G$98,G25)=0,"",COUNTIF($G$49:$G$98,G25))
C26: =IFERROR(G26,"") -> 0 | F26: =IF(COUNTIF($D$49:$D$98,D26)=0,"",COUNTIF($D$49:$D$98,D26)) | I26: =IF(COUNTIF($G$49:$G$98,G26)=0,"",COUNTIF($G$49:$G$98,G26))
C27: =IFERROR(G27,"") -> 0 | F27: =IF(COUNTIF($D$49:$D$98,D27)=0,"",COUNTIF($D$49:$D$98,D27)) | I27: =IF(COUNTIF($G$49:$G$98,G27)=0,"",COUNTIF($G$49:$G$98,G27))
C28: =IFERROR(G28,"") -> 0 | F28: =IF(COUNTIF($D$49:$D$98,D28)=0,"",COUNTIF($D$49:$D$98,D28)) | I28: =IF(COUNTIF($G$49:$G$98,G28)=0,"",COUNTIF($G$49:$G$98,G28))
... C35: =IFERROR(G35,"") -> 0 | F35: =IF(COUNTIF($D$49:$D$98,D35)=0,"",COUNTIF($D$49:$D$98,D35)) | I35: =IF(COUNTIF($G$49:$G$98,G35)=0,"",COUNTIF($G$49:$G$98,G35))
C36: =IFERROR(G36,"") -> 0 | F36: =IF(COUNTIF($D$49:$D$98,D36)=0,"",COUNTIF($D$49:$D$98,D36)) | I36: =IF(COUNTIF($G$49:$G$98,#REF!)=0,"",COUNTIF($G$49:$G$98,#REF!))
C37: =IFERROR(G37,"") -> 0 | F37: =IF(COUNTIF($D$49:$D$98,D37)=0,"",COUNTIF($D$49:$D$98,D37)) | I37: =IF(COUNTIF($G$49:$G$98,G36)=0,"",COUNTIF($G$49:$G$98,G36))
C38: =IFERROR(G38,"") -> 0 | F38: =IF(COUNTIF($D$49:$D$98,D38)=0,"",COUNTIF($D$49:$D$98,D38)) | I38: =IF(COUNTIF($G$49:$G$98,G38)=0,"",COUNTIF($G$49:$G$98,G38))
C39: =IFERROR(G39,"") -> 0 | F39: =IF(COUNTIF($D$49:$D$98,D39)=0,"",COUNTIF($D$49:$D$98,D39)) | I39: =IF(COUNTIF($G$49:$G$98,G39)=0,"",COUNTIF($G$49:$G$98,G39))
C40: =IFERROR(G40,"") -> 0 | F40: =IF(COUNTIF($D$49:$D$98,D40)=0,"",COUNTIF($D$49:$D$98,D40)) | I40: =IF(COUNTIF($G$49:$G$98,G40)=0,"",COUNTIF($G$49:$G$98,G40))
C41: =IFERROR(G41,"") -> 0 | F41: =IF(COUNTIF($D$49:$D$98,D41)=0,"",COUNTIF($D$49:$D$98,D41)) | I41: =IF(COUNTIF($G$49:$G$98,G41)=0,"",COUNTIF($G$49:$G$98,G41))
C42: =IFERROR(G42,"") -> 0 | F42: =IF(COUNTIF($D$49:$D$98,D42)=0,"",COUNTIF($D$49:$D$98,D42)) | I42: =IF(COUNTIF($G$49:$G$98,G42)=0,"",COUNTIF($G$49:$G$98,G42))
C43: =IFERROR(G43,"") -> 0 | F43: =IF(COUNTIF($D$49:$D$98,D43)=0,"",COUNTIF($D$49:$D$98,D43)) | I43: =IF(COUNTIF($G$49:$G$98,G43)=0,"",COUNTIF($G$49:$G$98,G43))
C44: =IFERROR(G44,"") -> 0 | F44: =IF(COUNTIF($D$49:$D$98,D44)=0,"",COUNTIF($D$49:$D$98,D44)) | I44: =IF(COUNTIF($G$49:$G$98,G44)=0,"",COUNTIF($G$49:$G$98,G44))
C45: =IFERROR(G45,"") -> 0 | F45: =IF(COUNTIF($D$49:$D$98,D45)=0,"",COUNTIF($D$49:$D$98,D45)) | I45: =IF(COUNTIF($G$49:$G$98,G45)=0,"",COUNTIF($G$49:$G$98,G45))
