Workbook
Name 능력단위: #REF!

Sheet 탬플릿-기준 (3)
A1: 커리큘럼 기초 내용
B2: 분류선택 | C2: 09.의료장비제조 > 01.의료기기품질관리> 의료기기 품질시스템 자원관리
A3: {{edu_title}} | B3: 훈련과정명 | C3: 의료·바이오 AI 리터러시 입문 | J3: 기획자와 컨설턴트를 위한 AI개발의 이해
B4: 커리큘럼 | C4: LLM 구조 및 의료 산업 특화 작동 원리 이해 (ChatGPT, Claude) 1. AI 패러다임 변화 2. 생성형 AI 모델 구조 이해 3. 의료/바이오 적용 한계와 가능성 4. 기초 툴 실습 업무 전환을 위한 프롬프트 기본 구조 실습 (ChatGPT 등) 1. 프롬프트 3요소 2. 컨텍스트 부여 방법 3. 페르소나 및 출력 제어 4. 직무별 적용 실습 민감정보 처리, 저작권, 윤리 가이드라인 학습 (비식별화 툴) 1. 의료 AI 윤리 개요 2. 개인정보 비식별화 역량 3. 저작권 문제 4. 사내 보안 가이드라인 기초
A5: {{edu_cate01}} | B5: 대분류 | C5: =VLOOKUP($C$2,통합!$A$3:$H$44,2,FALSE) -> 03.전자기기개발
A6: {{edu_cate02}} | B6: 중분류 | C6: =VLOOKUP($C$2,통합!$A$3:$H$44,3,FALSE) -> 09.의료장비제조
A7: {{edu_cate03}} | B7: 소분류 | C7: =VLOOKUP($C$2,통합!$A$3:$H$44,4,FALSE) -> 01.의료기기품질관리
A8: {{edu_cate04}} | B8: 세분류 | C8: =VLOOKUP($C$2,통합!$A$3:$H$44,7,FALSE)&"."&VLOOKUP($C$2,통합!$A$3:$H$44,8,FALSE) -> 02.의료기기 품질시스템 자원관리
A9: {{edu_cate05}} | B9: 훈련방법 | C9: =VLOOKUP($C$2,통합!$A$3:$H$44,6,FALSE) -> 1903090102_21v2
A10: {{edu_ncslevel}} | B10: 훈련수준 | C10: =VLOOKUP($C$2,통합!$A$3:$H$44,5,FALSE) -> 4
A11: {{edu_time}} | B11: 훈련시간 | C11: =F64&"시간( "&K117&"일)" -> 1시간( 0일) | J11: 000시간(00일)
A12: 교육과정 세부 정보
A13: {{edu_target}} | B13: 훈련대상자 | J13: 기획자, 컨설턴트, 디자이너 등 개발과 AI에 이해가 필요한 직무
A14: {{edu_job}} | B14: 대상직종 | J14: 기획자
A15: {{edu_limit}} | B15: 정원 | J15: 00명
A16: {{edu_feature}} | B16: 훈련과정 특성 | J16: 4차 산업혁명 등 관련된 신기술, 융복합, 미래전략산업 직종 과정 등 훈련과정의 특성 기재
A17: {{edu_summary}} | B17: 주요훈련내용 | J17: 주요훈련내용을 요약해서 작성
A18: {{edu_ncsreason}} | B18: NCS 미적용 사유 | J18: 주요훈련내용을 요약해서 작성
A19: {{edu_goal}} | B19: 훈련목표 | J19: IT 기본 지식을 습득하고 개발자와 원활히 소통하며, 컨설팅 업무에 필요한 IT 전문 지식과 생성형 AI에 대한 이해를 높여 실무에 바로 적용할 수 있는 역량을 키우는 것을 목표로 함
A20: {{edu_guidegoal}} | B20: 지도목표 | J20: IT 기본 개념을 명확히 이해하고, 실습을 통해 능력을 키워 최신 AI 기술을 활용한 실무 문제 해결 능력을 갖추어 업무의 효율성을 높입니다.
A21: {{edu_guidegoaldetail}} | B21: 세부 지도목표 | J21: * 운영체제, 서버, 클라우드 인프라의 기본 개념 설명 * 데이터베이스의 기초 지식과 데이터 관리 방법 이해 * 생성형 AI와 LLM의 원리 및 적용 사례 소개 * IT 용어와 개념을 쉽게 설명하고 실제 사례를 통해 이해 증진
A22: {{edu_guidegoaldetail-1}} | B22: 지도내용 | J22: [IT 기본 개념] - 운영체제와 서버의 기본 개념 - 클라우드 인프라의 이해
A23: {{edu_guidegoaldetail-2}} | J23: [데이터베이스와 개발 기초] - 데이터베이스 기초 개념 - 개발 관련 기초 지식 및 용어
A24: {{edu_guidegoaldetail-3}} | J24: [생성형 AI와 LLM] - 생성형 AI의 개념과 원리 - LLM의 동작 원리 및 실제 사례
A25: {{edu_learnhow}} | B25: 교수학습방법 | J25: 강의: 슬라이드 및 영상 자료를 활용하여 시각적 이해를 돕고, 사례 중심으로 설명 실습: 간단한 클라우드 설정 및 데이터베이스 생성 실습 토론: 실제 사례에 기반한 토론을 통해 실무 적용 능력 배양 Q&A: 실시간 질문을 통해 이해도 점검 및 피드백 제공
A26: {{edu_testhow}} | B26: 평가방법 | J26: 간단한 Q&A 세션을 통해 이해도 확인 실습 결과물 발표 및 피드백
A27: {{edu_book}} | B27: 훈련교재 | J27: 자체교재
A28: {{edu_book}} | B28: 연계 훈련과정 (해당 훈련과정의 중장기 체계적 운영의 적정성을 위한 레벨업 실시 계획) | J28: [Basic] Lv.1 - 기획자와 컨설턴트를 위한 AI개발의 이해 Lv.2 - 바이브코딩 이론 및 실습 Lv.2 - 웹서비스 배포 전략 및 클라우드 서비스의 이해 [Advance] Lv.3 - 데이터베이스 이해 및 실습 1 (MySQL) Lv.3 - 데이터베이스 이해 및 실습 2 (Supabase) Lv.3 - 데이터베이스 이해 및 실습 3 (Firebase) Lv.4 - 웹앱서비스운영전략 Lv.5 - 개발에서 배포 운영까지의 파이프라인 구축
D31: 능력단위코드 | E31: 능력단위 명 | F31: 훈련시간 | G31: 능력단위요소 코드 | H31: 능력단위요소 명 | I31: 훈련시간
C32: =IFERROR(G32,"") -> 2001010211_16v3.1 | D32: =VLOOKUP(J32,통합!$A$3:$H$44,6,FALSE) -> 1903090101_21v2 | E32: =VLOOKUP(J32,통합!$A$3:$H$44,8,FALSE) -> 의료기기 품질문서 개발 | F32: =IF(COUNTIF($D$67:$D$116,D32)=0,"",COUNTIF($D$67:$D$116,D32)) -> 1 | G32: 2001010211_16v3.1 | H32: 하드웨어 분석하기 | I32: =IF(COUNTIF($G$67:$G$116,G32)=0,"",COUNTIF($G$67:$G$116,G32)) -> 1 | J32: 09.의료장비제조 > 01.의료기기품질관리> 의료기기 품질문서 개발
C33: =IFERROR(G33,"") -> 0 | F33: =IF(COUNTIF($D$67:$D$116,D33)=0,"",COUNTIF($D$67:$D$116,D33)) | I33: =IF(COUNTIF($G$67:$G$116,G33)=0,"",COUNTIF($G$67:$G$116,G33))
C34: =IFERROR(G34,"") -> 0 | F34: =IF(COUNTIF($D$67:$D$116,D34)=0,"",COUNTIF($D$67:$D$116,D34)) | I34: =IF(COUNTIF($G$67:$G$116,G34)=0,"",COUNTIF($G$67:$G$116,G34))
C35: =IFERROR(G35,"") -> 0 | F35: =IF(COUNTIF($D$67:$D$116,D35)=0,"",COUNTIF($D$67:$D$116,D35)) | I35: =IF(COUNTIF($G$67:$G$116,G35)=0,"",COUNTIF($G$67:$G$116,G35))
C36: =IFERROR(G36,"") -> 0 | F36: =IF(COUNTIF($D$67:$D$116,D36)=0,"",COUNTIF($D$67:$D$116,D36)) | I36: =IF(COUNTIF($G$67:$G$116,G36)=0,"",COUNTIF($G$67:$G$116,G36))
C37: =IFERROR(G37,"") -> 0 | F37: =IF(COUNTIF($D$67:$D$116,D37)=0,"",COUNTIF($D$67:$D$116,D37)) | I37: =IF(COUNTIF($G$67:$G$116,G37)=0,"",COUNTIF($G$67:$G$116,G37))
C38: =IFERROR(G38,"") -> 0 | F38: =IF(COUNTIF($D$67:$D$116,D38)=0,"",COUNTIF($D$67:$D$116,D38)) | I38: =IF(COUNTIF($G$67:$G$116,G38)=0,"",COUNTIF($G$67:$G$116,G38))
C39: =IFERROR(G39,"") -> 0 | F39: =IF(COUNTIF($D$67:$D$116,D39)=0,"",COUNTIF($D$67:$D$116,D39)) | I39: =IF(COUNTIF($G$67:$G$116,G39)=0,"",COUNTIF($G$67:$G$116,G39))
C40: =IFERROR(G40,"") -> 0 | F40: =IF(COUNTIF($D$67:$D$116,D40)=0,"",COUNTIF($D$67:$D$116,D40)) | I40: =IF(COUNTIF($G$67:$G$116,G40)=0,"",COUNTIF($G$67:$G$116,G40))
C41: =IFERROR(G41,"") -> 0 | F41: =IF(COUNTIF($D$67:$D$116,D41)=0,"",COUNTIF($D$67:$D$116,D41)) | I41: =IF(COUNTIF($G$67:$G$116,G41)=0,"",COUNTIF($G$67:$G$116,G41))
C42: =IFERROR(G42,"") -> 0 | F42: =IF(COUNTIF($D$67:$D$116,D42)=0,"",COUNTIF($D$67:$D$116,D42)) | I42: =IF(COUNTIF($G$67:$G$116,G42)=0,"",COUNTIF($G$67:$G$116,G42))
...

Sheet AFX1-리터러시
A1: 커리큘럼 기초 내용
B2: 분류선택 | C2: 09.의료장비제조 > 04.의료기기연구개발> 의료기기 연구개발기획
A3: {{edu_title}} | B3: 훈련과정명 | C3: 의료·바이오 AI 리터러시 입문 | J3: 기획자와 컨설턴트를 위한 AI개발의 이해
B4: 커리큘럼 | C4: LLM 구조 및 의료 산업 특화 작동 원리 이해 (ChatGPT, Claude) 1. AI 패러다임 변화 2. 생성형 AI 모델 구조 이해 3. 의료/바이오 적용 한계와 가능성 4. 기초 툴 실습 업무 전환을 위한 프롬프트 기본 구조 실습 (ChatGPT 등) 1. 프롬프트 3요소 2. 컨텍스트 부여 방법 3. 페르소나 및 출력 제어 4. 직무별 적용 실습 민감정보 처리, 저작권, 윤리 가이드라인 학습 (비식별화 툴) 1. 의료 AI 윤리 개요 2. 개인정보 비식별화 역량 3. 저작권 문제 4. 사내 보안 가이드라인 기초
A5: {{edu_cate01}} | B5: 대분류 | C5: =VLOOKUP($C$2,통합!$A$3:$H$44,2,FALSE) -> 03.전자기기개발
A6: {{edu_cate02}} | B6: 중분류 | C6: =VLOOKUP($C$2,통합!$A$3:$H$44,3,FALSE) -> 09.의료장비제조
A7: {{edu_cate03}} | B7: 소분류 | C7: =VLOOKUP($C$2,통합!$A$3:$H$44,4,FALSE) -> 04.의료기기연구개발
A8: {{edu_cate04}} | B8: 세분류 | C8: =VLOOKUP($C$2,통합!$A$3:$H$44,7,FALSE)&"."&VLOOKUP($C$2,통합!$A$3:$H$44,8,FALSE) -> 01.의료기기 연구개발기획
A9: {{edu_cate05}} | B9: 훈련방법 | C9: =VLOOKUP($C$2,통합!$A$3:$H$44,6,FALSE) -> 1903090401_21v2
A10: {{edu_ncslevel}} | B10: 훈련수준 | C10: =VLOOKUP($C$2,통합!$A$3:$H$44,5,FALSE) -> 5
A11: {{edu_time}} | B11: 훈련시간 | C11: =F66&"시간( "&K119&"일)" -> 1시간( 0일) | J11: 000시간(00일)
A12: 교육과정 세부 정보
A13: {{edu_target}} | B13: 훈련대상자 | C13: 의료기기 개발·제조 기업 종사자 중 품질관리, 인허가(RA), 생산관리, 연구개발(R&D), 임상 등 부서에서 AI 활용 역량이 필요한 실무자 및 관리자 | J13: 기획자, 컨설턴트, 디자이너 등 개발과 AI에 이해가 필요한 직무
A14: {{edu_job}} | B14: 대상직종 | C14: 품질관리자, 인허가담당자(RA), 생산관리자, R&D 연구원, 임상담당자 | J14: 기획자
A15: {{edu_limit}} | B15: 정원 | C15: 20명 | J15: 00명
A16: {{edu_feature}} | B16: 훈련과정 특성 | C16: 의료기기 산업 특화 AI 전환(AX) 교육과정으로, 4차 산업혁명 핵심 기술인 생성형 AI(LLM)를 의료기기 품질관리·인허가·생산 등 실무에 접목하는 신기술 융복합 과정임. 의료기기 GMP(QMS), IEC 62304(의료기기 소프트웨어), FDA/MFDS 규제 환경을 고려한 AI 리터러시 역량을 배양하며, AI 기반 업무 전환(AX)을 위한 미래전략산업 직종 대응 과정임 | J16: 4차 산업혁명 등 관련된 신기술, 융복합, 미래전략산업 직종 과정 등 훈련과정의 특성 기재
A17: {{edu_summary}} | B17: 주요훈련내용 | C17: 본 과정은 의료기기 산업 종사자를 대상으로 생성형 AI(LLM)의 구조와 작동 원리를 의료·바이오 맥락에서 이해하고, 프롬프트 엔지니어링 기법을 활용하여 품질관리 문서 작성, 인허가 자료 검토, CAPA 보고서 초안 작성 등 직무별 업무에 즉시 적용할 수 있는 실습 중심 교육을 실시함. 또한 의료 데이터의 민감정보 처리, 비식별화 기법, AI 활용 시 저작권·윤리 이슈 및 사내 보안 가이드라인을 학습하여 규제 환경에 적합한 AI 활용 역량을 갖추도록 함 | J17: 주요훈련내용을 요약해서 작성
A18: {{edu_ncsreason}} | B18: NCS 미적용 사유 | C18: 본 과정은 의료기기 품질시스템 자원관리(NCS 세분류 1903090102)를 기반으로 하되, 기존 NCS 능력단위에 생성형 AI·LLM 활용 역량 및 AI 전환(AX) 관련 내용이 미반영되어 있어, 의료기기 산업 현장의 AI 도입 수요와 규제 환경(MFDS, FDA, IEC 62304)에 맞춘 AI 리터러시 교육 내용을 별도 설계하여 NCS 비적용으로 운영함 | J18: 주요훈련내용을 요약해서 작성
A19: {{edu_goal}} | B19: 훈련목표 | C19: 의료기기 개발·제조 실무자가 생성형 AI(LLM)의 구조와 원리를 이해하고, 의료기기 품질관리·인허가·생산 업무에 프롬프트 엔지니어링 기법을 적용하여 업무 효율성을 향상시키며, 의료 데이터 보안·윤리·규제 가이드라인을 준수하는 AI 활용 역량을 갖추는 것을 목표로 함 | J19: IT 기본 지식을 습득하고 개발자와 원활히 소통하며, 컨설팅 업무에 필요한 IT 전문 지식과 생성형 AI에 대한 이해를 높여 실무에 바로 적용할 수 있는 역량을 키우는 것을 목표로 함
A20: {{edu_guidegoal}} | B20: 지도목표 | C20: 의료기기 산업의 AI 전환(AX) 환경을 이해하고, LLM 기반 생성형 AI 도구를 활용한 실습을 통해 의료기기 품질문서 작성, 규제 대응 자료 검토, CAPA 분석 등 실무 문제 해결 능력을 갖추어 업무의 정확성과 효율성을 높입니다. | J20: IT 기본 개념을 명확히 이해하고, 실습을 통해 능력을 키워 최신 AI 기술을 활용한 실무 문제 해결 능력을 갖추어 업무의 효율성을 높입니다.
A21: {{edu_guidegoaldetail}} | B21: 세부 지도목표 | C21: * 생성형 AI(LLM)의 구조, 학습 방식, 토큰 처리 등 핵심 작동 원리 설명 * 의료기기 산업(GMP, 인허가, 임상)에서의 AI 적용 가능 영역과 한계 이해 * 프롬프트 엔지니어링의 3요소(역할·맥락·출력형식)와 의료기기 직무별 적용 방법 습득 * 의료 데이터 비식별화, 저작권, AI 윤리 및 사내 보안 가이드라인 기초 역량 확보 | J21: * 운영체제, 서버, 클라우드 인프라의 기본 개념 설명 * 데이터베이스의 기초 지식과 데이터 관리 방법 이해 * 생성형 AI와 LLM의 원리 및 적용 사례 소개 * IT 용어와 개념을 쉽게 설명하고 실제 사례를 통해 이해 증진
A22: {{edu_guidegoaldetail-1}} | B22: 지도내용 | C22: [LLM 구조 및 의료 산업 특화 작동 원리 이해] - AI 패러다임 변화와 의료기기 산업에의 영향 - 생성형 AI 모델(GPT, Claude) 구조 및 작동 원리 - 의료·바이오 분야 AI 적용 사례와 한계 - ChatGPT, Claude 기초 툴 실습 | J22: [IT 기본 개념] - 운영체제와 서버의 기본 개념 - 클라우드 인프라의 이해
A23: {{edu_guidegoaldetail-2}} | C23: [업무 전환을 위한 프롬프트 기본 구조 실습] - 프롬프트 3요소(역할·맥락·출력형식) 이해 - 의료기기 품질문서 맥락 부여 및 컨텍스트 설정 - 페르소나 및 출력 제어 기법(QMS 문서, CAPA 보고서 등) - 의료기기 직무별(품질관리, RA, R&D) 프롬프트 적용 실습 | J23: [데이터베이스와 개발 기초] - 데이터베이스 기초 개념 - 개발 관련 기초 지식 및 용어
A24: {{edu_guidegoaldetail-3}} | C24: [민감정보 처리, 저작권, 윤리 가이드라인] - 의료 AI 윤리 개요 및 규제 프레임워크(MFDS, FDA) - 의료 데이터 개인정보 비식별화 기법과 실습 - AI 생성물의 저작권 이슈 및 의료기기 문서 활용 시 유의사항 - 사내 AI 보안 가이드라인 수립 기초 | J24: [생성형 AI와 LLM] - 생성형 AI의 개념과 원리 - LLM의 동작 원리 및 실제 사례
A25: {{edu_learnhow}} | B25: 교수학습방법 | C25: 강의: 슬라이드 및 영상 자료를 활용하여 LLM 구조, 의료기기 규제 환경 등 이론적 내용을 시각적으로 전달하고, 의료기기 산업 실제 AI 적용 사례 중심으로 설명 실습: ChatGPT, Claude를 활용한 의료기기 품질문서 초안 작성, CAPA 보고서 프롬프트 설계, 비식별화 도구 체험 등 직무 밀착형 실습 수행 토론: 의료기기 기업의 AI 도입 시 규제·윤리·보안 이슈에 대한 사례 기반 그룹 토론을 통해 실무 적용 판단력 배양 Q&A: 각 모듈별 실시간 질의응답을 통해 이해도 점검 및 즉각 피드백 제공 | J25: 강의: 슬라이드 및 영상 자료를 활용하여 시각적 이해를 돕고, 사례 중심으로 설명 실습: 간단한 클라우드 설정 및 데이터베이스 생성 실습 토론: 실제 사례에 기반한 토론을 통해 실무 적용 능력 배양 Q&A: 실시간 질문을 통해 이해도 점검 및 피드백 제공
A26: {{edu_testhow}} | B26: 평가방법 | C26: 모듈별 Q&A 세션을 통해 핵심 개념 이해도 확인 프롬프트 설계 실습 결과물(의료기기 품질문서 초안, CAPA 보고서 등) 발표 및 동료·강사 피드백 의료 데이터 비식별화 실습 과제 수행 결과 평가 | J26: 간단한 Q&A 세션을 통해 이해도 확인 실습 결과물 발표 및 피드백
A27: {{edu_book}} | B27: 훈련교재 | C27: 자체교재 | J27: 자체교재
A28: {{edu_future}} | B28: 연계 훈련과정 (해당 훈련과정의 중장기 체계적 운영의 적정성을 위한 레벨업 실시 계획) | C28: [Basic] Lv.1 - 의료·바이오 AI 리터러시 입문 Lv.2 - AI 활용 문서 작성 및 데이터 분석 기초 Lv.3 - AI 워크플로우의 이해 및 실습 [Advance] Lv.4 - QA/QMS AX 문서 자동화 및 품질 AI 워크플로 설계 Lv.5 - 의료기기 제조공정 문서 AI 자동화 및 공정 데이터 분석 Lv.5 - 의료기기 개발(품질,임상,공정) 데이터 기반 의사결정 워크플로 및 대시보드 설계 Lv.4 - R&D 요구사항·설계 자동화 및 Traceability 구축 [Expert] Lv.6 - 제조 공정 AI 워크플로 MVP 구축 | J28: [Basic] Lv.1 - 기획자와 컨설턴트를 위한 AI개발의 이해 Lv.2 - 바이브코딩 이론 및 실습 Lv.2 - 웹서비스 배포 전략 및 클라우드 서비스의 이해 [Advance] Lv.3 - 데이터베이스 이해 및 실습 1 (MySQL) Lv.3 - 데이터베이스 이해 및 실습 2 (Supabase) Lv.3 - 데이터베이스 이해 및 실습 3 (Firebase) Lv.4 - 웹앱서비스운영전략 Lv.5 - 개발에서 배포 운영까지의 파이프라인 구축
A29: {{edu_needreason}} | B29: 사업 필요성&목적 | C29: 의료기기 산업은 AI 전환(AX)이 가속화되고 있으나, 현장 실무자들은 생성형 AI의 활용 방법과 규제 환경에 대한 이해가 부족하여 업무 적용에 어려움을 겪는 경우가 많음. 또한 품질관리, 인허가(RA), R&D 등 직무별 수요조사 결과 AI 리터러시 교육의 필요성이 제기됨. 본 과정은 이러한 현장의 AI 역량 격차를 해소하고, 의료기기 GMP·인허가·생산 실무에 생성형 AI를 안전하게 접목할 수 있는 기초 역량을 배양하여 업무의 정확성과 효율성을 높일 수 있다 | J29: 기획자들의 경우 개발자와의 커뮤니케이션에서 어려움을 겪는 경우가 많음, 또한 관련 직무의 수요조사 결과 관련된 교육의 필요성이 제기됨 본 과정은 이런 소통과 기획자의 직무에 필요한 IT관련 기초지식을 배양하여 직무관련 역량을 높이며, 바이브코딩을 통해 업무의 프로세스와 효율을 높일 수 있다
A30: {{edu_curri}} | B30: 커리큘럼 요약 | C30: 생성형 AI(LLM)의 구조와 작동 원리를 의료·바이오 산업 맥락에서 이해하고, AI 패러다임 변화가 의료기기 산업에 미치는 영향과 적용 사례를 학습하며 ChatGPT, Claude 등 기초 툴을 실습한다. 업무 전환을 위해 프롬프트 엔지니어링의 기본 구조(역할·맥락·출력형식)와 컨텍스트 설계, 페르소나 설정 및 출력 제어 방법을 익히고 의료기기 직무별(품질관리, RA, R&D) 적용 실습을 진행한다. 의료 AI 윤리 및 규제 프레임워크(MFDS, FDA), 개인정보 비식별화 기법, AI 생성물의 저작권 이슈 및 사내 보안 가이드라인을 학습하여 민감정보를 안전하게 처리하는 역량을 강화한다. | J30: LLM(예: ChatGPT, Claude)의 구조와 생성형 AI 패러다임을 이해하고, 의료·바이오 산업에서의 적용 가능성과 한계를 학습하며 기초 툴을 실습한다. 업무 전환을 위해 프롬프트의 기본 구조와 컨텍스트 설계, 페르소나 설정 및 출력 제어 방법을 익히고 직무별 적용 실습을 진행한다. 의료 AI 윤리, 개인정보 비식별화, 저작권 및 사내 보안 가이드라인을 학습하여 민감정보를 안전하게 처리하는 역량을 강화한다.
D33: 능력단위코드 | E33: 능력단위 명 | F33: 훈련시간 | G33: 능력단위요소 코드 | H33: 능력단위요소 명 | I33: 훈련시간
C34: =IFERROR(G34,"") -> 2001010211_16v3.1 | D34: =VLOOKUP(J34,통합!$A$3:$H$44,6,FALSE) -> 1903090101_21v2 | E34: =VLOOKUP(J34,통합!$A$3:$H$44,8,FALSE) -> 의료기기 품질문서 개발 | F34: =IF(COUNTIF($D$69:$D$118,D34)=0,"",COUNTIF($D$69:$D$118,D34)) -> 1 | G34: 2001010211_16v3.1 | H34: 하드웨어 분석하기 | I34: =IF(COUNTIF($G$69:$G$118,G34)=0,"",COUNTIF($G$69:$G$118,G34)) -> 1 | J34: 09.의료장비제조 > 01.의료기기품질관리> 의료기기 품질문서 개발
C35: =IFERROR(G35,"") -> 0 | F35: =IF(COUNTIF($D$69:$D$118,D35)=0,"",COUNTIF($D$69:$D$118,D35)) | I35: =IF(COUNTIF($G$69:$G$118,G35)=0,"",COUNTIF($G$69:$G$118,G35))
C36: =IFERROR(G36,"") -> 0 | F36: =IF(COUNTIF($D$69:$D$118,D36)=0,"",COUNTIF($D$69:$D$118,D36)) | I36: =IF(COUNTIF($G$69:$G$118,G36)=0,"",COUNTIF($G$69:$G$118,G36))
C37: =IFERROR(G37,"") -> 0 | F37: =IF(COUNTIF($D$69:$D$118,D37)=0,"",COUNTIF($D$69:$D$118,D37)) | I37: =IF(COUNTIF($G$69:$G$118,G37)=0,"",COUNTIF($G$69:$G$118,G37))
C38: =IFERROR(G38,"") -> 0 | F38: =IF(COUNTIF($D$69:$D$118,D38)=0,"",COUNTIF($D$69:$D$118,D38)) | I38: =IF(COUNTIF($G$69:$G$118,G38)=0,"",COUNTIF($G$69:$G$118,G38))
C39: =IFERROR(G39,"") -> 0 | F39: =IF(COUNTIF($D$69:$D$118,D39)=0,"",COUNTIF($D$69:$D$118,D39)) | I39: =IF(COUNTIF($G$69:$G$118,G39)=0,"",COUNTIF($G$69:$G$118,G39))
C40: =IFERROR(G40,"") -> 0 | F40: =IF(COUNTIF($D$69:$D$118,D40)=0,"",COUNTIF($D$69:$D$118,D40)) | I40: =IF(COUNTIF($G$69:$G$118,G40)=0,"",COUNTIF($G$69:$G$118,G40))
C41: =IFERROR(G41,"") -> 0 | F41: =IF(COUNTIF($D$69:$D$118,D41)=0,"",COUNTIF($D$69:$D$118,D41)) | I41: =IF(COUNTIF($G$69:$G$118,G41)=0,"",COUNTIF($G$69:$G$118,G41))
C42: =IFERROR(G42,"") -> 0 | F42: =IF(COUNTIF($D$69:$D$118,D42)=0,"",COUNTIF($D$69:$D$118,D42)) | I42: =IF(COUNTIF($G$69:$G$118,G42)=0,"",COUNTIF($G$69:$G$118,G42))
...

Sheet AFX2-AI문서데이터
A1: 커리큘럼 기초 내용
B2: 분류선택 | C2: 09.의료장비제조 > 01.의료기기품질관리> 의료기기 품질시스템 자원관리
A3: {{edu_title}} | B3: 훈련과정명 | C3: AI 활용 문서 작성 및 데이터 분석 기초 | J3: 기획자와 컨설턴트를 위한 AI개발의 이해
B4: 커리큘럼 | C4: LLM 구조 및 의료 산업 특화 작동 원리 이해 (ChatGPT, Claude) 1. AI 패러다임 변화 2. 생성형 AI 모델 구조 이해 3. 의료/바이오 적용 한계와 가능성 4. 기초 툴 실습 업무 전환을 위한 프롬프트 기본 구조 실습 (ChatGPT 등) 1. 프롬프트 3요소 2. 컨텍스트 부여 방법 3. 페르소나 및 출력 제어 4. 직무별 적용 실습 민감정보 처리, 저작권, 윤리 가이드라인 학습 (비식별화 툴) 1. 의료 AI 윤리 개요 2. 개인정보 비식별화 역량 3. 저작권 문제 4. 사내 보안 가이드라인 기초
A5: {{edu_cate01}} | B5: 대분류 | C5: =VLOOKUP($C$2,통합!$A$3:$H$44,2,FALSE) -> 03.전자기기개발
A6: {{edu_cate02}} | B6: 중분류 | C6: =VLOOKUP($C$2,통합!$A$3:$H$44,3,FALSE) -> 09.의료장비제조
A7: {{edu_cate03}} | B7: 소분류 | C7: =VLOOKUP($C$2,통합!$A$3:$H$44,4,FALSE) -> 01.의료기기품질관리
A8: {{edu_cate04}} | B8: 세분류 | C8: =VLOOKUP($C$2,통합!$A$3:$H$44,7,FALSE)&"."&VLOOKUP($C$2,통합!$A$3:$H$44,8,FALSE) -> 02.의료기기 품질시스템 자원관리
A9: {{edu_cate05}} | B9: 훈련방법 | C9: =VLOOKUP($C$2,통합!$A$3:$H$44,6,FALSE) -> 1903090102_21v2
A10: {{edu_ncslevel}} | B10: 훈련수준 | C10: =VLOOKUP($C$2,통합!$A$3:$H$44,5,FALSE) -> 4
A11: {{edu_time}} | B11: 훈련시간 | C11: =F66&"시간( "&K119&"일)" -> 1시간( 0일) | J11: 000시간(00일)
A12: 교육과정 세부 정보
A13: {{edu_target}} | B13: 훈련대상자 | C13: 의료기기 개발·제조 기업 종사자 중 품질관리(QMS), 인허가(RA), 생산관리, R&D, 임상 등 부서에서 AI를 활용한 문서 작성 및 데이터 분석 역량이 필요한 실무자 및 관리자 | J13: 기획자, 컨설턴트, 디자이너 등 개발과 AI에 이해가 필요한 직무
A14: {{edu_job}} | B14: 대상직종 | C14: 품질관리자, 인허가담당자(RA), 생산관리자, R&D 연구원, 임상담당자 | J14: 기획자
A15: {{edu_limit}} | B15: 정원 | C15: 20명 | J15: 00명
A16: {{edu_feature}} | B16: 훈련과정 특성 | C16: 4차 산업혁명 핵심 기술인 생성형 AI를 의료기기 품질관리·인허가·생산 등 실무 문서 작성 및 데이터 분석에 직접 적용하는 신기술 융복합 과정임. 의료기기 GMP(QMS), IEC 62304, FDA/MFDS 규제 환경에서 요구되는 절차서·보고서·품질문서를 AI 도구로 효율적으로 작성하고, 비정형 데이터를 정형화·시각화하여 의사결정을 지원하는 미래전략산업 직종 대응 과정임 | J16: 4차 산업혁명 등 관련된 신기술, 융복합, 미래전략산업 직종 과정 등 훈련과정의 특성 기재
A17: {{edu_summary}} | B17: 주요훈련내용 | C17: 본 과정은 의료기기 산업 종사자를 대상으로 Claude, ChatGPT, Gemini, NotebookLM 등 생성형 AI 도구를 활용하여 문헌 요약, 절차서·보고서 초안 작성, 비즈니스 글쓰기 제어 등 문서 작성 실무를 학습함. 또한 AI 생성물의 환각(Hallucination) 원인 분석, 출처·수치 교차 검증 프롬프트 설계, 팩트체크 루틴 체크리스트 수립 등 검증 역량을 배양하며, 비정형 데이터를 정형화하고 Excel, Google Spreadsheet, Tableau 등을 활용한 시각화 및 인사이트 도출·리포팅 실습을 수행함 | J17: 주요훈련내용을 요약해서 작성
A18: {{edu_ncsreason}} | B18: NCS 미적용 사유 | C18: 본 과정은 의료기기 품질시스템 자원관리(NCS 세분류 1903090102)를 기반으로 하되, 기존 NCS 능력단위에 생성형 AI를 활용한 문서 작성·팩트체크·데이터 분석 역량이 미반영되어 있어, 의료기기 산업 현장의 AI 기반 문서 자동화 및 데이터 분석 수요와 규제 환경(MFDS, FDA, IEC 62304)에 맞춘 교육 내용을 별도 설계하여 NCS 비적용으로 운영함 | J18: 주요훈련내용을 요약해서 작성
A19: {{edu_goal}} | B19: 훈련목표 | C19: 의료기기 개발·제조 실무자가 생성형 AI 도구를 활용하여 품질문서·절차서·보고서를 효율적으로 작성하고, AI 생성물의 정확성을 팩트체크 기법으로 검증하며, 비정형 데이터를 정형화·시각화하여 데이터 기반 의사결정 역량을 갖추는 것을 목표로 함 | J19: IT 기본 지식을 습득하고 개발자와 원활히 소통하며, 컨설팅 업무에 필요한 IT 전문 지식과 생성형 AI에 대한 이해를 높여 실무에 바로 적용할 수 있는 역량을 키우는 것을 목표로 함
A20: {{edu_guidegoal}} | B20: 지도목표 | C20: 의료기기 산업의 문서 작성 및 데이터 분석 업무에 생성형 AI 도구를 체계적으로 활용하는 실습을 통해, 품질문서·절차서 초안 작성 속도와 정확성을 높이고, AI 생성 결과물의 팩트체크 역량을 확보하며, 비정형 데이터의 정형화·시각화를 통한 인사이트 도출 능력을 갖추어 업무의 효율성과 신뢰성을 높입니다. | J20: IT 기본 개념을 명확히 이해하고, 실습을 통해 능력을 키워 최신 AI 기술을 활용한 실무 문제 해결 능력을 갖추어 업무의 효율성을 높입니다.
A21: {{edu_guidegoaldetail}} | B21: 세부 지도목표 | C21: * 생성형 AI(Claude, ChatGPT, Gemini, NotebookLM)를 활용한 대용량 문헌 요약 및 템플릿 기반 보고서 초안 작성 역량 습득 * AI 생성물의 환각(Hallucination) 원인 분석 및 출처·수치 교차 검증 프롬프트 설계 능력 확보 * 비정형 데이터를 정형화하고 Excel, Google Spreadsheet, Tableau를 활용한 시각화 및 리포팅 실습 * 의료기기 품질문서(QMS, DHF, CAPA) 맥락에서의 AI 활용 실무 적용 사례를 통해 이해 증진 | J21: * 운영체제, 서버, 클라우드 인프라의 기본 개념 설명 * 데이터베이스의 기초 지식과 데이터 관리 방법 이해 * 생성형 AI와 LLM의 원리 및 적용 사례 소개 * IT 용어와 개념을 쉽게 설명하고 실제 사례를 통해 이해 증진
A22: {{edu_guidegoaldetail-1}} | B22: 지도내용 | C22: [문헌, 절차서 요약 및 보고서 기초 실무] - 대용량 의료기기 규격·문헌 정보 압축 및 핵심 추출 - 의료기기 절차서·품질문서 템플릿 기반 초안 생성 - 비즈니스 글쓰기 톤·형식 제어 및 결과물 리뷰·보완 | J22: [IT 기본 개념] - 운영체제와 서버의 기본 개념 - 클라우드 인프라의 이해
A23: {{edu_guidegoaldetail-2}} | C23: [출처 및 수치 근거를 점검하는 팩트체크 기법] - AI 환각(Hallucination) 원인 분석 및 발생 패턴 이해 - 의료기기 규제 문서의 출처·수치 교차 검증 프롬프트 설계 - 팩트체크 검증 루틴 체크리스트 작성 및 적용 실습 | J23: [데이터베이스와 개발 기초] - 데이터베이스 기초 개념 - 개발 관련 기초 지식 및 용어
A24: {{edu_guidegoaldetail-3}} | C24: [비정형 데이터 정형화 및 AI 분석 실습] - 의료기기 품질·생산·임상 비정형 데이터 분석 기획 - 데이터 정제 프롬프트 설계 및 정형화 실습 - Excel, Google Spreadsheet, Tableau를 활용한 시각화 및 인사이트 도출·리포팅 | J24: [생성형 AI와 LLM] - 생성형 AI의 개념과 원리 - LLM의 동작 원리 및 실제 사례
A25: {{edu_learnhow}} | B25: 교수학습방법 | C25: 강의: 슬라이드 및 영상 자료를 활용하여 AI 문서 작성 원리, 팩트체크 기법, 데이터 분석 방법론을 의료기기 산업 실제 사례 중심으로 설명 실습: Claude, ChatGPT, Gemini, NotebookLM을 활용한 의료기기 절차서·보고서 초안 작성, 팩트체크 프롬프트 설계, Excel·Tableau 기반 데이터 시각화 등 직무 밀착형 실습 수행 토론: 의료기기 문서 AI 자동화 시 규제 적합성, 데이터 신뢰성 등 실무 이슈에 대한 사례 기반 그룹 토론 Q&A: 각 모듈별 실시간 질의응답을 통해 이해도 점검 및 즉각 피드백 제공 | J25: 강의: 슬라이드 및 영상 자료를 활용하여 시각적 이해를 돕고, 사례 중심으로 설명 실습: 간단한 클라우드 설정 및 데이터베이스 생성 실습 토론: 실제 사례에 기반한 토론을 통해 실무 적용 능력 배양 Q&A: 실시간 질문을 통해 이해도 점검 및 피드백 제공
A26: {{edu_testhow}} | B26: 평가방법 | C26: 모듈별 Q&A 세션을 통해 핵심 개념 이해도 확인 AI 활용 문서 작성 실습 결과물(절차서 초안, 보고서 등) 발표 및 동료·강사 피드백 팩트체크 체크리스트 작성 과제 및 데이터 시각화 결과물 평가 | J26: 간단한 Q&A 세션을 통해 이해도 확인 실습 결과물 발표 및 피드백
A27: {{edu_book}} | B27: 훈련교재 | C27: 자체교재 | J27: 자체교재
A28: {{edu_future}} | B28: 연계 훈련과정 (해당 훈련과정의 중장기 체계적 운영의 적정성을 위한 레벨업 실시 계획) | C28: [Basic] Lv.1 - 의료·바이오 AI 리터러시 입문 Lv.2 - AI 활용 문서 작성 및 데이터 분석 기초 Lv.3 - AI 워크플로우의 이해 및 실습 [Advance] Lv.4 - QA/QMS AX 문서 자동화 및 품질 AI 워크플로 설계 Lv.5 - 의료기기 제조공정 문서 AI 자동화 및 공정 데이터 분석 Lv.5 - 의료기기 개발(품질,임상,공정) 데이터 기반 의사결정 워크플로 및 대시보드 설계 Lv.4 - R&D 요구사항·설계 자동화 및 Traceability 구축 [Expert] Lv.6 - 제조 공정 AI 워크플로 MVP 구축 | J28: [Basic] Lv.1 - 기획자와 컨설턴트를 위한 AI개발의 이해 Lv.2 - 바이브코딩 이론 및 실습 Lv.2 - 웹서비스 배포 전략 및 클라우드 서비스의 이해 [Advance] Lv.3 - 데이터베이스 이해 및 실습 1 (MySQL) Lv.3 - 데이터베이스 이해 및 실습 2 (Supabase) Lv.3 - 데이터베이스 이해 및 실습 3 (Firebase) Lv.4 - 웹앱서비스운영전략 Lv.5 - 개발에서 배포 운영까지의 파이프라인 구축
A29: {{edu_needreason}} | B29: 사업 필요성&목적 | C29: 의료기기 산업에서는 품질문서·절차서·보고서 등 대량의 문서 작성과 비정형 데이터 분석이 핵심 업무이나, 현장 실무자들은 AI 도구를 활용한 문서 자동화 및 데이터 분석 역량이 부족하여 업무 효율화에 한계를 겪고 있음. 또한 AI 생성물의 환각(Hallucination) 문제와 팩트체크 역량 부재로 규제 문서의 신뢰성 확보에 어려움이 제기됨. 본 과정은 이러한 현장의 문서 작성·데이터 분석 역량 격차를 해소하고, 생성형 AI를 활용한 품질문서 초안 작성, 팩트체크 검증, 비정형 데이터 정형화·시각화 역량을 배양하여 업무의 효율성과 신뢰성을 높일 수 있다 | J29: 기획자들의 경우 개발자와의 커뮤니케이션에서 어려움을 겪는 경우가 많음, 또한 관련 직무의 수요조사 결과 관련된 교육의 필요성이 제기됨 본 과정은 이런 소통과 기획자의 직무에 필요한 IT관련 기초지식을 배양하여 직무관련 역량을 높이며, 바이브코딩을 통해 업무의 프로세스와 효율을 높일 수 있다
A30: {{edu_curri}} | B30: 커리큘럼 요약 | C30: 생성형 AI(Claude, ChatGPT, Gemini, NotebookLM)를 활용하여 대용량 의료기기 규격·문헌을 요약하고, 절차서·품질문서 템플릿 기반 초안을 생성하며, 비즈니스 글쓰기 톤·형식 제어를 통해 문서 작성 실무 역량을 학습한다. AI 생성물의 환각(Hallucination) 원인과 발생 패턴을 분석하고, 의료기기 규제 문서의 출처·수치 교차 검증 프롬프트를 설계하며, 팩트체크 검증 루틴 체크리스트를 작성·적용하는 실습을 진행한다. 의료기기 품질·생산·임상 분야의 비정형 데이터를 분석·기획하고, 데이터 정제 프롬프트 설계 및 정형화 실습을 수행하며, Excel, Google Spreadsheet, Tableau를 활용한 시각화 및 인사이트 도출·리포팅 역량을 강화한다. | J30: LLM(예: ChatGPT, Claude)의 구조와 생성형 AI 패러다임을 이해하고, 의료·바이오 산업에서의 적용 가능성과 한계를 학습하며 기초 툴을 실습한다. 업무 전환을 위해 프롬프트의 기본 구조와 컨텍스트 설계, 페르소나 설정 및 출력 제어 방법을 익히고 직무별 적용 실습을 진행한다. 의료 AI 윤리, 개인정보 비식별화, 저작권 및 사내 보안 가이드라인을 학습하여 민감정보를 안전하게 처리하는 역량을 강화한다.
D33: 능력단위코드 | E33: 능력단위 명 | F33: 훈련시간 | G33: 능력단위요소 코드 | H33: 능력단위요소 명 | I33: 훈련시간
C34: =IFERROR(G34,"") -> 2001010211_16v3.1 | D34: =VLOOKUP(J34,통합!$A$3:$H$44,6,FALSE) -> 1903090101_21v2 | E34: =VLOOKUP(J34,통합!$A$3:$H$44,8,FALSE) -> 의료기기 품질문서 개발 | F34: =IF(COUNTIF($D$69:$D$118,D34)=0,"",COUNTIF($D$69:$D$118,D34)) -> 1 | G34: 2001010211_16v3.1 | H34: 하드웨어 분석하기 | I34: =IF(COUNTIF($G$69:$G$118,G34)=0,"",COUNTIF($G$69:$G$118,G34)) -> 1 | J34: 09.의료장비제조 > 01.의료기기품질관리> 의료기기 품질문서 개발
C35: =IFERROR(G35,"") -> 0 | F35: =IF(COUNTIF($D$69:$D$118,D35)=0,"",COUNTIF($D$69:$D$118,D35)) | I35: =IF(COUNTIF($G$69:$G$118,G35)=0,"",COUNTIF($G$69:$G$118,G35))
C36: =IFERROR(G36,"") -> 0 | F36: =IF(COUNTIF($D$69:$D$118,D36)=0,"",COUNTIF($D$69:$D$118,D36)) | I36: =IF(COUNTIF($G$69:$G$118,G36)=0,"",COUNTIF($G$69:$G$118,G36))
C37: =IFERROR(G37,"") -> 0 | F37: =IF(COUNTIF($D$69:$D$118,D37)=0,"",COUNTIF($D$69:$D$118,D37)) | I37: =IF(COUNTIF($G$69:$G$118,G37)=0,"",COUNTIF($G$69:$G$118,G37))
C38: =IFERROR(G38,"") -> 0 | F38: =IF(COUNTIF($D$69:$D$118,D38)=0,"",COUNTIF($D$69:$D$118,D38)) | I38: =IF(COUNTIF($G$69:$G$118,G38)=0,"",COUNTIF($G$69:$G$118,G38))
C39: =IFERROR(G39,"") -> 0 | F39: =IF(COUNTIF($D$69:$D$118,D39)=0,"",COUNTIF($D$69:$D$118,D39)) | I39: =IF(COUNTIF($G$69:$G$118,G39)=0,"",COUNTIF($G$69:$G$118,G39))
C40: =IFERROR(G40,"") -> 0 | F40: =IF(COUNTIF($D$69:$D$118,D40)=0,"",COUNTIF($D$69:$D$118,D40)) | I40: =IF(COUNTIF($G$69:$G$118,G40)=0,"",COUNTIF($G$69:$G$118,G40))
C41: =IFERROR(G41,"") -> 0 | F41: =IF(COUNTIF($D$69:$D$118,D41)=0,"",COUNTIF($D$69:$D$118,D41)) | I41: =IF(COUNTIF($G$69:$G$118,G41)=0,"",COUNTIF($G$69:$G$118,G41))
C42: =IFERROR(G42,"") -> 0 | F42: =IF(COUNTIF($D$69:$D$118,D42)=0,"",COUNTIF($D$69:$D$118,D42)) | I42: =IF(COUNTIF($G$69:$G$118,G42)=0,"",COUNTIF($G$69:$G$118,G42))
...

Sheet AFX3-AI워크플로우
A1: 커리큘럼 기초 내용
B2: 분류선택 | C2: 09.의료장비제조 > 01.의료기기품질관리> 의료기기 품질시스템 자원관리
A3: {{edu_title}} | B3: 훈련과정명 | C3: AI 워크플로우의 이해 및 실습 | J3: 기획자와 컨설턴트를 위한 AI개발의 이해
B4: 커리큘럼 | C4: LLM 구조 및 의료 산업 특화 작동 원리 이해 (ChatGPT, Claude) 1. AI 패러다임 변화 2. 생성형 AI 모델 구조 이해 3. 의료/바이오 적용 한계와 가능성 4. 기초 툴 실습 업무 전환을 위한 프롬프트 기본 구조 실습 (ChatGPT 등) 1. 프롬프트 3요소 2. 컨텍스트 부여 방법 3. 페르소나 및 출력 제어 4. 직무별 적용 실습 민감정보 처리, 저작권, 윤리 가이드라인 학습 (비식별화 툴) 1. 의료 AI 윤리 개요 2. 개인정보 비식별화 역량 3. 저작권 문제 4. 사내 보안 가이드라인 기초
A5: {{edu_cate01}} | B5: 대분류 | C5: =VLOOKUP($C$2,통합!$A$3:$H$44,2,FALSE) -> 03.전자기기개발
A6: {{edu_cate02}} | B6: 중분류 | C6: =VLOOKUP($C$2,통합!$A$3:$H$44,3,FALSE) -> 09.의료장비제조
A7: {{edu_cate03}} | B7: 소분류 | C7: =VLOOKUP($C$2,통합!$A$3:$H$44,4,FALSE) -> 01.의료기기품질관리
A8: {{edu_cate04}} | B8: 세분류 | C8: =VLOOKUP($C$2,통합!$A$3:$H$44,7,FALSE)&"."&VLOOKUP($C$2,통합!$A$3:$H$44,8,FALSE) -> 02.의료기기 품질시스템 자원관리
A9: {{edu_cate05}} | B9: 훈련방법 | C9: =VLOOKUP($C$2,통합!$A$3:$H$44,6,FALSE) -> 1903090102_21v2
A10: {{edu_ncslevel}} | B10: 훈련수준 | C10: =VLOOKUP($C$2,통합!$A$3:$H$44,5,FALSE) -> 4
A11: {{edu_time}} | B11: 훈련시간 | C11: =F66&"시간( "&K119&"일)" -> 1시간( 0일) | J11: 000시간(00일)
A12: 교육과정 세부 정보
A13: {{edu_target}} | B13: 훈련대상자 | C13: 의료기기 개발·제조 기업 종사자 중 품질관리(QMS), 인허가(RA), 생산관리, R&D, 임상 등 부서에서 반복 업무의 AI 자동화 및 워크플로우 설계·구현 역량이 필요한 실무자 및 관리자 | J13: 기획자, 컨설턴트, 디자이너 등 개발과 AI에 이해가 필요한 직무
A14: {{edu_job}} | B14: 대상직종 | C14: 품질관리자, 인허가담당자(RA), 생산관리자, R&D 연구원, 임상담당자 | J14: 기획자
A15: {{edu_limit}} | B15: 정원 | C15: 20명 | J15: 00명
A16: {{edu_feature}} | B16: 훈련과정 특성 | C16: 4차 산업혁명 핵심 기술인 AI 워크플로우 자동화를 의료기기 품질관리·인허가·생산 등 실무 프로세스에 직접 적용하는 신기술 융복합 과정임. 의료기기 GMP(QMS), IEC 62304, FDA/MFDS 규제 환경에서 요구되는 반복 업무(문서 검토, 일탈 관리, CAPA 추적 등)를 AI 워크플로우 도구(n8n, Google AI Studio 등)로 자동화하고, 업무별 최적 AI 모델을 선정·배치하여 프로세스 효율성을 혁신하는 미래전략산업 직종 대응 과정임 | J16: 4차 산업혁명 등 관련된 신기술, 융복합, 미래전략산업 직종 과정 등 훈련과정의 특성 기재
A17: {{edu_summary}} | B17: 주요훈련내용 | C17: 본 과정은 의료기기 산업 종사자를 대상으로 직무 워크플로우를 체계적으로 분해하여 AI 개입이 가능한 병목 구간을 식별하고, 주요 AI 모델(GPT, Claude, Gemini 등)의 장단점을 비교하여 업무별 최적 도구를 매칭하는 역량을 배양함. 또한 n8n, Google AI Studio 등 노코드·로우코드 기반 AI 워크플로우 자동화 도구를 활용하여 의료기기 품질관리·인허가·생산 업무의 반복 프로세스를 자동화하는 실습 중심 교육을 실시함 | J17: 주요훈련내용을 요약해서 작성
A18: {{edu_ncsreason}} | B18: NCS 미적용 사유 | C18: 본 과정은 의료기기 품질시스템 자원관리(NCS 세분류 1903090102)를 기반으로 하되, 기존 NCS 능력단위에 AI 워크플로우 설계·구현, 업무 자동화 도구 활용, AI 모델 선정·배치 등의 역량이 미반영되어 있어, 의료기기 산업 현장의 업무 프로세스 자동화 수요와 규제 환경(MFDS, FDA, IEC 62304)에 맞춘 AI 워크플로우 교육 내용을 별도 설계하여 NCS 비적용으로 운영함 | J18: 주요훈련내용을 요약해서 작성
A19: {{edu_goal}} | B19: 훈련목표 | C19: 의료기기 개발·제조 실무자가 직무 워크플로우를 분해하여 AI 자동화 가능 지점을 발굴하고, 업무 특성에 맞는 AI 모델과 도구를 선정·매칭하며, n8n·Google AI Studio 등을 활용하여 의료기기 업무 프로세스를 자동화하는 워크플로우를 직접 설계·구현할 수 있는 역량을 갖추는 것을 목표로 함 | J19: IT 기본 지식을 습득하고 개발자와 원활히 소통하며, 컨설팅 업무에 필요한 IT 전문 지식과 생성형 AI에 대한 이해를 높여 실무에 바로 적용할 수 있는 역량을 키우는 것을 목표로 함
A20: {{edu_guidegoal}} | B20: 지도목표 | C20: 의료기기 산업의 업무 프로세스를 체계적으로 분석하고, AI 워크플로우 자동화 도구를 활용한 실습을 통해 품질관리·인허가·생산 업무의 반복 프로세스를 자동화하는 실무 문제 해결 능력을 갖추어 업무의 효율성과 정확성을 높입니다. | J20: IT 기본 개념을 명확히 이해하고, 실습을 통해 능력을 키워 최신 AI 기술을 활용한 실무 문제 해결 능력을 갖추어 업무의 효율성을 높입니다.
A21: {{edu_guidegoaldetail}} | B21: 세부 지도목표 | C21: * 직무 워크플로우 분해 기법을 활용하여 의료기기 업무의 병목 구간 식별 및 AI 개입 지점 매핑 역량 습득 * 주요 AI 모델(GPT, Claude, Gemini 등)의 특성 비교 및 의료기기 업무별 최적 도구 선정·배치 기준 이해 * n8n, Google AI Studio 등 노코드·로우코드 AI 워크플로우 도구를 활용한 업무 자동화 구현 실습 * 의료기기 규제 환경(GMP, MFDS, FDA)을 고려한 보안 환경별 도구 선택 및 멀티모달 기초 활용 사례를 통해 이해 증진 | J21: * 운영체제, 서버, 클라우드 인프라의 기본 개념 설명 * 데이터베이스의 기초 지식과 데이터 관리 방법 이해 * 생성형 AI와 LLM의 원리 및 적용 사례 소개 * IT 용어와 개념을 쉽게 설명하고 실제 사례를 통해 이해 증진
A22: {{edu_guidegoaldetail-1}} | B22: 지도내용 | C22: [업무 분해를 통한 AI 개입 지점 발굴] - 의료기기 직무 워크플로우(품질관리, RA, 생산 등) 분해 기법 - 업무 병목 구간 식별 및 AI 역할 재정의 - AI 개입 지점 매핑 및 결과 공유·토론 | J22: [IT 기본 개념] - 운영체제와 서버의 기본 개념 - 클라우드 인프라의 이해
A23: {{edu_guidegoaldetail-2}} | C23: [주요 모델별 장단점 비교 및 업무별 툴 매칭] - GPT, Claude, Gemini 등 주요 AI 모델 특성 비교 분석 - 의료기기 업무 특성에 맞는 적재적소 도구 배치 전략 - GMP·규제 환경별 보안 기준에 따른 도구 선택 및 멀티모달 기초 활용 | J23: [데이터베이스와 개발 기초] - 데이터베이스 기초 개념 - 개발 관련 기초 지식 및 용어
A24: {{edu_guidegoaldetail-3}} | C24: [AI워크플로우 구현 실습] - n8n 기반 의료기기 업무 AI 워크플로우 설계 및 구현 실습 - Google AI Studio를 활용한 AI 업무 자동화 파이프라인 구현 실습 - 의료기기 실무 시나리오(CAPA 추적, 일탈 관리, 문서 검토 자동화 등) 적용 | J24: [생성형 AI와 LLM] - 생성형 AI의 개념과 원리 - LLM의 동작 원리 및 실제 사례
A25: {{edu_learnhow}} | B25: 교수학습방법 | C25: 강의: 슬라이드 및 영상 자료를 활용하여 AI 워크플로우 설계 원리, 모델별 특성 비교, 보안 환경별 도구 선택 기준 등을 의료기기 산업 실제 사례 중심으로 설명 실습: n8n, Google AI Studio를 활용한 의료기기 업무 워크플로우 자동화 구현, 직무별 AI 개입 지점 매핑, 모델·도구 매칭 등 직무 밀착형 실습 수행 토론: 의료기기 업무 프로세스 자동화 시 규제 적합성, 보안, 실무 적용 이슈에 대한 사례 기반 그룹 토론 Q&A: 각 모듈별 실시간 질의응답을 통해 이해도 점검 및 즉각 피드백 제공 | J25: 강의: 슬라이드 및 영상 자료를 활용하여 시각적 이해를 돕고, 사례 중심으로 설명 실습: 간단한 클라우드 설정 및 데이터베이스 생성 실습 토론: 실제 사례에 기반한 토론을 통해 실무 적용 능력 배양 Q&A: 실시간 질문을 통해 이해도 점검 및 피드백 제공
A26: {{edu_testhow}} | B26: 평가방법 | C26: 모듈별 Q&A 세션을 통해 핵심 개념 이해도 확인 AI 워크플로우 구현 실습 결과물(n8n 워크플로우, Google AI Studio 자동화 파이프라인) 발표 및 동료·강사 피드백 직무 워크플로우 분해 및 AI 개입 지점 매핑 과제 수행 결과 평가 | J26: 간단한 Q&A 세션을 통해 이해도 확인 실습 결과물 발표 및 피드백
A27: {{edu_book}} | B27: 훈련교재 | C27: 자체교재 | J27: 자체교재
A28: {{edu_future}} | B28: 연계 훈련과정 (해당 훈련과정의 중장기 체계적 운영의 적정성을 위한 레벨업 실시 계획) | C28: [Basic] Lv.1 - 의료·바이오 AI 리터러시 입문 Lv.2 - AI 활용 문서 작성 및 데이터 분석 기초 Lv.3 - AI 워크플로우의 이해 및 실습 [Advance] Lv.4 - QA/QMS AX 문서 자동화 및 품질 AI 워크플로 설계 Lv.5 - 의료기기 제조공정 문서 AI 자동화 및 공정 데이터 분석 Lv.5 - 의료기기 개발(품질,임상,공정) 데이터 기반 의사결정 워크플로 및 대시보드 설계 Lv.4 - R&D 요구사항·설계 자동화 및 Traceability 구축 [Expert] Lv.6 - 제조 공정 AI 워크플로 MVP 구축 | J28: [Basic] Lv.1 - 기획자와 컨설턴트를 위한 AI개발의 이해 Lv.2 - 바이브코딩 이론 및 실습 Lv.2 - 웹서비스 배포 전략 및 클라우드 서비스의 이해 [Advance] Lv.3 - 데이터베이스 이해 및 실습 1 (MySQL) Lv.3 - 데이터베이스 이해 및 실습 2 (Supabase) Lv.3 - 데이터베이스 이해 및 실습 3 (Firebase) Lv.4 - 웹앱서비스운영전략 Lv.5 - 개발에서 배포 운영까지의 파이프라인 구축
A29: {{edu_needreason}} | B29: 사업 필요성&목적 | C29: 의료기기 산업에서는 품질관리·인허가·생산 등 반복 업무의 비중이 높으나, 현장 실무자들은 AI 워크플로우 설계·자동화 역량이 부족하여 업무 프로세스 혁신에 한계를 겪고 있음. 또한 업무별 최적 AI 모델 선정 기준과 노코드·로우코드 자동화 도구 활용 역량에 대한 교육 수요가 제기됨. 본 과정은 이러한 현장의 업무 자동화 역량 격차를 해소하고, 직무 워크플로우를 체계적으로 분해하여 AI 개입 지점을 발굴하며, n8n·Google AI Studio 등을 활용한 업무 프로세스 자동화 역량을 배양하여 업무의 효율성과 정확성을 높일 수 있다 | J29: 기획자들의 경우 개발자와의 커뮤니케이션에서 어려움을 겪는 경우가 많음, 또한 관련 직무의 수요조사 결과 관련된 교육의 필요성이 제기됨 본 과정은 이런 소통과 기획자의 직무에 필요한 IT관련 기초지식을 배양하여 직무관련 역량을 높이며, 바이브코딩을 통해 업무의 프로세스와 효율을 높일 수 있다
A30: {{edu_curri}} | B30: 커리큘럼 요약 | C30: 의료기기 직무 워크플로우(품질관리, RA, 생산 등)를 체계적으로 분해하여 업무 병목 구간을 식별하고, AI 개입 지점을 매핑하여 업무 자동화 가능 영역을 발굴하는 실습을 진행한다. 주요 AI 모델(GPT, Claude, Gemini 등)의 특성과 장단점을 비교 분석하고, 의료기기 업무 특성에 맞는 적재적소 도구 배치 전략을 수립하며, GMP·규제 환경별 보안 기준에 따른 도구 선택 및 멀티모달 기초 활용 방법을 학습한다. n8n 기반 의료기기 업무 AI 워크플로우 설계·구현과 Google AI Studio를 활용한 자동화 파이프라인 구현 실습을 수행하며, CAPA 추적·일탈 관리·문서 검토 자동화 등 실무 시나리오에 적용하는 역량을 강화한다. | J30: LLM(예: ChatGPT, Claude)의 구조와 생성형 AI 패러다임을 이해하고, 의료·바이오 산업에서의 적용 가능성과 한계를 학습하며 기초 툴을 실습한다. 업무 전환을 위해 프롬프트의 기본 구조와 컨텍스트 설계, 페르소나 설정 및 출력 제어 방법을 익히고 직무별 적용 실습을 진행한다. 의료 AI 윤리, 개인정보 비식별화, 저작권 및 사내 보안 가이드라인을 학습하여 민감정보를 안전하게 처리하는 역량을 강화한다.
D33: 능력단위코드 | E33: 능력단위 명 | F33: 훈련시간 | G33: 능력단위요소 코드 | H33: 능력단위요소 명 | I33: 훈련시간
C34: =IFERROR(G34,"") -> 2001010211_16v3.1 | D34: =VLOOKUP(J34,통합!$A$3:$H$44,6,FALSE) -> 1903090101_21v2 | E34: =VLOOKUP(J34,통합!$A$3:$H$44,8,FALSE) -> 의료기기 품질문서 개발 | F34: =IF(COUNTIF($D$69:$D$118,D34)=0,"",COUNTIF($D$69:$D$118,D34)) -> 1 | G34: 2001010211_16v3.1 | H34: 하드웨어 분석하기 | I34: =IF(COUNTIF($G$69:$G$118,G34)=0,"",COUNTIF($G$69:$G$118,G34)) -> 1 | J34: 09.의료장비제조 > 01.의료기기품질관리> 의료기기 품질문서 개발
C35: =IFERROR(G35,"") -> 0 | F35: =IF(COUNTIF($D$69:$D$118,D35)=0,"",COUNTIF($D$69:$D$118,D35)) | I35: =IF(COUNTIF($G$69:$G$118,G35)=0,"",COUNTIF($G$69:$G$118,G35))
C36: =IFERROR(G36,"") -> 0 | F36: =IF(COUNTIF($D$69:$D$118,D36)=0,"",COUNTIF($D$69:$D$118,D36)) | I36: =IF(COUNTIF($G$69:$G$118,G36)=0,"",COUNTIF($G$69:$G$118,G36))
C37: =IFERROR(G37,"") -> 0 | F37: =IF(COUNTIF($D$69:$D$118,D37)=0,"",COUNTIF($D$69:$D$118,D37)) | I37: =IF(COUNTIF($G$69:$G$118,G37)=0,"",COUNTIF($G$69:$G$118,G37))
C38: =IFERROR(G38,"") -> 0 | F38: =IF(COUNTIF($D$69:$D$118,D38)=0,"",COUNTIF($D$69:$D$118,D38)) | I38: =IF(COUNTIF($G$69:$G$118,G38)=0,"",COUNTIF($G$69:$G$118,G38))
C39: =IFERROR(G39,"") -> 0 | F39: =IF(COUNTIF($D$69:$D$118,D39)=0,"",COUNTIF($D$69:$D$118,D39)) | I39: =IF(COUNTIF($G$69:$G$118,G39)=0,"",COUNTIF($G$69:$G$118,G39))
C40: =IFERROR(G40,"") -> 0 | F40: =IF(COUNTIF($D$69:$D$118,D40)=0,"",COUNTIF($D$69:$D$118,D40)) | I40: =IF(COUNTIF($G$69:$G$118,G40)=0,"",COUNTIF($G$69:$G$118,G40))
C41: =IFERROR(G41,"") -> 0 | F41: =IF(COUNTIF($D$69:$D$118,D41)=0,"",COUNTIF($D$69:$D$118,D41)) | I41: =IF(COUNTIF($G$69:$G$118,G41)=0,"",COUNTIF($G$69:$G$118,G41))
C42: =IFERROR(G42,"") -> 0 | F42: =IF(COUNTIF($D$69:$D$118,D42)=0,"",COUNTIF($D$69:$D$118,D42)) | I42: =IF(COUNTIF($G$69:$G$118,G42)=0,"",COUNTIF($G$69:$G$118,G42))
...

Sheet ALX1-QA품질보증
A1: 커리큘럼 기초 내용
B2: 분류선택 | C2: 09.의료장비제조 > 01.의료기기품질관리> 의료기기 품질시스템 자원관리
A3: {{edu_title}} | B3: 훈련과정명 | C3: QA/QMS AX 문서 자동화 및 품질 AI 워크플로 설계 | J3: 기획자와 컨설턴트를 위한 AI개발의 이해
B4: 커리큘럼 | C4: LLM 구조 및 의료 산업 특화 작동 원리 이해 (ChatGPT, Claude) 1. AI 패러다임 변화 2. 생성형 AI 모델 구조 이해 3. 의료/바이오 적용 한계와 가능성 4. 기초 툴 실습 업무 전환을 위한 프롬프트 기본 구조 실습 (ChatGPT 등) 1. 프롬프트 3요소 2. 컨텍스트 부여 방법 3. 페르소나 및 출력 제어 4. 직무별 적용 실습 민감정보 처리, 저작권, 윤리 가이드라인 학습 (비식별화 툴) 1. 의료 AI 윤리 개요 2. 개인정보 비식별화 역량 3. 저작권 문제 4. 사내 보안 가이드라인 기초
A5: {{edu_cate01}} | B5: 대분류 | C5: =VLOOKUP($C$2,통합!$A$3:$H$44,2,FALSE) -> 03.전자기기개발
A6: {{edu_cate02}} | B6: 중분류 | C6: =VLOOKUP($C$2,통합!$A$3:$H$44,3,FALSE) -> 09.의료장비제조
A7: {{edu_cate03}} | B7: 소분류 | C7: =VLOOKUP($C$2,통합!$A$3:$H$44,4,FALSE) -> 01.의료기기품질관리
A8: {{edu_cate04}} | B8: 세분류 | C8: =VLOOKUP($C$2,통합!$A$3:$H$44,7,FALSE)&"."&VLOOKUP($C$2,통합!$A$3:$H$44,8,FALSE) -> 02.의료기기 품질시스템 자원관리
A9: {{edu_cate05}} | B9: 훈련방법 | C9: =VLOOKUP($C$2,통합!$A$3:$H$44,6,FALSE) -> 1903090102_21v2
A10: {{edu_ncslevel}} | B10: 훈련수준 | C10: =VLOOKUP($C$2,통합!$A$3:$H$44,5,FALSE) -> 4
A11: {{edu_time}} | B11: 훈련시간 | C11: =F66&"시간( "&K119&"일)" -> 1시간( 0일) | J11: 000시간(00일)
A12: 교육과정 세부 정보
A13: {{edu_target}} | B13: 훈련대상자 | C13: 의료기기 개발·제조 기업의 품질보증(QA) 및 품질관리(QC) 부서 종사자로, ISO 13485 기반 QMS 체계 내 반복 문서(SOP, CAPA, 내부감사 보고서 등) 작성·관리 업무를 수행하며, AI 기반 문서 자동화 및 품질 워크플로 설계 역량이 필요한 실무자 및 관리자 | J13: 기획자, 컨설턴트, 디자이너 등 개발과 AI에 이해가 필요한 직무
A14: {{edu_job}} | B14: 대상직종 | C14: 품질보증(QA)담당자, 품질관리(QC)담당자, QMS 문서관리자, 내부감사원 | J14: 기획자
A15: {{edu_limit}} | B15: 정원 | C15: 20명 | J15: 00명
A16: {{edu_feature}} | B16: 훈련과정 특성 | C16: 4차 산업혁명 핵심 기술인 생성형 AI를 의료기기 QA/QMS 직무에 특화하여 적용하는 신기술 융복합 과정임. ISO 13485 품질경영시스템 체계 내 반복 문서(SOP, CAPA, 내부감사 체크리스트 등)를 GPT/Claude 기반으로 구조화·자동 생성하고, 문서 작성 → 검증 → 이력관리까지의 전체 품질 프로세스를 n8n 노코드 자동화 및 엑셀/구글시트 기반 품질 로그 분석과 결합하여 하나의 품질 AI 워크플로로 구축하는 미래전략산업 직종 대응 과정임 | J16: 4차 산업혁명 등 관련된 신기술, 융복합, 미래전략산업 직종 과정 등 훈련과정의 특성 기재
A17: {{edu_summary}} | B17: 주요훈련내용 | C17: 본 과정은 ISO 13485 및 QMS 체계 내 반복 문서(SOP, CAPA, 내부감사)를 AI 기반으로 구조화하고, 문서 작성 → 검증 → 이력관리까지 하나의 품질 AI 워크플로로 구축하는 실습 중심 교육을 실시함. QMS 반복문서 구조 분석, ISO 요구사항 자동 매핑 구조 설계, CAPA 보고서 AI 논리 구조화, 내부감사 체크리스트 자동 생성, 문서 검증 체크리스트 자동화, QA 워크플로 자동화 설계 등 6개 모듈을 통해 GPT/Claude 기반 문서 생성, Office for Claude & Claude Cowork 기반 문서 작성, 내부 템플릿 프롬프트 설계, n8n 노코드 자동화, 엑셀/구글시트 기반 품질 로그 자동 분석 역량을 배양함 | J17: 주요훈련내용을 요약해서 작성
A18: {{edu_ncsreason}} | B18: NCS 미적용 사유 | C18: 본 과정은 의료기기 품질시스템 자원관리(NCS 세분류 1903090102)를 기반으로 하되, 기존 NCS 능력단위에 AI 기반 QMS 문서 자동화, 품질 AI 워크플로 설계·구현, ISO 요구사항 자동 매핑, n8n 노코드 자동화 등의 역량이 미반영되어 있어, 의료기기 QA/QMS 현장의 AI 전환(AX) 수요와 규제 환경(ISO 13485, MFDS, FDA)에 맞춘 교육 내용을 별도 설계하여 NCS 비적용으로 운영함 | J18: 주요훈련내용을 요약해서 작성
A19: {{edu_goal}} | B19: 훈련목표 | C19: 의료기기 QA/QMS 실무자가 ISO 13485 체계 내 반복 문서(SOP, CAPA, 내부감사 보고서 등)를 생성형 AI 도구로 구조화·자동 생성하고, 문서 검증 체크리스트를 자동화하며, 문서 작성부터 검증·이력관리까지 하나의 품질 AI 워크플로를 n8n 기반으로 설계·구축할 수 있는 역량을 갖추는 것을 목표로 함 | J19: IT 기본 지식을 습득하고 개발자와 원활히 소통하며, 컨설팅 업무에 필요한 IT 전문 지식과 생성형 AI에 대한 이해를 높여 실무에 바로 적용할 수 있는 역량을 키우는 것을 목표로 함
A20: {{edu_guidegoal}} | B20: 지도목표 | C20: ISO 13485 QMS 체계를 기반으로 AI 도구를 체계적으로 활용하는 실습을 통해, QMS 반복 문서의 구조화·자동 생성 역량을 키우고, 문서 검증 및 감사 대응 체크리스트를 자동화하며, 품질 프로세스 전반을 AI 워크플로로 통합·설계하여 QA 업무의 정확성·효율성·추적성을 높입니다. | J20: IT 기본 개념을 명확히 이해하고, 실습을 통해 능력을 키워 최신 AI 기술을 활용한 실무 문제 해결 능력을 갖추어 업무의 효율성을 높입니다.
A21: {{edu_guidegoaldetail}} | B21: 세부 지도목표 | C21: * ISO 13485 QMS 체계 내 반복 문서(SOP, CAPA, 내부감사 보고서) 구조 분석 및 AI 적용 지점 도출 역량 습득 * GPT/Claude 및 Office for Claude를 활용한 ISO 요구사항 자동 매핑 및 CAPA 보고서 AI 논리 구조화 기법 이해 * 내부감사 체크리스트·문서 검증 체크리스트의 AI 자동 생성 및 품질 로그 자동 분석 실습 * n8n 노코드 자동화 도구를 활용한 QA 워크플로(문서 작성 → 검증 → 이력관리) 설계·구축 사례를 통해 이해 증진 | J21: * 운영체제, 서버, 클라우드 인프라의 기본 개념 설명 * 데이터베이스의 기초 지식과 데이터 관리 방법 이해 * 생성형 AI와 LLM의 원리 및 적용 사례 소개 * IT 용어와 개념을 쉽게 설명하고 실제 사례를 통해 이해 증진
A22: {{edu_guidegoaldetail-1}} | B22: 지도내용 | C22: [QMS 반복문서 구조 분석 및 ISO 요구사항 자동 매핑] - ISO 13485 기반 QMS 반복 문서(SOP, CAPA, 내부감사) 구조 분석 - ISO 요구사항과 문서 항목 간 자동 매핑 구조 설계 - GPT/Claude를 활용한 문서 템플릿 프롬프트 설계 실습 | J22: [IT 기본 개념] - 운영체제와 서버의 기본 개념 - 클라우드 인프라의 이해
A23: {{edu_guidegoaldetail-2}} | C23: [CAPA 보고서 AI 구조화 및 문서 검증 자동화] - CAPA 보고서 AI 논리 구조화 및 자동 초안 생성 - 내부감사 체크리스트 AI 자동 생성 실습 - 문서 검증 체크리스트 자동화 및 품질 로그 분석 | J23: [데이터베이스와 개발 기초] - 데이터베이스 기초 개념 - 개발 관련 기초 지식 및 용어
A24: {{edu_guidegoaldetail-3}} | C24: [QA 워크플로 자동화 설계 및 산출물 완성] - n8n 기반 QA 워크플로 자동화 설계(문서 작성 → 검증 → 이력관리) - 엑셀/구글시트 기반 품질 로그 자동 분석 파이프라인 구현 - 산출물 완성: SOP 자동 작성 템플릿, CAPA 워크플로, 감사 대응 체크리스트, QA 플레이북 | J24: [생성형 AI와 LLM] - 생성형 AI의 개념과 원리 - LLM의 동작 원리 및 실제 사례
A25: {{edu_learnhow}} | B25: 교수학습방법 | C25: 강의: 슬라이드 및 영상 자료를 활용하여 ISO 13485 QMS 문서 체계, AI 문서 자동화 원리, n8n 워크플로 설계 방법론을 의료기기 QA 실제 사례 중심으로 설명 실습: GPT/Claude 기반 SOP·CAPA 보고서 자동 생성, Office for Claude를 활용한 문서 작성, 내부감사 체크리스트 자동화, n8n 기반 QA 워크플로 구축 등 직무 밀착형 실습 수행 토론: 의료기기 QA 업무의 AI 자동화 시 ISO 적합성, 문서 무결성, 감사 대응 전략 등 실무 이슈에 대한 사례 기반 그룹 토론 Q&A: 각 모듈별 실시간 질의응답을 통해 이해도 점검 및 즉각 피드백 제공 | J25: 강의: 슬라이드 및 영상 자료를 활용하여 시각적 이해를 돕고, 사례 중심으로 설명 실습: 간단한 클라우드 설정 및 데이터베이스 생성 실습 토론: 실제 사례에 기반한 토론을 통해 실무 적용 능력 배양 Q&A: 실시간 질문을 통해 이해도 점검 및 피드백 제공
A26: {{edu_testhow}} | B26: 평가방법 | C26: 모듈별 Q&A 세션을 통해 핵심 개념 이해도 확인 AI 기반 QMS 문서 자동화 실습 결과물(SOP 템플릿, CAPA 보고서, 감사 체크리스트, QA 플레이북) 발표 및 동료·강사 피드백 n8n QA 워크플로 자동화 설계 과제 수행 결과 평가 | J26: 간단한 Q&A 세션을 통해 이해도 확인 실습 결과물 발표 및 피드백
A27: {{edu_book}} | B27: 훈련교재 | C27: 자체교재 | J27: 자체교재
A28: {{edu_future}} | B28: 연계 훈련과정 (해당 훈련과정의 중장기 체계적 운영의 적정성을 위한 레벨업 실시 계획) | C28: [Basic] Lv.1 - 의료·바이오 AI 리터러시 입문 Lv.2 - AI 활용 문서 작성 및 데이터 분석 기초 Lv.3 - AI 워크플로우의 이해 및 실습 [Advance] Lv.4 - QA/QMS AX 문서 자동화 및 품질 AI 워크플로 설계 Lv.5 - 의료기기 제조공정 문서 AI 자동화 및 공정 데이터 분석 Lv.5 - 의료기기 개발(품질,임상,공정) 데이터 기반 의사결정 워크플로 및 대시보드 설계 Lv.4 - R&D 요구사항·설계 자동화 및 Traceability 구축 [Expert] Lv.6 - 제조 공정 AI 워크플로 MVP 구축 | J28: [Basic] Lv.1 - 기획자와 컨설턴트를 위한 AI개발의 이해 Lv.2 - 바이브코딩 이론 및 실습 Lv.2 - 웹서비스 배포 전략 및 클라우드 서비스의 이해 [Advance] Lv.3 - 데이터베이스 이해 및 실습 1 (MySQL) Lv.3 - 데이터베이스 이해 및 실습 2 (Supabase) Lv.3 - 데이터베이스 이해 및 실습 3 (Firebase) Lv.4 - 웹앱서비스운영전략 Lv.5 - 개발에서 배포 운영까지의 파이프라인 구축
A29: {{edu_needreason}} | B29: 사업 필요성&목적 | C29: 의료기기 QA/QMS 현장에서는 ISO 13485 체계 내 SOP, CAPA, 내부감사 보고서 등 반복 문서의 작성·관리 업무 부담이 높으나, AI 기반 문서 자동화 및 품질 워크플로 설계 역량이 부족하여 업무 효율화에 한계를 겪고 있음. 또한 문서 검증·이력관리의 수작업 의존도가 높아 정확성과 추적성 확보에 어려움이 제기됨. 본 과정은 이러한 현장의 QMS 문서 자동화 역량 격차를 해소하고, GPT/Claude 기반 문서 구조화·자동 생성, 검증 체크리스트 자동화, n8n 기반 품질 AI 워크플로 설계·구축 역량을 배양하여 QA 업무의 정확성·효율성·추적성을 높일 수 있다 | J29: 기획자들의 경우 개발자와의 커뮤니케이션에서 어려움을 겪는 경우가 많음, 또한 관련 직무의 수요조사 결과 관련된 교육의 필요성이 제기됨 본 과정은 이런 소통과 기획자의 직무에 필요한 IT관련 기초지식을 배양하여 직무관련 역량을 높이며, 바이브코딩을 통해 업무의 프로세스와 효율을 높일 수 있다
A30: {{edu_curri}} | B30: 커리큘럼 요약 | C30: ISO 13485 기반 QMS 반복 문서(SOP, CAPA, 내부감사)의 구조를 분석하고, ISO 요구사항과 문서 항목 간 자동 매핑 구조를 설계하며, GPT/Claude를 활용한 문서 템플릿 프롬프트 설계 실습을 진행한다. CAPA 보고서의 AI 논리 구조화 및 자동 초안 생성, 내부감사 체크리스트 AI 자동 생성, 문서 검증 체크리스트 자동화 및 품질 로그 분석 기법을 학습한다. n8n 기반 QA 워크플로 자동화(문서 작성 → 검증 → 이력관리)를 설계하고, 엑셀/구글시트 기반 품질 로그 자동 분석 파이프라인을 구현하며, SOP 자동 작성 템플릿·CAPA 워크플로·감사 대응 체크리스트·QA 플레이북 등 산출물을 완성하는 역량을 강화한다. | J30: LLM(예: ChatGPT, Claude)의 구조와 생성형 AI 패러다임을 이해하고, 의료·바이오 산업에서의 적용 가능성과 한계를 학습하며 기초 툴을 실습한다. 업무 전환을 위해 프롬프트의 기본 구조와 컨텍스트 설계, 페르소나 설정 및 출력 제어 방법을 익히고 직무별 적용 실습을 진행한다. 의료 AI 윤리, 개인정보 비식별화, 저작권 및 사내 보안 가이드라인을 학습하여 민감정보를 안전하게 처리하는 역량을 강화한다.
D33: 능력단위코드 | E33: 능력단위 명 | F33: 훈련시간 | G33: 능력단위요소 코드 | H33: 능력단위요소 명 | I33: 훈련시간
C34: =IFERROR(G34,"") -> 2001010211_16v3.1 | D34: =VLOOKUP(J34,통합!$A$3:$H$44,6,FALSE) -> 1903090101_21v2 | E34: =VLOOKUP(J34,통합!$A$3:$H$44,8,FALSE) -> 의료기기 품질문서 개발 | F34: =IF(COUNTIF($D$69:$D$118,D34)=0,"",COUNTIF($D$69:$D$118,D34)) -> 1 | G34: 2001010211_16v3.1 | H34: 하드웨어 분석하기 | I34: =IF(COUNTIF($G$69:$G$118,G34)=0,"",COUNTIF($G$69:$G$118,G34)) -> 1 | J34: 09.의료장비제조 > 01.의료기기품질관리> 의료기기 품질문서 개발
C35: =IFERROR(G35,"") -> 0 | F35: =IF(COUNTIF($D$69:$D$118,D35)=0,"",COUNTIF($D$69:$D$118,D35)) | I35: =IF(COUNTIF($G$69:$G$118,G35)=0,"",COUNTIF($G$69:$G$118,G35))
C36: =IFERROR(G36,"") -> 0 | F36: =IF(COUNTIF($D$69:$D$118,D36)=0,"",COUNTIF($D$69:$D$118,D36)) | I36: =IF(COUNTIF($G$69:$G$118,G36)=0,"",COUNTIF($G$69:$G$118,G36))
C37: =IFERROR(G37,"") -> 0 | F37: =IF(COUNTIF($D$69:$D$118,D37)=0,"",COUNTIF($D$69:$D$118,D37)) | I37: =IF(COUNTIF($G$69:$G$118,G37)=0,"",COUNTIF($G$69:$G$118,G37))
C38: =IFERROR(G38,"") -> 0 | F38: =IF(COUNTIF($D$69:$D$118,D38)=0,"",COUNTIF($D$69:$D$118,D38)) | I38: =IF(COUNTIF($G$69:$G$118,G38)=0,"",COUNTIF($G$69:$G$118,G38))
C39: =IFERROR(G39,"") -> 0 | F39: =IF(COUNTIF($D$69:$D$118,D39)=0,"",COUNTIF($D$69:$D$118,D39)) | I39: =IF(COUNTIF($G$69:$G$118,G39)=0,"",COUNTIF($G$69:$G$118,G39))
C40: =IFERROR(G40,"") -> 0 | F40: =IF(COUNTIF($D$69:$D$118,D40)=0,"",COUNTIF($D$69:$D$118,D40)) | I40: =IF(COUNTIF($G$69:$G$118,G40)=0,"",COUNTIF($G$69:$G$118,G40))
C41: =IFERROR(G41,"") -> 0 | F41: =IF(COUNTIF($D$69:$D$118,D41)=0,"",COUNTIF($D$69:$D$118,D41)) | I41: =IF(COUNTIF($G$69:$G$118,G41)=0,"",COUNTIF($G$69:$G$118,G41))
C42: =IFERROR(G42,"") -> 0 | F42: =IF(COUNTIF($D$69:$D$118,D42)=0,"",COUNTIF($D$69:$D$118,D42)) | I42: =IF(COUNTIF($G$69:$G$118,G42)=0,"",COUNTIF($G$69:$G$118,G42))
...

Sheet ALX2-제조공정문서
A1: 커리큘럼 기초 내용
B2: 분류선택 | C2: 09.의료장비제조 > 01.의료기기품질관리> 의료기기 품질시스템 자원관리
A3: {{edu_title}} | B3: 훈련과정명 | C3: 의료기기 제조공정 문서 AI 자동화 및 공정 데이터 분석 | J3: 기획자와 컨설턴트를 위한 AI개발의 이해
B4: 커리큘럼 | C4: LLM 구조 및 의료 산업 특화 작동 원리 이해 (ChatGPT, Claude) 1. AI 패러다임 변화 2. 생성형 AI 모델 구조 이해 3. 의료/바이오 적용 한계와 가능성 4. 기초 툴 실습 업무 전환을 위한 프롬프트 기본 구조 실습 (ChatGPT 등) 1. 프롬프트 3요소 2. 컨텍스트 부여 방법 3. 페르소나 및 출력 제어 4. 직무별 적용 실습 민감정보 처리, 저작권, 윤리 가이드라인 학습 (비식별화 툴) 1. 의료 AI 윤리 개요 2. 개인정보 비식별화 역량 3. 저작권 문제 4. 사내 보안 가이드라인 기초
A5: {{edu_cate01}} | B5: 대분류 | C5: =VLOOKUP($C$2,통합!$A$3:$H$44,2,FALSE) -> 03.전자기기개발
A6: {{edu_cate02}} | B6: 중분류 | C6: =VLOOKUP($C$2,통합!$A$3:$H$44,3,FALSE) -> 09.의료장비제조
A7: {{edu_cate03}} | B7: 소분류 | C7: =VLOOKUP($C$2,통합!$A$3:$H$44,4,FALSE) -> 01.의료기기품질관리
A8: {{edu_cate04}} | B8: 세분류 | C8: =VLOOKUP($C$2,통합!$A$3:$H$44,7,FALSE)&"."&VLOOKUP($C$2,통합!$A$3:$H$44,8,FALSE) -> 02.의료기기 품질시스템 자원관리
A9: {{edu_cate05}} | B9: 훈련방법 | C9: =VLOOKUP($C$2,통합!$A$3:$H$44,6,FALSE) -> 1903090102_21v2
A10: {{edu_ncslevel}} | B10: 훈련수준 | C10: =VLOOKUP($C$2,통합!$A$3:$H$44,5,FALSE) -> 4
A11: {{edu_time}} | B11: 훈련시간 | C11: =F66&"시간( "&K119&"일)" -> 1시간( 0일) | J11: 000시간(00일)
A12: 교육과정 세부 정보
A13: {{edu_target}} | B13: 훈련대상자 | C13: 의료기기 개발·제조 기업의 제조부문(생산관리, 공정관리, 제조품질) 종사자로, DMR/DHR, 제조기록서, 공정 밸리데이션 문서 등 제조공정 문서 작성·관리 업무를 수행하며, AI 기반 문서 자동화 및 공정 데이터 분석 역량이 필요한 실무자 및 관리자 | J13: 기획자, 컨설턴트, 디자이너 등 개발과 AI에 이해가 필요한 직무
A14: {{edu_job}} | B14: 대상직종 | C14: 생산관리자, 공정관리자, 제조품질담당자, 설비관리자 | J14: 기획자
A15: {{edu_limit}} | B15: 정원 | C15: 20명 | J15: 00명
A16: {{edu_feature}} | B16: 훈련과정 특성 | C16: 4차 산업혁명 핵심 기술인 생성형 AI를 의료기기 제조공정 직무에 특화하여 적용하는 신기술 융복합 과정임. 의료기기 GMP 제조관리 기준(KGMP, FDA 21 CFR Part 820) 체계 내 반복 문서(DMR, DHR, 제조기록서, 공정 밸리데이션 문서)를 GPT/Claude 기반으로 자동 생성·검증하고, 제조공정 데이터(수율, 일탈, 설비 가동률 등)를 AI로 분석하여 공정 개선 인사이트를 도출하는 미래전략산업 직종 대응 과정임 | J16: 4차 산업혁명 등 관련된 신기술, 융복합, 미래전략산업 직종 과정 등 훈련과정의 특성 기재
A17: {{edu_summary}} | B17: 주요훈련내용 | C17: 본 과정은 의료기기 제조부문 종사자를 대상으로 DMR/DHR 문서 구조를 분석하고 AI로 자동 생성하는 역량을 배양하며, 제조기록서·밸리데이션 문서를 GPT/Claude로 자동 초안 생성하는 실습을 수행함. 또한 제조공정 데이터(수율, 일탈, 설비 가동률)를 엑셀/구글시트 기반 AI 분석으로 시각화하고, 공정 이상 감지 및 예측 모델 기초를 이해하며, n8n 기반 제조공정 AI 워크플로를 설계하여 공정 개선 인사이트 리포팅 및 산출물을 완성하는 실습 중심 교육을 실시함 | J17: 주요훈련내용을 요약해서 작성
A18: {{edu_ncsreason}} | B18: NCS 미적용 사유 | C18: 본 과정은 의료기기 품질시스템 자원관리(NCS 세분류 1903090102)를 기반으로 하되, 기존 NCS 능력단위에 AI 기반 제조공정 문서 자동화, 공정 데이터 AI 분석, 이상 감지·예측 모델 활용, n8n 제조공정 워크플로 설계 등의 역량이 미반영되어 있어, 의료기기 제조부문의 AI 전환(AX) 수요와 규제 환경(KGMP, FDA 21 CFR Part 820)에 맞춘 교육 내용을 별도 설계하여 NCS 비적용으로 운영함 | J18: 주요훈련내용을 요약해서 작성
A19: {{edu_goal}} | B19: 훈련목표 | C19: 의료기기 제조부문 실무자가 제조공정 반복 문서(DMR, DHR, 제조기록서, 밸리데이션 문서)를 생성형 AI 도구로 자동 생성·검증하고, 제조공정 데이터를 AI로 분석하여 공정 이상 감지 및 개선 인사이트를 도출하며, n8n 기반 제조공정 AI 워크플로를 설계·구축할 수 있는 역럅을 갖추는 것을 목표로 함 | J19: IT 기본 지식을 습득하고 개발자와 원활히 소통하며, 컨설팅 업무에 필요한 IT 전문 지식과 생성형 AI에 대한 이해를 높여 실무에 바로 적용할 수 있는 역량을 키우는 것을 목표로 함
A20: {{edu_guidegoal}} | B20: 지도목표 | C20: 의료기기 제조공정의 문서 관리 및 데이터 분석 업무에 AI 도구를 체계적으로 활용하는 실습을 통해, 제조공정 문서 자동화 역럅을 키우고, 공정 데이터 기반 이상 감지·예측 및 개선 인사이트 도출 능력을 갖추어 제조 현장의 품질·생산성·추적성을 높입니다. | J20: IT 기본 개념을 명확히 이해하고, 실습을 통해 능력을 키워 최신 AI 기술을 활용한 실무 문제 해결 능력을 갖추어 업무의 효율성을 높입니다.
A21: {{edu_guidegoaldetail}} | B21: 세부 지도목표 | C21: * 의료기기 GMP 체계 내 DMR/DHR 문서 구조 분석 및 AI 자동 생성 적용 지점 도출 역량 습득 * GPT/Claude 및 Office for Claude를 활용한 제조기록서·밸리데이션 문서 자동 초안 생성 기법 이해 * 제조공정 데이터(수율, 일탈, 설비 가동률)의 AI 분석·시각화 및 공정 이상 감지·예측 모델 기초 이해 * n8n 기반 제조공정 AI 워크플로 설계·구축 및 공정 개선 인사이트 리포팅 사례를 통해 이해 증진 | J21: * 운영체제, 서버, 클라우드 인프라의 기본 개념 설명 * 데이터베이스의 기초 지식과 데이터 관리 방법 이해 * 생성형 AI와 LLM의 원리 및 적용 사례 소개 * IT 용어와 개념을 쉽게 설명하고 실제 사례를 통해 이해 증진
A22: {{edu_guidegoaldetail-1}} | B22: 지도내용 | C22: [DMR/DHR 문서 구조 분석 및 AI 제조문서 자동 생성] - 의료기기 GMP(KGMP, FDA 21 CFR Part 820) 기반 DMR/DHR 문서 구조 분석 - 제조기록서·밸리데이션 문서 AI 자동 초안 생성 실습 - GPT/Claude 및 Office for Claude 활용 템플릿 프롬프트 설계 | J22: [IT 기본 개념] - 운영체제와 서버의 기본 개념 - 클라우드 인프라의 이해
A23: {{edu_guidegoaldetail-2}} | C23: [제조공정 데이터 AI 분석 및 이상 감지·예측] - 제조공정 데이터(수율, 일탈, 설비 가동률) AI 분석 및 시각화 실습 - 공정 이상 감지 및 예측 모델 기초 이해(SPC·트렌드 분석) - 엑셀/구글시트 기반 공정 데이터 대시보드 구성 실습 | J23: [데이터베이스와 개발 기초] - 데이터베이스 기초 개념 - 개발 관련 기초 지식 및 용어
A24: {{edu_guidegoaldetail-3}} | C24: [제조공정 AI 워크플로 설계 및 산출물 완성] - n8n 기반 제조공정 AI 워크플로 자동화 설계(문서 생성 → 검증 → 공정데이터 분석) - 공정 개선 인사이트 리포팅 실습 - 산출물 완성: DMR/DHR 자동 작성 템플릿, 제조기록서 AI 워크플로, 공정 데이터 대시보드, 제조공정 AI 플레이북 | J24: [생성형 AI와 LLM] - 생성형 AI의 개념과 원리 - LLM의 동작 원리 및 실제 사례
A25: {{edu_learnhow}} | B25: 교수학습방법 | C25: 강의: 슬라이드 및 영상 자료를 활용하여 의료기기 GMP 제조문서 체계, AI 문서 자동화 원리, 공정 데이터 분석 방법론을 제조 현장 실제 사례 중심으로 설명 실습: GPT/Claude 기반 DMR/DHR·제조기록서 자동 생성, 엑셀/구글시트 기반 공정 데이터 시각화, n8n 기반 제조공정 워크플로 구축 등 직무 밀착형 실습 수행 토론: 의료기기 제조공정 AI 자동화 시 GMP 적합성, 데이터 무결성, 공정 변경관리 등 실무 이슈에 대한 사례 기반 그룹 토론 Q&A: 각 모듈별 실시간 질의응답을 통해 이해도 점검 및 즉각 피드백 제공 | J25: 강의: 슬라이드 및 영상 자료를 활용하여 시각적 이해를 돕고, 사례 중심으로 설명 실습: 간단한 클라우드 설정 및 데이터베이스 생성 실습 토론: 실제 사례에 기반한 토론을 통해 실무 적용 능력 배양 Q&A: 실시간 질문을 통해 이해도 점검 및 피드백 제공
A26: {{edu_testhow}} | B26: 평가방법 | C26: 모듈별 Q&A 세션을 통해 핵심 개념 이해도 확인 AI 기반 제조공정 문서 자동화 실습 결과물(DMR/DHR 템플릿, 제조기록서 워크플로, 공정 대시보드, AI 플레이북) 발표 및 동료·강사 피드백 공정 데이터 분석 및 인사이트 리포팅 과제 수행 결과 평가 | J26: 간단한 Q&A 세션을 통해 이해도 확인 실습 결과물 발표 및 피드백
A27: {{edu_book}} | B27: 훈련교재 | C27: 자체교재 | J27: 자체교재
A28: {{edu_future}} | B28: 연계 훈련과정 (해당 훈련과정의 중장기 체계적 운영의 적정성을 위한 레벨업 실시 계획) | C28: [Basic] Lv.1 - 의료·바이오 AI 리터러시 입문 Lv.2 - AI 활용 문서 작성 및 데이터 분석 기초 Lv.3 - AI 워크플로우의 이해 및 실습 [Advance] Lv.4 - QA/QMS AX 문서 자동화 및 품질 AI 워크플로 설계 Lv.5 - 의료기기 제조공정 문서 AI 자동화 및 공정 데이터 분석 Lv.5 - 의료기기 개발(품질,임상,공정) 데이터 기반 의사결정 워크플로 및 대시보드 설계 Lv.4 - R&D 요구사항·설계 자동화 및 Traceability 구축 [Expert] Lv.6 - 제조 공정 AI 워크플로 MVP 구축 | J28: [Basic] Lv.1 - 기획자와 컨설턴트를 위한 AI개발의 이해 Lv.2 - 바이브코딩 이론 및 실습 Lv.2 - 웹서비스 배포 전략 및 클라우드 서비스의 이해 [Advance] Lv.3 - 데이터베이스 이해 및 실습 1 (MySQL) Lv.3 - 데이터베이스 이해 및 실습 2 (Supabase) Lv.3 - 데이터베이스 이해 및 실습 3 (Firebase) Lv.4 - 웹앱서비스운영전략 Lv.5 - 개발에서 배포 운영까지의 파이프라인 구축
A29: {{edu_needreason}} | B29: 사업 필요성&목적 | C29: 의료기기 제조부문에서는 DMR/DHR, 제조기록서, 공정 밸리데이션 문서 등 반복 문서의 작성·관리 부담이 높으나, AI 기반 문서 자동화 및 공정 데이터 분석 역량이 부족하여 업무 효율화에 한계를 겪고 있음. 또한 제조공정 데이터(수율, 일탈, 설비 가동률)의 체계적 분석과 이상 감지·예측 역량에 대한 현장 교육 수요가 제기됨. 본 과정은 이러한 현장의 제조공정 문서 자동화·데이터 분석 역량 격차를 해소하고, GPT/Claude 기반 제조문서 자동 생성·검증, 공정 데이터 AI 분석·시각화, n8n 기반 제조공정 AI 워크플로 설계·구축 역량을 배양하여 제조 현장의 품질·생산성·추적성을 높일 수 있다 | J29: 기획자들의 경우 개발자와의 커뮤니케이션에서 어려움을 겪는 경우가 많음, 또한 관련 직무의 수요조사 결과 관련된 교육의 필요성이 제기됨 본 과정은 이런 소통과 기획자의 직무에 필요한 IT관련 기초지식을 배양하여 직무관련 역량을 높이며, 바이브코딩을 통해 업무의 프로세스와 효율을 높일 수 있다
A30: {{edu_curri}} | B30: 커리큘럼 요약 | C30: 의료기기 GMP(KGMP, FDA 21 CFR Part 820) 기반 DMR/DHR 문서 구조를 분석하고, 제조기록서·밸리데이션 문서의 AI 자동 초안 생성 실습을 수행하며, GPT/Claude 및 Office for Claude를 활용한 템플릿 프롬프트 설계 역량을 학습한다. 제조공정 데이터(수율, 일탈, 설비 가동률)를 AI로 분석·시각화하고, 공정 이상 감지 및 예측 모델(SPC·트렌드 분석) 기초를 이해하며, 엑셀/구글시트 기반 공정 데이터 대시보드를 구성하는 실습을 진행한다. n8n 기반 제조공정 AI 워크플로 자동화(문서 생성 → 검증 → 공정데이터 분석)를 설계하고, 공정 개선 인사이트 리포팅 실습을 수행하며, DMR/DHR 자동 작성 템플릿·제조기록서 AI 워크플로·공정 데이터 대시보드·제조공정 AI 플레이북 등 산출물을 완성하는 역량을 강화한다. | J30: LLM(예: ChatGPT, Claude)의 구조와 생성형 AI 패러다임을 이해하고, 의료·바이오 산업에서의 적용 가능성과 한계를 학습하며 기초 툴을 실습한다. 업무 전환을 위해 프롬프트의 기본 구조와 컨텍스트 설계, 페르소나 설정 및 출력 제어 방법을 익히고 직무별 적용 실습을 진행한다. 의료 AI 윤리, 개인정보 비식별화, 저작권 및 사내 보안 가이드라인을 학습하여 민감정보를 안전하게 처리하는 역량을 강화한다.
D33: 능력단위코드 | E33: 능력단위 명 | F33: 훈련시간 | G33: 능력단위요소 코드 | H33: 능력단위요소 명 | I33: 훈련시간
C34: =IFERROR(G34,"") -> 2001010211_16v3.1 | D34: =VLOOKUP(J34,통합!$A$3:$H$44,6,FALSE) -> 1903090101_21v2 | E34: =VLOOKUP(J34,통합!$A$3:$H$44,8,FALSE) -> 의료기기 품질문서 개발 | F34: =IF(COUNTIF($D$69:$D$118,D34)=0,"",COUNTIF($D$69:$D$118,D34)) -> 1 | G34: 2001010211_16v3.1 | H34: 하드웨어 분석하기 | I34: =IF(COUNTIF($G$69:$G$118,G34)=0,"",COUNTIF($G$69:$G$118,G34)) -> 1 | J34: 09.의료장비제조 > 01.의료기기품질관리> 의료기기 품질문서 개발
C35: =IFERROR(G35,"") -> 0 | F35: =IF(COUNTIF($D$69:$D$118,D35)=0,"",COUNTIF($D$69:$D$118,D35)) | I35: =IF(COUNTIF($G$69:$G$118,G35)=0,"",COUNTIF($G$69:$G$118,G35))
C36: =IFERROR(G36,"") -> 0 | F36: =IF(COUNTIF($D$69:$D$118,D36)=0,"",COUNTIF($D$69:$D$118,D36)) | I36: =IF(COUNTIF($G$69:$G$118,G36)=0,"",COUNTIF($G$69:$G$118,G36))
C37: =IFERROR(G37,"") -> 0 | F37: =IF(COUNTIF($D$69:$D$118,D37)=0,"",COUNTIF($D$69:$D$118,D37)) | I37: =IF(COUNTIF($G$69:$G$118,G37)=0,"",COUNTIF($G$69:$G$118,G37))
C38: =IFERROR(G38,"") -> 0 | F38: =IF(COUNTIF($D$69:$D$118,D38)=0,"",COUNTIF($D$69:$D$118,D38)) | I38: =IF(COUNTIF($G$69:$G$118,G38)=0,"",COUNTIF($G$69:$G$118,G38))
C39: =IFERROR(G39,"") -> 0 | F39: =IF(COUNTIF($D$69:$D$118,D39)=0,"",COUNTIF($D$69:$D$118,D39)) | I39: =IF(COUNTIF($G$69:$G$118,G39)=0,"",COUNTIF($G$69:$G$118,G39))
C40: =IFERROR(G40,"") -> 0 | F40: =IF(COUNTIF($D$69:$D$118,D40)=0,"",COUNTIF($D$69:$D$118,D40)) | I40: =IF(COUNTIF($G$69:$G$118,G40)=0,"",COUNTIF($G$69:$G$118,G40))
C41: =IFERROR(G41,"") -> 0 | F41: =IF(COUNTIF($D$69:$D$118,D41)=0,"",COUNTIF($D$69:$D$118,D41)) | I41: =IF(COUNTIF($G$69:$G$118,G41)=0,"",COUNTIF($G$69:$G$118,G41))
C42: =IFERROR(G42,"") -> 0 | F42: =IF(COUNTIF($D$69:$D$118,D42)=0,"",COUNTIF($D$69:$D$118,D42)) | I42: =IF(COUNTIF($G$69:$G$118,G42)=0,"",COUNTIF($G$69:$G$118,G42))
...

Sheet ALX3-데이터기반의사결정
A1: 커리큘럼 기초 내용
B2: 분류선택 | C2: 09.의료장비제조 > 01.의료기기품질관리> 의료기기 품질시스템 자원관리
A3: {{edu_title}} | B3: 훈련과정명 | C3: 의료기기 개발(품질,임상,공정) 데이터 기반 의사결정 워크플로 및 대시보드 설계 | J3: 기획자와 컨설턴트를 위한 AI개발의 이해
B4: 커리큘럼 | C4: LLM 구조 및 의료 산업 특화 작동 원리 이해 (ChatGPT, Claude) 1. AI 패러다임 변화 2. 생성형 AI 모델 구조 이해 3. 의료/바이오 적용 한계와 가능성 4. 기초 툴 실습 업무 전환을 위한 프롬프트 기본 구조 실습 (ChatGPT 등) 1. 프롬프트 3요소 2. 컨텍스트 부여 방법 3. 페르소나 및 출력 제어 4. 직무별 적용 실습 민감정보 처리, 저작권, 윤리 가이드라인 학습 (비식별화 툴) 1. 의료 AI 윤리 개요 2. 개인정보 비식별화 역량 3. 저작권 문제 4. 사내 보안 가이드라인 기초
A5: {{edu_cate01}} | B5: 대분류 | C5: =VLOOKUP($C$2,통합!$A$3:$H$44,2,FALSE) -> 03.전자기기개발
A6: {{edu_cate02}} | B6: 중분류 | C6: =VLOOKUP($C$2,통합!$A$3:$H$44,3,FALSE) -> 09.의료장비제조
A7: {{edu_cate03}} | B7: 소분류 | C7: =VLOOKUP($C$2,통합!$A$3:$H$44,4,FALSE) -> 01.의료기기품질관리
A8: {{edu_cate04}} | B8: 세분류 | C8: =VLOOKUP($C$2,통합!$A$3:$H$44,7,FALSE)&"."&VLOOKUP($C$2,통합!$A$3:$H$44,8,FALSE) -> 02.의료기기 품질시스템 자원관리
A9: {{edu_cate05}} | B9: 훈련방법 | C9: =VLOOKUP($C$2,통합!$A$3:$H$44,6,FALSE) -> 1903090102_21v2
A10: {{edu_ncslevel}} | B10: 훈련수준 | C10: =VLOOKUP($C$2,통합!$A$3:$H$44,5,FALSE) -> 4
A11: {{edu_time}} | B11: 훈련시간 | C11: =F66&"시간( "&K119&"일)" -> 1시간( 0일) | J11: 000시간(00일)
A12: 교육과정 세부 정보
A13: {{edu_target}} | B13: 훈련대상자 | C13: 의료기기 개발·제조 기업의 품질(QA), 임상(Clinical), 제조공정(Process) 부서 종사자 중 부서별 분산 데이터를 통합·분석하여 KPI 기반 의사결정 체계를 구축하고, Python/Streamlit 기반 대시보드 및 자동 리포트 시스템 설계 역량이 필요한 실무자 및 관리자 | J13: 기획자, 컨설턴트, 디자이너 등 개발과 AI에 이해가 필요한 직무
A14: {{edu_job}} | B14: 대상직종 | C14: 품질보증(QA)담당자, 임상담당자, 생산관리자, 공정관리자, 데이터분석 담당자 | J14: 기획자
A15: {{edu_limit}} | B15: 정원 | C15: 20명 | J15: 00명
A16: {{edu_feature}} | B16: 훈련과정 특성 | C16: 4차 산업혁명 핵심 기술인 AI·데이터 분석을 의료기기 품질·임상·공정 전 영역에 걸쳐 통합 적용하는 신기술 융복합 과정임. 기존 부서별 엑셀 개별 관리·수동 집계·복붙 보고서 방식(As-Is)에서 데이터 수집 → 자동 정제 → KPI 자동 계산 → 시각화 대시보드 → AI 자동 분석 코멘트 → 보고서 자동 생성(To-Be)으로의 AX 전환을 실현하는 미래전략산업 직종 대응 과정임. Python/바이브코딩, Pandas, Streamlit, GPT 기반 분석 등 실무 도구를 활용하여 의료기기 GMP(QMS), 임상시험, 제조공정 규제 환경에 적합한 데이터 기반 의사결정 체계를 구축함 | J16: 4차 산업혁명 등 관련된 신기술, 융복합, 미래전략산업 직종 과정 등 훈련과정의 특성 기재
A17: {{edu_summary}} | B17: 주요훈련내용 | C17: 본 과정은 의료기기 산업의 품질(QA)·임상(Clinical)·제조공정(Process) 데이터를 통합하여 의사결정이 자동으로 생성되는 AI 워크플로를 구축하는 2일 과정임. Day 1에서는 의료기기 데이터 유형을 분석하고, Pandas 기반 데이터 정제, KPI 수식 설계, 자동 분석 코드 생성(바이브코딩) 실습을 수행함. Day 2에서는 Streamlit 기반 내부 KPI 대시보드를 제작하고, KPI 시각화 구성, GPT 기반 자동 해석 코멘트 생성, 내부 분석 워크플로 완성 및 자동 리포트 생성 프로그램을 구축함 | J17: 주요훈련내용을 요약해서 작성
A18: {{edu_ncsreason}} | B18: NCS 미적용 사유 | C18: 본 과정은 의료기기 품질시스템 자원관리(NCS 세분류 1903090102)를 기반으로 하되, 기존 NCS 능력단위에 Python/바이브코딩 기반 데이터 분석, Streamlit 대시보드 설계, GPT 기반 자동 분석·리포팅, 품질·임상·공정 데이터 통합 KPI 체계 구축, AI 기반 의사결정 워크플로 자동화 등의 역량이 미반영되어 있어, 의료기기 산업 현장의 데이터 기반 의사결정(AX) 수요와 규제 환경(ISO 13485, MFDS, FDA)에 맞춘 교육 내용을 별도 설계하여 NCS 비적용으로 운영함 | J18: 주요훈련내용을 요약해서 작성
A19: {{edu_goal}} | B19: 훈련목표 | C19: 의료기기 개발·제조 실무자가 품질·임상·공정 부서별 분산 데이터를 통합·정제하고, KPI를 체계적으로 설계하여 Streamlit 기반 의사결정 대시보드를 직접 구축하며, GPT를 활용한 자동 분석 코멘트 및 리포트 생성 워크플로를 완성하여 데이터 기반 의사결정 역량을 갖추는 것을 목표로 함 | J19: IT 기본 지식을 습득하고 개발자와 원활히 소통하며, 컨설팅 업무에 필요한 IT 전문 지식과 생성형 AI에 대한 이해를 높여 실무에 바로 적용할 수 있는 역량을 키우는 것을 목표로 함
A20: {{edu_guidegoal}} | B20: 지도목표 | C20: 의료기기 산업의 품질·임상·공정 데이터를 Python/Pandas로 정제·분석하고, Streamlit 기반 KPI 대시보드를 직접 구축하는 실습을 통해, 기존 수동 집계·개인 역량 의존 방식에서 AI 자동 분석·리포팅 체계로의 전환 역량을 갖추어 데이터 기반 의사결정의 정확성·신속성·일관성을 높입니다. | J20: IT 기본 개념을 명확히 이해하고, 실습을 통해 능력을 키워 최신 AI 기술을 활용한 실무 문제 해결 능력을 갖추어 업무의 효율성을 높입니다.
A21: {{edu_guidegoaldetail}} | B21: 세부 지도목표 | C21: * 의료기기 품질·임상·공정 데이터 유형 분석 및 Pandas 기반 데이터 정제·구조화 역량 습득 * KPI 수식 설계(수율, 일탈률, CAPA 완료율, 임상 등록률 등) 및 자동 분석 코드 생성(바이브코딩) 기법 이해 * Streamlit 기반 내부 KPI 대시보드 설계·제작 및 시각화 구성 실습 * GPT 기반 자동 해석 코멘트 생성 및 내부 분석 워크플로 완성·자동 리포트 프로그램 구축 사례를 통해 이해 증진 | J21: * 운영체제, 서버, 클라우드 인프라의 기본 개념 설명 * 데이터베이스의 기초 지식과 데이터 관리 방법 이해 * 생성형 AI와 LLM의 원리 및 적용 사례 소개 * IT 용어와 개념을 쉽게 설명하고 실제 사례를 통해 이해 증진
A22: {{edu_guidegoaldetail-1}} | B22: 지도내용 | C22: [Day 1 – 데이터 구조화 및 KPI 설계] - 의료기기 품질·임상·공정 데이터 유형 분석 및 현황 진단 - Pandas 기반 데이터 정제·정렬·구조화 실습 - KPI 수식 설계(수율, 일탈률, CAPA 완료율, 임상 등록률 등) - 바이브코딩을 활용한 자동 분석 코드 생성 실습 | J22: [IT 기본 개념] - 운영체제와 서버의 기본 개념 - 클라우드 인프라의 이해
A23: {{edu_guidegoaldetail-2}} | C23: [Day 2-① – 대시보드 제작 및 시각화] - Streamlit 기반 내부 KPI 대시보드 앱 제작 실습 - 품질·임상·공정 KPI 시각화 구성(차트, 테이블, 필터) - 부서별 데이터 통합 뷰 설계 및 인터랙티브 기능 구현 | J23: [데이터베이스와 개발 기초] - 데이터베이스 기초 개념 - 개발 관련 기초 지식 및 용어
A24: {{edu_guidegoaldetail-3}} | C24: [Day 2-② – AI 자동 해석 및 워크플로 완성] - GPT 기반 KPI 자동 해석 코멘트 생성 실습 - 내부 분석 워크플로 완성(데이터 수집 → 정제 → KPI → 시각화 → AI 코멘트 → 리포트) - 자동 리포트 생성 프로그램 구축 - 산출물 완성: KPI 대시보드, Python 코드, 자동 리포트, KPI 정의 문서, 의사결정 프레임워크 | J24: [생성형 AI와 LLM] - 생성형 AI의 개념과 원리 - LLM의 동작 원리 및 실제 사례
A25: {{edu_learnhow}} | B25: 교수학습방법 | C25: 강의: 슬라이드 및 영상 자료를 활용하여 의료기기 데이터 유형, KPI 설계 방법론, Streamlit 아키텍처, GPT 연동 원리 등을 품질·임상·공정 실제 사례 중심으로 설명 실습: Python/Pandas 기반 데이터 정제, KPI 자동 분석 코드 생성(바이브코딩), Streamlit 대시보드 제작, GPT 자동 해석 연동 등 직무 밀착형 실습 수행 토론: 의료기기 데이터 통합 시 부서 간 데이터 표준화, KPI 정의 합의, 규제 적합성 등 실무 이슈에 대한 사례 기반 그룹 토론 Q&A: 각 모듈별 실시간 질의응답을 통해 이해도 점검 및 즉각 피드백 제공 | J25: 강의: 슬라이드 및 영상 자료를 활용하여 시각적 이해를 돕고, 사례 중심으로 설명 실습: 간단한 클라우드 설정 및 데이터베이스 생성 실습 토론: 실제 사례에 기반한 토론을 통해 실무 적용 능력 배양 Q&A: 실시간 질문을 통해 이해도 점검 및 피드백 제공
A26: {{edu_testhow}} | B26: 평가방법 | C26: 모듈별 Q&A 세션을 통해 핵심 개념 이해도 확인 Day 1 실습 결과물(데이터 정제 코드, KPI 수식 설계서) 중간 점검 및 피드백 Day 2 최종 산출물 5종(KPI 대시보드, Python 코드, 자동 리포트, KPI 정의 문서, 의사결정 프레임워크) 발표 및 동료·강사 피드백 전체 워크플로 완성도 및 실무 적용 가능성 종합 평가 | J26: 간단한 Q&A 세션을 통해 이해도 확인 실습 결과물 발표 및 피드백
A27: {{edu_book}} | B27: 훈련교재 | C27: 자체교재 | J27: 자체교재
A28: {{edu_future}} | B28: 연계 훈련과정 (해당 훈련과정의 중장기 체계적 운영의 적정성을 위한 레벨업 실시 계획) | C28: [Basic] Lv.1 - 의료·바이오 AI 리터러시 입문 Lv.2 - AI 활용 문서 작성 및 데이터 분석 기초 Lv.3 - AI 워크플로우의 이해 및 실습 [Advance] Lv.4 - QA/QMS AX 문서 자동화 및 품질 AI 워크플로 설계 Lv.5 - 의료기기 제조공정 문서 AI 자동화 및 공정 데이터 분석 Lv.5 - 의료기기 개발(품질,임상,공정) 데이터 기반 의사결정 워크플로 및 대시보드 설계 Lv.4 - R&D 요구사항·설계 자동화 및 Traceability 구축 [Expert] Lv.6 - 제조 공정 AI 워크플로 MVP 구축 | J28: [Basic] Lv.1 - 기획자와 컨설턴트를 위한 AI개발의 이해 Lv.2 - 바이브코딩 이론 및 실습 Lv.2 - 웹서비스 배포 전략 및 클라우드 서비스의 이해 [Advance] Lv.3 - 데이터베이스 이해 및 실습 1 (MySQL) Lv.3 - 데이터베이스 이해 및 실습 2 (Supabase) Lv.3 - 데이터베이스 이해 및 실습 3 (Firebase) Lv.4 - 웹앱서비스운영전략 Lv.5 - 개발에서 배포 운영까지의 파이프라인 구축
A29: {{edu_needreason}} | B29: 사업 필요성&목적 | C29: 의료기기 산업 현장에서는 품질·임상·공정 부서별 데이터가 엑셀 개별 관리·수동 집계·복붙 보고서 방식으로 분산 운영되어, 데이터 기반 의사결정의 정확성·신속성·일관성 확보에 한계를 겪고 있음. 또한 KPI 체계 부재와 자동 분석·리포팅 역량 부족으로 부서 간 통합 데이터 활용에 대한 현장 교육 수요가 제기됨. 본 과정은 이러한 현장의 데이터 기반 의사결정 역량 격차를 해소하고, Python/Pandas 기반 데이터 정제·KPI 설계, Streamlit 기반 대시보드 구축, GPT 기반 자동 분석 코멘트·리포트 생성 워크플로를 완성하여 기존 수동 방식에서 AI 자동 분석·리포팅 체계로의 전환 역량을 배양할 수 있다 | J29: 기획자들의 경우 개발자와의 커뮤니케이션에서 어려움을 겪는 경우가 많음, 또한 관련 직무의 수요조사 결과 관련된 교육의 필요성이 제기됨 본 과정은 이런 소통과 기획자의 직무에 필요한 IT관련 기초지식을 배양하여 직무관련 역량을 높이며, 바이브코딩을 통해 업무의 프로세스와 효율을 높일 수 있다
A30: {{edu_curri}} | B30: 커리큘럼 요약 | C30: 의료기기 품질·임상·공정 데이터 유형을 분석·진단하고, Pandas 기반 데이터 정제·구조화 실습을 수행하며, KPI 수식(수율, 일탈률, CAPA 완료율, 임상 등록률 등)을 설계하고 바이브코딩을 활용한 자동 분석 코드 생성 역량을 학습한다. Streamlit 기반 내부 KPI 대시보드 앱을 직접 제작하고, 품질·임상·공정 KPI 시각화 구성(차트, 테이블, 필터) 및 부서별 데이터 통합 뷰 설계·인터랙티브 기능을 구현하는 실습을 진행한다. GPT 기반 KPI 자동 해석 코멘트 생성 기법을 익히고, 데이터 수집부터 정제·KPI·시각화·AI 코멘트·리포트까지 내부 분석 워크플로를 완성하며, 자동 리포트 생성 프로그램을 구축하여 KPI 대시보드·Python 코드·자동 리포트·KPI 정의 문서·의사결정 프레임워크 등 산출물을 완성하는 역량을 강화한다. | J30: LLM(예: ChatGPT, Claude)의 구조와 생성형 AI 패러다임을 이해하고, 의료·바이오 산업에서의 적용 가능성과 한계를 학습하며 기초 툴을 실습한다. 업무 전환을 위해 프롬프트의 기본 구조와 컨텍스트 설계, 페르소나 설정 및 출력 제어 방법을 익히고 직무별 적용 실습을 진행한다. 의료 AI 윤리, 개인정보 비식별화, 저작권 및 사내 보안 가이드라인을 학습하여 민감정보를 안전하게 처리하는 역량을 강화한다.
D33: 능력단위코드 | E33: 능력단위 명 | F33: 훈련시간 | G33: 능력단위요소 코드 | H33: 능력단위요소 명 | I33: 훈련시간
C34: =IFERROR(G34,"") -> 2001010211_16v3.1 | D34: =VLOOKUP(J34,통합!$A$3:$H$44,6,FALSE) -> 1903090101_21v2 | E34: =VLOOKUP(J34,통합!$A$3:$H$44,8,FALSE) -> 의료기기 품질문서 개발 | F34: =IF(COUNTIF($D$69:$D$118,D34)=0,"",COUNTIF($D$69:$D$118,D34)) -> 1 | G34: 2001010211_16v3.1 | H34: 하드웨어 분석하기 | I34: =IF(COUNTIF($G$69:$G$118,G34)=0,"",COUNTIF($G$69:$G$118,G34)) -> 1 | J34: 09.의료장비제조 > 01.의료기기품질관리> 의료기기 품질문서 개발
C35: =IFERROR(G35,"") -> 0 | F35: =IF(COUNTIF($D$69:$D$118,D35)=0,"",COUNTIF($D$69:$D$118,D35)) | I35: =IF(COUNTIF($G$69:$G$118,G35)=0,"",COUNTIF($G$69:$G$118,G35))
C36: =IFERROR(G36,"") -> 0 | F36: =IF(COUNTIF($D$69:$D$118,D36)=0,"",COUNTIF($D$69:$D$118,D36)) | I36: =IF(COUNTIF($G$69:$G$118,G36)=0,"",COUNTIF($G$69:$G$118,G36))
C37: =IFERROR(G37,"") -> 0 | F37: =IF(COUNTIF($D$69:$D$118,D37)=0,"",COUNTIF($D$69:$D$118,D37)) | I37: =IF(COUNTIF($G$69:$G$118,G37)=0,"",COUNTIF($G$69:$G$118,G37))
C38: =IFERROR(G38,"") -> 0 | F38: =IF(COUNTIF($D$69:$D$118,D38)=0,"",COUNTIF($D$69:$D$118,D38)) | I38: =IF(COUNTIF($G$69:$G$118,G38)=0,"",COUNTIF($G$69:$G$118,G38))
C39: =IFERROR(G39,"") -> 0 | F39: =IF(COUNTIF($D$69:$D$118,D39)=0,"",COUNTIF($D$69:$D$118,D39)) | I39: =IF(COUNTIF($G$69:$G$118,G39)=0,"",COUNTIF($G$69:$G$118,G39))
C40: =IFERROR(G40,"") -> 0 | F40: =IF(COUNTIF($D$69:$D$118,D40)=0,"",COUNTIF($D$69:$D$118,D40)) | I40: =IF(COUNTIF($G$69:$G$118,G40)=0,"",COUNTIF($G$69:$G$118,G40))
C41: =IFERROR(G41,"") -> 0 | F41: =IF(COUNTIF($D$69:$D$118,D41)=0,"",COUNTIF($D$69:$D$118,D41)) | I41: =IF(COUNTIF($G$69:$G$118,G41)=0,"",COUNTIF($G$69:$G$118,G41))
C42: =IFERROR(G42,"") -> 0 | F42: =IF(COUNTIF($D$69:$D$118,D42)=0,"",COUNTIF($D$69:$D$118,D42)) | I42: =IF(COUNTIF($G$69:$G$118,G42)=0,"",COUNTIF($G$69:$G$118,G42))
...

Sheet ALX4-R&D요구사항설계자동화
A1: 커리큘럼 기초 내용
B2: 분류선택 | C2: 09.의료장비제조 > 01.의료기기품질관리> 의료기기 품질시스템 자원관리
A3: {{edu_title}} | B3: 훈련과정명 | C3: R&D 요구사항·설계 자동화 및 Traceability 구축 | J3: 기획자와 컨설턴트를 위한 AI개발의 이해
B4: 커리큘럼 | C4: LLM 구조 및 의료 산업 특화 작동 원리 이해 (ChatGPT, Claude) 1. AI 패러다임 변화 2. 생성형 AI 모델 구조 이해 3. 의료/바이오 적용 한계와 가능성 4. 기초 툴 실습 업무 전환을 위한 프롬프트 기본 구조 실습 (ChatGPT 등) 1. 프롬프트 3요소 2. 컨텍스트 부여 방법 3. 페르소나 및 출력 제어 4. 직무별 적용 실습 민감정보 처리, 저작권, 윤리 가이드라인 학습 (비식별화 툴) 1. 의료 AI 윤리 개요 2. 개인정보 비식별화 역량 3. 저작권 문제 4. 사내 보안 가이드라인 기초
A5: {{edu_cate01}} | B5: 대분류 | C5: =VLOOKUP($C$2,통합!$A$3:$H$44,2,FALSE) -> 03.전자기기개발
A6: {{edu_cate02}} | B6: 중분류 | C6: =VLOOKUP($C$2,통합!$A$3:$H$44,3,FALSE) -> 09.의료장비제조
A7: {{edu_cate03}} | B7: 소분류 | C7: =VLOOKUP($C$2,통합!$A$3:$H$44,4,FALSE) -> 01.의료기기품질관리
A8: {{edu_cate04}} | B8: 세분류 | C8: =VLOOKUP($C$2,통합!$A$3:$H$44,7,FALSE)&"."&VLOOKUP($C$2,통합!$A$3:$H$44,8,FALSE) -> 02.의료기기 품질시스템 자원관리
A9: {{edu_cate05}} | B9: 훈련방법 | C9: =VLOOKUP($C$2,통합!$A$3:$H$44,6,FALSE) -> 1903090102_21v2
A10: {{edu_ncslevel}} | B10: 훈련수준 | C10: =VLOOKUP($C$2,통합!$A$3:$H$44,5,FALSE) -> 4
A11: {{edu_time}} | B11: 훈련시간 | C11: =F66&"시간( "&K119&"일)" -> 1시간( 0일) | J11: 000시간(00일)
A12: 교육과정 세부 정보
A13: {{edu_target}} | B13: 훈련대상자 | C13: 의료기기 개발·제조 기업의 R&D(연구개발) 부서 종사자로, 의료기기 설계관리(Design Controls) 프로세스에서 URS/SRS 도출, 테스트 케이스 작성, 변경 영향 분석(ECO), Traceability 매트릭스 관리 등 설계문서 작성·추적 업무를 수행하며, AI 기반 설계관리 자동화 및 추적성 구축 역량이 필요한 실무자 및 관리자 | J13: 기획자, 컨설턴트, 디자이너 등 개발과 AI에 이해가 필요한 직무
A14: {{edu_job}} | B14: 대상직종 | C14: R&D 설계엔지니어, 시스템엔지니어, V&V(검증·밸리데이션)담당자, 설계변경관리자 | J14: 기획자
A15: {{edu_limit}} | B15: 정원 | C15: 20명 | J15: 00명
A16: {{edu_feature}} | B16: 훈련과정 특성 | C16: 4차 산업혁명 핵심 기술인 생성형 AI를 의료기기 R&D 설계관리(Design Controls) 직무에 특화하여 적용하는 신기술 융복합 과정임. 기존 수기 URS 정리→수동 SRS 작성→개별 TC 작성→수기 영향분석→수동 추적 매트릭스(As-Is)에서, AI 요구사항 구조화→자동 SRS 생성→테스트 케이스 자동 생성→Traceability 자동 연결→변경 영향 자동 분석(To-Be)으로의 AX 전환을 실현하는 과정임. IEC 62304(의료기기 소프트웨어), ISO 14971(리스크 관리), FDA Design Controls 규제 환경에 적합한 AI 기반 설계관리 프로세스를 구축하는 미래전략산업 직종 대응 과정임 | J16: 4차 산업혁명 등 관련된 신기술, 융복합, 미래전략산업 직종 과정 등 훈련과정의 특성 기재
A17: {{edu_summary}} | B17: 주요훈련내용 | C17: 본 과정은 의료기기 R&D 종사자를 대상으로 설계관리(Design Controls) 전체 프로세스를 AI 기반 워크플로로 재구성하는 실습 중심 교육을 실시함. 설계 프로세스를 분석하여 AI 자동화 적용 지점을 도출하고, ChatGPT/Claude를 활용하여 URS에서 SRS를 자동 도출하며, Python Script 기반 테스트 케이스(TC) 자동 생성 및 CSV/Excel 출력 실습을 수행함. 또한 ECO(Engineering Change Order) 발생 시 변경 영향 분석을 AI로 자동화하고, 요구사항–설계–테스트–리스크 간 Traceability 매트릭스를 자동 구축하며, n8n/Google AI Studio를 활용하여 설계관리 AI 워크플로를 완성하는 교육을 실시함 | J17: 주요훈련내용을 요약해서 작성
